File: XPS/Casa format/HT CP 19 Ap location C1 in image-0.6621.vms
VAMAS Surface Chemical Analysis Standard Data Transfer Format 1988 May 4
Not specified
MI-600-BE9240AA
XPSUser
KTH Amireza_C-paper-Mxene-sample sent on 17 April2023.experiment
0
NORM
REGULAR
1
4
Index
d
PositionX [mm]
n
PositionY [mm]
n
PositionZ [mm]
n
0
0
0
0
10
wide
HT CP 19 Ap
2023
5
9
14
42
36
2
39
Creation
Created by : XPSUser
Date created : 09/05/2023 14:42
Computer : DESKTOP-U3MGE2F
Location
Location ID : C1
Sample : HT CP 19 Ap
Description : (47.619,16.070,-0.852)mm
Tilt : 0.00
Charge Neutraliser : On
Filament Current : 0.53A
Filament Bias : 2.02V
Charge Balance : 5.02V
Settings
Excitation
Mode : XPS - monochromatic
Tuning : Spectroscopy
Emission current : 15.00mA
Anode library : Al
ESCA modes
Collimation : Slot
Lens : Hybrid
Resolution : 160.00
Scan
Deflection : (0.000, 0.000)mm
wide : 286.690-1491.690eV, Sweeps 5
Start : 286.690eV
End : 1491.690eV
Centre : 889.190eV
Width : 1205.000eV
Step size : 1.000eV
Number Steps : 1205
Dwell time : 100ms
Sweep time : 120s
Sweeps : 5
Instrument Conditions
Work function : -4.50
Acquisition Conditions
X-ray Power : 225.00W
XPS
1
47.6185
16.0701171875
-0.852359375
Al (mono)
1486.69
225
1E+37
1E+37
1E+37
1E+37
FAT
160
1E+37
-4.5
1E+37
1E+37
1E+37
1E+37
1E+37
wide

-1
Kinetic energy
eV
286.69
1
2
Intensity
d
Transmission
d
pulse counting
0.0995024875621891
0
1E+37
0
1
31.1899525550317
22946
23092
22746
22631
23028
23059
22881
22804
22980
23116
23163
22932
22924
23238
23198
23146
23184
23118
23275
23227
23014
23309
23343
23116
23576
23459
23516
23444
23630
23638
23669
23406
23656
23759
23675
23638
23922
23948
24007
23754
23732
23872
23969
24072
23989
24007
23934
23920
23745
23841
23898
23903
23730
24042
24024
24064
24096
24433
24134
24181
24161
24123
24086
24403
24136
24351
24290
24216
24573
24867
24642
24590
24377
24600
24580
24408
24661
24737
24845
24813
25048
24894
25054
24990
25053
24838
24969
24895
25072
25330
25425
25215
25290
25405
25377
25589
25264
25312
25423
25526
25432
25682
25591
25544
25853
25703
25757
25768
25754
25795
25700
25654
25663
25829
25913
25896
25969
25957
25974
26219
26299
26206
26190
26237
26356
26191
26258
26414
26561
26656
26625
26576
26523
26853
26874
27048
26817
26900
26772
26859
26817
26723
26992
26825
26977
27042
27300
27195
27441
27291
27330
27390
27404
27623
27412
27273
27389
27146
27312
27355
27632
27666
27819
27839
27731
27805
28014
28160
28051
28079
28299
28321
28052
27959
28200
28216
28264
28477
28624
28528
28801
28988
29026
29077
28817
28796
28969
29032
29111
29210
29299
29385
29536
29632
29734
29626
29631
30010
30019
30348
30759
30668
30787
30882
31101
30632
30655
30587
30373
30492
30421
30273
30406
30307
30729
30712
30747
31048
31342
31606
31995
32744
33297
33217
33828
33755
33332
33643
33433
33031
32417
31926
31461
30841
30408
29937
29041
28819
28911
28873
28712
28596
28602
28932
28588
28625
28674
28527
28458
28660
28843
28992
28863
28660
28553
28711
28891
28657
28813
28928
29046
28948
28932
28686
29076
29168
28813
28937
29202
29140
29107
29094
29098
29145
29269
29141
29399
29165
29180
29337
29126
29454
29669
29646
29361
29384
29271
29564
29558
29678
29779
29826
29488
29619
29613
29900
29658
29755
29889
29852
29947
29972
29796
29929
29884
29898
30196
30140
30103
30148
30198
30121
30056
30144
30189
30283
30310
30414
30363
30269
30289
30059
30069
30392
30368
30195
30606
30604
30382
30608
30744
30479
30468
30555
30474
30810
30827
30508
30611
30697
30842
30939
30732
30727
31005
30776
31017
30884
31140
31353
31069
31189
30672
30863
31188
31222
31144
31250
31139
31301
31332
31193
31059
31167
31224
31577
31559
31615
31540
31543
31398
31592
31511
31704
31371
31476
31425
31636
31639
31965
31794
31962
31848
31813
32175
32033
31822
31925
31742
31931
31874
31915
32107
32012
31832
32101
32253
31977
32280
31989
31941
32108
32044
32222
32327
32100
32202
32374
32407
32170
32238
32369
32360
32543
32417
32393
32339
32600
32498
32245
32489
32764
32718
32722
32657
32548
32651
32762
32679
32748
32647
32939
33206
33057
33053
32960
33053
32897
32774
32929
33013
33115
33171
33045
32948
33333
33449
33352
33026
33017
32775
33165
32873
33315
33097
33064
33188
33400
33122
33179
33262
33555
33272
33157
33430
33290
33577
33545
33612
33676
33537
33692
33696
33633
33627
33928
33916
33487
33914
34022
34301
34073
33788
33972
33514
34210
34214
33935
33754
33734
33982
34150
34141
34114
34028
33995
34129
34093
34222
34293
34106
34195
34376
34321
34250
34408
34133
34308
34337
34494
34380
34371
34312
34424
34379
34567
34230
34374
34488
34739
35055
34640
34950
34550
34475
34707
34918
34808
34944
34948
34549
34949
34873
34968
34899
34757
34857
34969
34938
35196
35372
35169
34788
34984
35409
35434
35251
34953
35180
35294
35411
35162
34977
35139
35392
35458
35323
35196
35243
35354
35424
35576
35654
35633
35495
35687
35707
35564
35577
35612
35646
35710
35570
35599
35418
35721
35666
35801
35937
35987
36134
35976
35861
35585
35860
35912
36140
35821
35926
36050
36393
36223
36597
36347
36204
36302
36369
36653
36330
36561
36426
36464
36425
36668
36839
36818
36491
36393
36630
36660
36532
36672
36755
36687
36681
36878
36626
36840
36990
37076
36888
36583
37038
36981
36997
37038
37241
37345
37595
37164
37143
37448
37285
37385
37531
37331
37574
37667
37630
37715
38019
37947
37826
37925
37832
37914
38148
38334
38109
37597
37746
37654
37686
37620
37710
37756
37810
37715
37613
37938
38035
38159
38640
39120
39595
40479
42819
46315
49197
48231
44142
40325
38122
37245
36968
37046
37145
37046
37076
37160
37104
37028
36947
37293
37069
37091
37121
37218
37144
37117
37254
37343
37388
36946
37090
37581
37074
37242
37724
37334
37569
37103
37215
37186
37502
37451
37572
37648
37611
37895
37813
37868
37758
37656
37776
37877
37723
37672
37909
38138
37547
37667
38264
37811
38008
38151
38046
38044
38001
38345
38226
38453
38309
38095
38103
38320
38396
38401
38127
38266
38332
38423
38610
38713
38513
38519
38282
38433
38828
38900
38539
38698
38885
38784
38954
38715
38855
39168
38618
38929
39002
39043
38740
39185
38939
39169
39431
39272
39223
39489
39444
39507
39612
39482
39541
39533
39461
39248
39372
39447
39407
39789
39714
40042
39896
39888
39783
39846
40013
40142
40152
40018
40284
40212
40251
40188
40085
40370
40474
40556
40590
40438
40319
40374
40535
40416
40518
40651
40755
40696
40853
40649
40493
40674
40858
40744
41091
41069
40842
41184
41205
41226
41231
41231
41415
41549
41674
41442
41594
41535
41634
41763
41332
41556
41785
41486
41351
41577
41879
41878
41968
42240
41819
42058
42049
42137
42470
42894
42990
42954
43419
43265
43504
43847
43786
43700
43880
43944
43813
43600
43520
43268
42729
42407
42054
41529
40889
40429
40655
40404
40200
40358
40890
41482
42059
42913
43644
44790
45904
46694
47364
47825
48494
49020
49484
49466
49681
49432
48738
47734
46375
44582
41954
39213
36772
34460
31948
29946
27594
25671
24212
23236
22806
22980
23816
25370
28308
31452
36260
41723
44887
45493
47235
53851
74377
137235
240862
169888
43112
8367
4958
3546
2576
2022
1810
1700
1660
1576
1550
1560
1524
1500
1431
1468
1409
1408
1440
1435
1427
1384
1391
1352
1415
1406
1413
1404
1410
1465
1408
1389
1387
1458
1428
1394
1390
1396
1404
1446
1387
1446
1419
1377
1385
1370
1417
1403
1400
1408
1365
1418
1423
1400
1384
1377
1360
1379
1430
1443
1410
1410
1404
1456
1500
1431
1404
1419
1384
1380
1478
1453
1400
1405
1415
1469
1455
1431
1397
1421
1426
1484
1445
1457
1418
1394
1439
1392
1430
1383
1477
1466
1410
1378
1390
1413
1448
1454
1447
1432
1460
1476
1459
1468
1492
1449
1462
1503
1463
1433
1468
1483
1515
1455
1508
1494
1476
1473
1452
1437
1449
1424
1403
1451
1539
1536
1506
1704
1772
1820
1855
1747
1582
1473
1451
1425
1487
1484
1467
1453
1431
1440
1505
1442
1532
1501
1532
1490
1499
1499
1459
1495
1546
1482
1467
1493
1492
1511
1515
1507
1484
1521
1476
1461
1524
1498
1505
1498
1434
1496
1480
1559
1466
1504
1512
1510
1499
1534
1675
1809
1939
1846
1657
1554
1454
1460
1445
1483
1508
1500
1449
1508
1512
1531
1523
1518
1523
1447
1474
1447
1488
1559
1535
1552
1477
1482
1515
1598
1589
1544
1610
1581
1530
1537
1550
1514
1525
1469
1469
1464
1444
1458
1474
1555
1575
1553
1573
1579
1700
1680
1700
1700
1764
1837
1836
1829
1916
1864
1780
1822
1803
1750
1693
1630
1594
1549
1452
1410
1364
1293
1293
1329
1343
1346
1425
1502
1516
1711
1768
1906
2111
2494
2777
2987
2988
3031
2884
2645
2385
2249
2074
1744
1516
1403
1219
1054
764
558
358
251
168
92
39
12
4
3
2
1
31.1899525550317
C 1s
HT CP 19 Ap
2023
5
9
19
57
45
2
41
Creation
Created by : XPSUser
Date created : 09/05/2023 19:57
Computer : DESKTOP-U3MGE2F
Location
Location ID : C1
Sample : HT CP 19 Ap
Description : (47.619,16.070,-0.852)mm
Tilt : 0.00
Charge Neutraliser : On
Filament Current : 0.53A
Filament Bias : 2.02V
Charge Balance : 5.02V
Settings
Excitation
Mode : XPS - monochromatic
Tuning : Spectroscopy
Emission current : 15.00mA
Anode library : Al
ESCA modes
Collimation : Slot
Lens : Hybrid
Resolution : 20.00
Scan
Deflection : (0.000, 0.000)mm
C 1s : 1191.690-1209.690eV, Sweeps 1
Start : 1191.690eV
End : 1209.690eV
Centre : 1200.690eV
Width : 18.000eV
Step size : 0.100eV
Number Steps : 180
Dwell time : 331ms
Sweep time : 60s
Sweeps : 1
Target quality : 200
Instrument Conditions
Work function : -4.50
Acquisition Conditions
X-ray Power : 225.00W
Quality : 315.34
XPS
2
47.6185
16.0701171875
-0.852359375
Al (mono)
1486.69
225
1E+37
1E+37
1E+37
1E+37
FAT
20
1E+37
-4.5
1E+37
1E+37
1E+37
1E+37
1E+37
C
1s
-1
Kinetic energy
eV
1191.69
0.1
2
Intensity
d
Transmission
d
pulse counting
0.331492
1
0
1E+37
1E+37
1E+37
0
362
52
29840
1.33571680812406
1.34279197206053
852
1.33571680812406
905
1.33575611459037
922
1.33579542105669
882
1.335834727523
925
1.33587403398932
968
1.33591334045563
950
1.33595264692194
951
1.33599195338826
951
1.33603125985457
995
1.33607056632088
986
1.3361098727872
1000
1.33614917925351
1008
1.33618848571983
1027
1.33622779218614
1047
1.33626709865245
1024
1.33630640511877
999
1.33634571158508
1047
1.33638501805139
1084
1.33642432451771
1018
1.33646363098402
1048
1.33650293745034
1083
1.33654224391665
1067
1.33658155038296
1076
1.33662085684928
1120
1.33666016331559
1133
1.3366994697819
1123
1.33673877624822
1137
1.33677808271453
1151
1.33681738918085
1203
1.33685669564716
1256
1.33689600211347
1269
1.33693530857979
1262
1.3369746150461
1273
1.33701392151241
1384
1.33705322797873
1380
1.33709253444504
1443
1.33713184091135
1427
1.33717114737767
1474
1.33721045384398
1550
1.3372497603103
1565
1.33728906677661
1571
1.33732837324292
1607
1.33736767970924
1556
1.33740698617555
1561
1.33744629264186
1574
1.33748559910818
1634
1.33752490557449
1509
1.33756421204081
1566
1.33760351850712
1516
1.33764282497343
1468
1.33768213143975
1510
1.33772143790606
1481
1.33776074437237
1479
1.33780005083869
1493
1.337839357305
1516
1.33787866377132
1449
1.33791797023763
1399
1.33795727670394
1374
1.33799658317026
1419
1.33803588963657
1392
1.33807519610288
1409
1.3381145025692
1399
1.33815380903551
1372
1.33819311550182
1348
1.33823242196814
1410
1.33827172843445
1341
1.33831103490077
1348
1.33835034136708
1349
1.33838964783339
1361
1.33842895429971
1391
1.33846826076602
1390
1.33850756723233
1430
1.33854687369865
1418
1.33858618016496
1473
1.33862548663128
1495
1.33866479309759
1450
1.3387040995639
1474
1.33874340603022
1516
1.33878271249653
1550
1.33882201896284
1605
1.33886132542916
1617
1.33890063189547
1599
1.33893993836179
1709
1.3389792448281
1758
1.33901855129441
1834
1.33905785776073
1905
1.33909716422704
1962
1.33913647069335
1922
1.33917577715967
2068
1.33921508362598
2176
1.3392543900923
2237
1.33929369655861
2329
1.33933300302492
2507
1.33937230949124
2527
1.33941161595755
2641
1.33945092242386
2727
1.33949022889018
2895
1.33952953535649
2970
1.3395688418228
3122
1.33960814828912
3313
1.33964745475543
3582
1.33968676122175
3810
1.33972606768806
4280
1.33976537415437
5053
1.33980468062069
5912
1.339843987087
7443
1.33988329355331
10357
1.33992260001963
14370
1.33996190648594
19862
1.34000121295226
25946
1.34004051941857
29840
1.34007982588488
28438
1.3401191323512
22021
1.34015843881751
13932
1.34019774528382
7796
1.34023705175014
4350
1.34027635821645
2621
1.34031566468277
1774
1.34035497114908
1309
1.34039427761539
1007
1.34043358408171
780
1.34047289054802
627
1.34051219701433
508
1.34055150348065
388
1.34059080994696
324
1.34063011641328
299
1.34066942287959
245
1.3407087293459
220
1.34074803581222
200
1.34078734227853
184
1.34082664874484
166
1.34086595521116
161
1.34090526167747
170
1.34094456814378
144
1.3409838746101
132
1.34102318107641
140
1.34106248754273
132
1.34110179400904
119
1.34114110047535
101
1.34118040694167
108
1.34121971340798
101
1.34125901987429
104
1.34129832634061
96
1.34133763280692
90
1.34137693927324
76
1.34141624573955
85
1.34145555220586
77
1.34149485867218
73
1.34153416513849
91
1.3415734716048
79
1.34161277807112
72
1.34165208453743
81
1.34169139100375
78
1.34173069747006
75
1.34177000393637
75
1.34180931040269
74
1.341848616869
66
1.34188792333531
73
1.34192722980163
75
1.34196653626794
73
1.34200584273426
62
1.34204514920057
60
1.34208445566688
63
1.3421237621332
56
1.34216306859951
68
1.34220237506582
72
1.34224168153214
56
1.34228098799845
62
1.34232029446476
57
1.34235960093108
61
1.34239890739739
52
1.34243821386371
67
1.34247752033002
69
1.34251682679633
65
1.34255613326265
63
1.34259543972896
56
1.34263474619527
66
1.34267405266159
68
1.3427133591279
55
1.34275266559422
58
1.34279197206053
Cl2s
HT CP 19 Ap
2023
5
9
19
57
45
2
41
Creation
Created by : XPSUser
Date created : 09/05/2023 19:57
Computer : DESKTOP-U3MGE2F
Location
Location ID : C1
Sample : HT CP 19 Ap
Description : (47.619,16.070,-0.852)mm
Tilt : 0.00
Charge Neutraliser : On
Filament Current : 0.53A
Filament Bias : 2.02V
Charge Balance : 5.02V
Settings
Excitation
Mode : XPS - monochromatic
Tuning : Spectroscopy
Emission current : 15.00mA
Anode library : Al
ESCA modes
Collimation : Slot
Lens : Hybrid
Resolution : 20.00
Scan
Deflection : (0.000, 0.000)mm
Cl2s : 1201.690-1231.690eV, Sweeps 1
Start : 1201.690eV
End : 1231.690eV
Centre : 1216.690eV
Width : 30.000eV
Step size : 0.100eV
Number Steps : 300
Dwell time : 199ms
Sweep time : 60s
Sweeps : 1
Target quality : 200
Instrument Conditions
Work function : -4.50
Acquisition Conditions
X-ray Power : 225.00W
Quality : 577.70
XPS
3
47.6185
16.0701171875
-0.852359375
Al (mono)
1486.69
225
1E+37
1E+37
1E+37
1E+37
FAT
20
1E+37
-4.5
1E+37
1E+37
1E+37
1E+37
1E+37
Cl2s

-1
Kinetic energy
eV
1201.69
0.1
2
Intensity
d
Transmission
d
pulse counting
0.199335548172757
1
0
1E+37
1E+37
1E+37
0
602
17
18090
1.33964745475543
1.35143939464955
2000
1.33964745475543
2198
1.33968676122175
2385
1.33972606768806
2599
1.33976537415437
3074
1.33980468062069
3766
1.339843987087
4808
1.33988329355331
6490
1.33992260001963
9072
1.33996190648594
12707
1.34000121295226
16208
1.34004051941857
18090
1.34007982588488
16484
1.3401191323512
12265
1.34015843881751
7589
1.34019774528382
4229
1.34023705175014
2363
1.34027635821645
1432
1.34031566468277
1013
1.34035497114908
714
1.34039427761539
561
1.34043358408171
431
1.34047289054802
358
1.34051219701433
307
1.34055150348065
242
1.34059080994696
208
1.34063011641328
166
1.34066942287959
125
1.3407087293459
112
1.34074803581222
124
1.34078734227853
106
1.34082664874484
89
1.34086595521116
100
1.34090526167747
88
1.34094456814378
78
1.3409838746101
73
1.34102318107641
80
1.34106248754273
77
1.34110179400904
74
1.34114110047535
70
1.34118040694167
51
1.34121971340798
62
1.34125901987429
56
1.34129832634061
58
1.34133763280692
53
1.34137693927324
53
1.34141624573955
52
1.34145555220586
60
1.34149485867218
61
1.34153416513849
59
1.3415734716048
53
1.34161277807112
51
1.34165208453743
45
1.34169139100375
38
1.34173069747006
46
1.34177000393637
40
1.34180931040269
49
1.341848616869
30
1.34188792333531
38
1.34192722980163
46
1.34196653626794
37
1.34200584273426
44
1.34204514920057
46
1.34208445566688
39
1.3421237621332
28
1.34216306859951
33
1.34220237506582
33
1.34224168153214
24
1.34228098799845
30
1.34232029446476
46
1.34235960093108
36
1.34239890739739
41
1.34243821386371
34
1.34247752033002
49
1.34251682679633
36
1.34255613326265
32
1.34259543972896
45
1.34263474619527
37
1.34267405266159
42
1.3427133591279
36
1.34275266559422
29
1.34279197206053
29
1.34283127852684
42
1.34287058499316
36
1.34290989145947
31
1.34294919792578
37
1.3429885043921
29
1.34302781085841
24
1.34306711732473
35
1.34310642379104
39
1.34314573025735
32
1.34318503672367
26
1.34322434318998
30
1.34326364965629
33
1.34330295612261
34
1.34334226258892
37
1.34338156905524
32
1.34342087552155
25
1.34346018198786
28
1.34349948845418
30
1.34353879492049
35
1.3435781013868
37
1.34361740785312
38
1.34365671431943
25
1.34369602078574
33
1.34373532725206
31
1.34377463371837
33
1.34381394018469
38
1.343853246651
36
1.34389255311731
36
1.34393185958363
29
1.34397116604994
21
1.34401047251625
26
1.34404977898257
29
1.34408908544888
35
1.3441283919152
36
1.34416769838151
43
1.34420700484782
37
1.34424631131414
30
1.34428561778045
33
1.34432492424676
33
1.34436423071308
30
1.34440353717939
35
1.34444284364571
37
1.34448215011202
27
1.34452145657833
27
1.34456076304465
34
1.34460006951096
32
1.34463937597727
30
1.34467868244359
41
1.3447179889099
32
1.34475729537622
36
1.34479660184253
34
1.34483590830884
30
1.34487521477516
38
1.34491452124147
33
1.34495382770778
30
1.3449931341741
35
1.34503244064041
34
1.34507174710672
28
1.34511105357304
23
1.34515036003935
21
1.34518966650567
25
1.34522897297198
26
1.34526827943829
32
1.34530758590461
33
1.34534689237092
40
1.34538619883723
33
1.34542550530355
27
1.34546481176986
38
1.34550411823618
37
1.34554342470249
40
1.3455827311688
41
1.34562203763512
32
1.34566134410143
26
1.34570065056774
35
1.34573995703406
37
1.34577926350037
27
1.34581856996669
35
1.345857876433
36
1.34589718289931
36
1.34593648936563
34
1.34597579583194
31
1.34601510229825
29
1.34605440876457
31
1.34609371523088
22
1.34613302169719
31
1.34617232816351
34
1.34621163462982
43
1.34625094109614
31
1.34629024756245
26
1.34632955402876
33
1.34636886049508
30
1.34640816696139
33
1.3464474734277
27
1.34648677989402
24
1.34652608636033
38
1.34656539282665
40
1.34660469929296
34
1.34664400575927
29
1.34668331222559
30
1.3467226186919
33
1.34676192515821
34
1.34680123162453
36
1.34684053809084
38
1.34687984455716
26
1.34691915102347
29
1.34695845748978
22
1.3469977639561
27
1.34703707042241
34
1.34707637688872
37
1.34711568335504
36
1.34715498982135
24
1.34719429628767
31
1.34723360275398
27
1.34727290922029
28
1.34731221568661
26
1.34735152215292
32
1.34739082861923
28
1.34743013508555
34
1.34746944155186
31
1.34750874801817
28
1.34754805448449
29
1.3475873609508
28
1.34762666741712
42
1.34766597388343
37
1.34770528034974
32
1.34774458681606
26
1.34778389328237
25
1.34782319974868
39
1.347862506215
34
1.34790181268131
32
1.34794111914763
34
1.34798042561394
31
1.34801973208025
23
1.34805903854657
26
1.34809834501288
25
1.34813765147919
34
1.34817695794551
35
1.34821626441182
36
1.34825557087814
36
1.34829487734445
36
1.34833418381076
34
1.34837349027708
30
1.34841279674339
37
1.3484521032097
34
1.34849140967602
30
1.34853071614233
27
1.34857002260865
34
1.34860932907496
36
1.34864863554127
49
1.34868794200759
33
1.3487272484739
28
1.34876655494021
24
1.34880586140653
27
1.34884516787284
26
1.34888447433916
32
1.34892378080547
26
1.34896308727178
35
1.3490023937381
27
1.34904170020441
30
1.34908100667072
34
1.34912031313704
38
1.34915961960335
32
1.34919892606966
32
1.34923823253598
32
1.34927753900229
28
1.34931684546861
32
1.34935615193492
28
1.34939545840123
31
1.34943476486755
33
1.34947407133386
33
1.34951337780017
34
1.34955268426649
37
1.3495919907328
31
1.34963129719912
30
1.34967060366543
36
1.34970991013174
37
1.34974921659806
32
1.34978852306437
32
1.34982782953068
30
1.349867135997
29
1.34990644246331
30
1.34994574892963
23
1.34998505539594
30
1.35002436186225
38
1.35006366832857
28
1.35010297479488
29
1.35014228126119
31
1.35018158772751
27
1.35022089419382
30
1.35026020066013
30
1.35029950712645
22
1.35033881359276
28
1.35037812005908
27
1.35041742652539
33
1.3504567329917
29
1.35049603945802
26
1.35053534592433
28
1.35057465239064
23
1.35061395885696
27
1.35065326532327
30
1.35069257178959
27
1.3507318782559
37
1.35077118472221
29
1.35081049118853
35
1.35084979765484
30
1.35088910412115
35
1.35092841058747
36
1.35096771705378
25
1.3510070235201
28
1.35104632998641
26
1.35108563645272
30
1.35112494291904
45
1.35116424938535
37
1.35120355585166
31
1.35124286231798
20
1.35128216878429
17
1.35132147525061
26
1.35136078171692
30
1.35140008818323
30
1.35143939464955
F1s
HT CP 19 Ap
2023
5
9
19
57
45
2
41
Creation
Created by : XPSUser
Date created : 09/05/2023 19:57
Computer : DESKTOP-U3MGE2F
Location
Location ID : C1
Sample : HT CP 19 Ap
Description : (47.619,16.070,-0.852)mm
Tilt : 0.00
Charge Neutraliser : On
Filament Current : 0.53A
Filament Bias : 2.02V
Charge Balance : 5.02V
Settings
Excitation
Mode : XPS - monochromatic
Tuning : Spectroscopy
Emission current : 15.00mA
Anode library : Al
ESCA modes
Collimation : Slot
Lens : Hybrid
Resolution : 20.00
Scan
Deflection : (0.000, 0.000)mm
F1s : 791.690-811.690eV, Sweeps 5
Start : 791.690eV
End : 811.690eV
Centre : 801.690eV
Width : 20.000eV
Step size : 0.100eV
Number Steps : 200
Dwell time : 299ms
Sweep time : 60s
Sweeps : 5
Target quality : 200
Instrument Conditions
Work function : -4.50
Acquisition Conditions
X-ray Power : 225.00W
Quality : 7.00
XPS
4
47.6185
16.0701171875
-0.852359375
Al (mono)
1486.69
225
1E+37
1E+37
1E+37
1E+37
FAT
20
1E+37
-4.5
1E+37
1E+37
1E+37
1E+37
1E+37
F1s

-1
Kinetic energy
eV
791.69
0.1
2
Intensity
d
Transmission
d
pulse counting
0.298507462686567
5
0
1E+37
1E+37
1E+37
0
402
5946
6285
1.45714403256293
1.46809980524165
6063
1.46809980524165
6011
1.46804594968559
6010
1.46799209412953
6122
1.46793823857347
6267
1.46788438301742
6215
1.46783052746136
6109
1.4677766719053
6079
1.46772281634924
6117
1.46766896079318
6114
1.46761510523713
6139
1.46756124968107
6136
1.46750739412501
6106
1.46745353856895
6033
1.46739968301289
5946
1.46734582745684
6092
1.46729197190078
6114
1.46723811634472
6075
1.46718426078866
6184
1.4671304052326
6248
1.46707654967654
6127
1.46702269412049
5984
1.46696883856443
6100
1.46691498300837
6079
1.46686112745231
6017
1.46680727189625
6005
1.4667534163402
6234
1.46669956078414
6121
1.46664570522808
6171
1.46659184967202
6068
1.46653799411596
6076
1.46648413855991
6106
1.46643028300385
6080
1.46637642744779
6093
1.46632257189173
6055
1.46626871633567
6134
1.46621486077962
6101
1.46616100522356
6173
1.4661071496675
6150
1.46605329411144
6274
1.46599943855538
6115
1.46594558299933
6155
1.46589172744327
5985
1.46583787188721
6060
1.46578401633115
6088
1.46573016077509
6124
1.46567630521904
6188
1.46562244966298
6185
1.46556859410692
6067
1.46551473855086
6117
1.4654608829948
6222
1.46540702743874
6150
1.46535317188269
6002
1.46529931632663
6189
1.46524546077057
6207
1.46519160521451
6076
1.46513774965845
6128
1.4650838941024
6156
1.46503003854634
6127
1.46497618299028
6153
1.46492232743422
6107
1.46486847187816
6115
1.46481461632211
6203
1.46476076076605
6123
1.46470690520999
6087
1.46465304965393
6145
1.46459919409787
6117
1.46454533854182
6061
1.46449148298576
6188
1.4644376274297
6166
1.46438377187364
6154
1.46432991631758
6140
1.46427606076153
6069
1.46422220520547
6115
1.46416834964941
6147
1.46411449409335
6146
1.46406063853729
6119
1.46400678298124
6119
1.46395292742518
6099
1.46389907186912
6133
1.46384521631306
6055
1.463791360757
6164
1.46373750520094
6060
1.46368364964489
6149
1.46362979408883
6080
1.46357593853277
6082
1.46352208297671
6157
1.46346822742065
6075
1.4634143718646
6134
1.46336051630854
6164
1.46330666075248
6110
1.46325280519642
6102
1.46319894964036
6066
1.46314509408431
6161
1.46309123852825
6128
1.46303738297219
6129
1.46298352741613
6090
1.46292967186007
6032
1.46287581630402
6079
1.46282196074796
6119
1.4627681051919
6203
1.46271424963584
6152
1.46266039407978
6104
1.46260653852373
6163
1.46255268296767
6184
1.46249882741161
6089
1.46244497185555
6155
1.46239111629949
6224
1.46233726074344
6285
1.46228340518738
6110
1.46222954963132
6094
1.46217569407526
6086
1.4621218385192
6115
1.46206798296314
6116
1.46201412740709
6095
1.46196027185103
6131
1.46190641629497
6048
1.46185256073891
6146
1.46179870518285
6147
1.4617448496268
6096
1.46169099407074
6101
1.46163713851468
6057
1.46158328295862
6071
1.46152942740256
6125
1.46147557184651
6096
1.46142171629045
6217
1.46136786073439
6167
1.46131400517833
6132
1.46126014962227
6003
1.46120629406622
6158
1.46115243851016
6190
1.4610985829541
6184
1.46104472739804
6091
1.46099087184198
6168
1.46093701628593
6190
1.46088316072987
6103
1.46082930517381
6118
1.46077544961775
6053
1.46072159406169
6088
1.46066773850564
6132
1.46061388294958
6117
1.46056002739352
6197
1.46050617183746
6173
1.4604523162814
6130
1.46039846072534
6128
1.46034460516929
6220
1.46029074961323
6117
1.46023689405717
6180
1.46018303850111
6241
1.46012918294505
6003
1.460075327389
5994
1.46002147183294
6233
1.45996761627688
6119
1.45991376072082
6111
1.45985990516476
6197
1.45980604960871
6154
1.45975219405265
6187
1.45969833849659
6093
1.45964448294053
6169
1.45959062738447
6217
1.45953677182842
6159
1.45948291627236
6160
1.4594290607163
6057
1.45937520516024
6124
1.45932134960418
6128
1.45926749404813
6109
1.45921363849207
6180
1.45915978293601
6167
1.45910592737995
6179
1.45905207182389
6189
1.45899821626783
6135
1.45894436071178
6006
1.45889050515572
6024
1.45883664959966
6117
1.4587827940436
6220
1.45872893848754
6275
1.45867508293149
6246
1.45862122737543
6185
1.45856737181937
6160
1.45851351626331
6170
1.45845966070725
6064
1.4584058051512
6157
1.45835194959514
6114
1.45829809403908
6143
1.45824423848302
6111
1.45818054888434
6142
1.45811576661425
6188
1.45805098434416
6181
1.45798620207407
6033
1.45792141980398
6106
1.4578566375339
6140
1.45779185526381
6273
1.45772707299372
6090
1.45766229072363
6064
1.45759750845354
6098
1.45753272618346
6085
1.45746794391337
6123
1.45740316164328
6097
1.45733837937319
6202
1.4572735971031
6191
1.45720881483302
6133
1.45714403256293
O1s
HT CP 19 Ap
2023
5
9
19
57
45
2
41
Creation
Created by : XPSUser
Date created : 09/05/2023 19:57
Computer : DESKTOP-U3MGE2F
Location
Location ID : C1
Sample : HT CP 19 Ap
Description : (47.619,16.070,-0.852)mm
Tilt : 0.00
Charge Neutraliser : On
Filament Current : 0.53A
Filament Bias : 2.02V
Charge Balance : 5.02V
Settings
Excitation
Mode : XPS - monochromatic
Tuning : Spectroscopy
Emission current : 15.00mA
Anode library : Al
ESCA modes
Collimation : Slot
Lens : Hybrid
Resolution : 20.00
Scan
Deflection : (0.000, 0.000)mm
O1s : 946.690-961.690eV, Sweeps 5
Start : 946.690eV
End : 961.690eV
Centre : 954.190eV
Width : 15.000eV
Step size : 0.100eV
Number Steps : 150
Dwell time : 397ms
Sweep time : 60s
Sweeps : 5
Target quality : 200
Instrument Conditions
Work function : -4.50
Acquisition Conditions
X-ray Power : 225.00W
Quality : 65.68
XPS
5
47.6185
16.0701171875
-0.852359375
Al (mono)
1486.69
225
1E+37
1E+37
1E+37
1E+37
FAT
20
1E+37
-4.5
1E+37
1E+37
1E+37
1E+37
1E+37
O1s

-1
Kinetic energy
eV
946.69
0.1
2
Intensity
d
Transmission
d
pulse counting
0.397351
5
0
1E+37
1E+37
1E+37
0
302
8129
11919
1.39073012089434
1.39549665066723
8623
1.39549665066723
8536
1.39546487380208
8526
1.39543309693692
8373
1.39540132007177
8498
1.39536954320662
8537
1.39533776634147
8553
1.39530598947631
8592
1.39527421261116
8625
1.39524243574601
8687
1.39521065888085
8556
1.3951788820157
8558
1.39514710515055
8634
1.3951153282854
8548
1.39508355142024
8608
1.39505177455509
8644
1.39501999768994
8675
1.39498822082479
8429
1.39495644395963
8791
1.39492466709448
8676
1.39489289022933
8721
1.39486111336418
8678
1.39482933649902
8704
1.39479755963387
8706
1.39476578276872
8671
1.39473400590357
8699
1.39470222903841
8740
1.39467045217326
8724
1.39463867530811
8666
1.39460689844296
8773
1.3945751215778
8747
1.39454334471265
8691
1.3945115678475
8651
1.39447979098235
8600
1.39444801411719
8661
1.39441623725204
8719
1.39438446038689
8685
1.39435268352174
8703
1.39432090665658
8770
1.39428912979143
8852
1.39425735292628
8763
1.39422557606112
8772
1.39419379919597
8664
1.39416202233082
8744
1.39413024546567
8884
1.39409846860051
8955
1.39406669173536
8892
1.39403491487021
8882
1.39400313800506
8877
1.3939713611399
8906
1.39393958427475
9002
1.3939078074096
8950
1.39387603054445
8856
1.39384425367929
8875
1.39381247681414
9079
1.39378069994899
9154
1.39374892308384
9024
1.39371714621868
9179
1.39368536935353
9175
1.39365359248838
9291
1.39362181562323
9491
1.39359003875807
9536
1.39355826189292
9514
1.39352648502777
9640
1.39349470816262
9710
1.39346293129746
9973
1.39343115443231
10154
1.39339937756716
10474
1.393367600702
10628
1.39333582383685
10770
1.3933040469717
11040
1.39327227010655
11256
1.39324049324139
11412
1.39320871637624
11513
1.39317693951109
11697
1.39314516264594
11919
1.39311338578078
11827
1.39308160891563
11754
1.39304983205048
11656
1.39301805518533
11742
1.39298627832017
11801
1.39295450145502
11684
1.39292272458987
11627
1.39289094772472
11603
1.39285917085956
11645
1.39282739399441
11496
1.39279561712926
11509
1.39276384026411
11366
1.39273206339895
11067
1.3927002865338
10923
1.39266850966865
10934
1.3926367328035
10914
1.39260495593834
10763
1.39257317907319
10862
1.39254140220804
10686
1.39250962534289
10606
1.39247784847773
10502
1.39244607161258
10278
1.39241429474743
10248
1.39238251788227
9879
1.39235074101712
9973
1.39231896415197
9720
1.39228718728682
9484
1.39225541042166
9401
1.39222363355651
9152
1.39219185669136
8911
1.39216007982621
8883
1.39212830296105
8811
1.3920965260959
8601
1.39206474923075
8655
1.3920329723656
8626
1.39200119550044
8378
1.39196941863529
8435
1.39193764177014
8512
1.39190586490499
8498
1.39187408803983
8389
1.39184231117468
8403
1.39181053430953
8385
1.39177875744438
8318
1.39174698057922
8264
1.39171520371407
8396
1.39168342684892
8306
1.39165164998377
8207
1.39161987311861
8318
1.39158809625346
8403
1.39155631938831
8293
1.39152454252316
8353
1.391492765658
8287
1.39146098879285
8290
1.3914292119277
8289
1.39139743506254
8248
1.39136565819739
8377
1.39133388133224
8313
1.39130210446709
8315
1.39127032760193
8261
1.39123855073678
8129
1.39120677387163
8214
1.39117499700648
8268
1.39114322014132
8318
1.39111144327617
8309
1.39107966641102
8320
1.39104788954587
8360
1.39101611268071
8187
1.39098433581556
8190
1.39095255895041
8181
1.39092078208526
8225
1.3908890052201
8236
1.39085722835495
8333
1.3908254514898
8242
1.39079367462465
8322
1.39076189775949
8408
1.39073012089434
Cl2p
HT CP 19 Ap
2023
5
9
19
57
45
2
41
Creation
Created by : XPSUser
Date created : 09/05/2023 19:57
Computer : DESKTOP-U3MGE2F
Location
Location ID : C1
Sample : HT CP 19 Ap
Description : (47.619,16.070,-0.852)mm
Tilt : 0.00
Charge Neutraliser : On
Filament Current : 0.53A
Filament Bias : 2.02V
Charge Balance : 5.02V
Settings
Excitation
Mode : XPS - monochromatic
Tuning : Spectroscopy
Emission current : 15.00mA
Anode library : Al
ESCA modes
Collimation : Slot
Lens : Hybrid
Resolution : 20.00
Scan
Deflection : (0.000, 0.000)mm
Cl2p : 1278.690-1291.690eV, Sweeps 5
Start : 1278.690eV
End : 1291.690eV
Centre : 1285.190eV
Width : 13.000eV
Step size : 0.100eV
Number Steps : 130
Dwell time : 458ms
Sweep time : 60s
Sweeps : 5
Target quality : 200
Instrument Conditions
Work function : -4.50
Acquisition Conditions
X-ray Power : 225.00W
Quality : 6.40
XPS
6
47.6185
16.0701171875
-0.852359375
Al (mono)
1486.69
225
1E+37
1E+37
1E+37
1E+37
FAT
20
1E+37
-4.5
1E+37
1E+37
1E+37
1E+37
1E+37
Cl2p

-1
Kinetic energy
eV
1278.69
0.1
2
Intensity
d
Transmission
d
pulse counting
0.458015267175573
5
0
1E+37
1E+37
1E+37
0
262
329
408
1.34975176565477
1.35099769238123
366
1.35099769238123
379
1.35098810832949
363
1.35097852427775
384
1.35096894022601
356
1.35095935617426
349
1.35094977212252
371
1.35094018807078
408
1.35093060401904
367
1.3509210199673
337
1.35091143591555
348
1.35090185186381
359
1.35089226781207
370
1.35088268376033
375
1.35087309970859
390
1.35086351565684
359
1.3508539316051
376
1.35084434755336
376
1.35083476350162
343
1.35082517944988
360
1.35081559539813
361
1.35080601134639
359
1.35079642729465
366
1.35078684324291
350
1.35077725919117
380
1.35076767513942
375
1.35075809108768
361
1.35074850703594
360
1.3507389229842
353
1.35072933893246
371
1.35071975488071
357
1.35071017082897
363
1.35070058677723
371
1.35069100272549
356
1.35068141867375
362
1.350671834622
363
1.35066225057026
348
1.35065266651852
375
1.35064308246678
362
1.35063349841504
345
1.35062391436329
367
1.35061433031155
360
1.35060474625981
387
1.35059516220807
370
1.35058557815633
372
1.35057599410458
371
1.35056641005284
345
1.3505568260011
365
1.35054724194936
371
1.35053765789762
353
1.35052807384587
342
1.35051848979413
356
1.35050890574239
364
1.35049932169065
364
1.35048973763891
353
1.35048015358716
345
1.35047056953542
360
1.35046098548368
372
1.35045140143194
374
1.3504418173802
377
1.35043223332845
358
1.35042264927671
352
1.35041306522497
374
1.35040348117323
376
1.35039389712149
398
1.35038431306974
379
1.350374729018
361
1.35036514496626
372
1.35035556091452
389
1.35034597686278
359
1.35033639281103
376
1.35032680875929
377
1.35031722470755
364
1.35030764065581
352
1.35029805660407
383
1.35028847255232
360
1.35027888850058
341
1.35026930444884
373
1.3502597203971
369
1.35025013634536
365
1.35024055229361
381
1.35023096824187
365
1.35022138419013
356
1.35021180013839
372
1.35020221608665
376
1.3501926320349
369
1.35018304798316
380
1.35017346393142
376
1.35016387987968
397
1.35015429582794
358
1.35014471177619
365
1.35013512772445
347
1.35012554367271
342
1.35011595962097
362
1.35010637556923
363
1.35009679151748
381
1.35008720746574
386
1.350077623414
362
1.35006803936226
383
1.35005845531052
402
1.35004887125877
396
1.35003928720703
362
1.35002970315529
340
1.35002011910355
360
1.35001053505181
343
1.35000095100006
337
1.34999136694832
337
1.34998178289658
370
1.34997219884484
374
1.3499626147931
356
1.34995303074135
388
1.34994344668961
397
1.34993386263787
362
1.34992427858613
382
1.34991469453439
350
1.34990511048264
329
1.3498955264309
370
1.34988594237916
362
1.34987635832742
355
1.34986677427568
358
1.34985719022393
375
1.34984760617219
350
1.34983802212045
374
1.34982843806871
353
1.34981885401697
354
1.34980926996522
381
1.34979968591348
388
1.34979010186174
363
1.34978051781
384
1.34977093375826
357
1.34976134970651
334
1.34975176565477
Ti3s
HT CP 19 Ap
2023
5
9
19
57
45
2
41
Creation
Created by : XPSUser
Date created : 09/05/2023 19:57
Computer : DESKTOP-U3MGE2F
Location
Location ID : C1
Sample : HT CP 19 Ap
Description : (47.619,16.070,-0.852)mm
Tilt : 0.00
Charge Neutraliser : On
Filament Current : 0.53A
Filament Bias : 2.02V
Charge Balance : 5.02V
Settings
Excitation
Mode : XPS - monochromatic
Tuning : Spectroscopy
Emission current : 15.00mA
Anode library : Al
ESCA modes
Collimation : Slot
Lens : Hybrid
Resolution : 20.00
Scan
Deflection : (0.000, 0.000)mm
Ti3s : 1412.690-1442.690eV, Sweeps 5
Start : 1412.690eV
End : 1442.690eV
Centre : 1427.690eV
Width : 30.000eV
Step size : 0.100eV
Number Steps : 300
Dwell time : 199ms
Sweep time : 60s
Sweeps : 5
Target quality : 200
Instrument Conditions
Work function : -4.50
Acquisition Conditions
X-ray Power : 225.00W
Quality : 9.68
XPS
7
47.6185
16.0701171875
-0.852359375
Al (mono)
1486.69
225
1E+37
1E+37
1E+37
1E+37
FAT
20
1E+37
-4.5
1E+37
1E+37
1E+37
1E+37
1E+37
Ti3s

-1
Kinetic energy
eV
1412.69
0.1
2
Intensity
d
Transmission
d
pulse counting
0.199335548172757
5
0
1E+37
1E+37
1E+37
0
602
137
216
1.29494863949153
1.2965505499007
166
1.2965505499007
168
1.29654521019933
156
1.29653987049797
167
1.2965345307966
168
1.29652919109524
180
1.29652385139388
177
1.29651851169251
182
1.29651317199115
174
1.29650783228978
165
1.29650249258842
176
1.29649715288706
154
1.29649181318569
147
1.29648647348433
181
1.29648113378297
157
1.2964757940816
178
1.29647045438024
163
1.29646511467887
163
1.29645977497751
170
1.29645443527615
166
1.29644909557478
163
1.29644375587342
161
1.29643841617205
158
1.29643307647069
178
1.29642773676933
154
1.29642239706796
162
1.2964170573666
166
1.29641171766523
161
1.29640637796387
174
1.29640103826251
177
1.29639569856114
156
1.29639035885978
162
1.29638501915842
166
1.29637967945705
175
1.29637433975569
173
1.29636900005432
157
1.29636366035296
180
1.2963583206516
181
1.29635298095023
168
1.29634764124887
152
1.2963423015475
142
1.29633696184614
161
1.29633162214478
171
1.29632628244341
173
1.29632094274205
158
1.29631560304068
166
1.29631026333932
176
1.29630492363796
163
1.29629958393659
150
1.29629424423523
183
1.29628890453386
171
1.2962835648325
172
1.29627822513114
174
1.29627288542977
168
1.29626754572841
168
1.29626220602705
186
1.29625686632568
174
1.29625152662432
174
1.29624618692295
158
1.29624084722159
151
1.29623550752023
156
1.29623016781886
170
1.2962248281175
158
1.29621948841613
169
1.29621414871477
165
1.29620880901341
168
1.29620346931204
181
1.29619812961068
162
1.29619278990931
156
1.29618745020795
153
1.29618211050659
151
1.29617677080522
163
1.29617143110386
161
1.2961660914025
165
1.29616075170113
156
1.29615541199977
155
1.2961500722984
155
1.29614473259704
173
1.29613939289568
163
1.29613405319431
167
1.29612871349295
160
1.29612337379158
159
1.29611803409022
161
1.29611269438886
155
1.29610735468749
146
1.29610201498613
147
1.29609667528476
147
1.2960913355834
157
1.29608599588204
156
1.29608065618067
159
1.29607531647931
155
1.29606997677794
164
1.29606463707658
153
1.29605929737522
156
1.29605395767385
137
1.29604861797249
172
1.29604327827113
160
1.29603793856976
162
1.2960325988684
152
1.29602725916703
165
1.29602191946567
151
1.29601657976431
151
1.29601124006294
171
1.29600590036158
145
1.29600056066021
142
1.29599522095885
158
1.29598988125749
164
1.29598454155612
179
1.29597920185476
150
1.29597386215339
156
1.29596852245203
155
1.29596318275067
159
1.2959578430493
158
1.29595250334794
162
1.29594716364658
160
1.29594182394521
152
1.29593648424385
153
1.29593114454248
154
1.29592580484112
160
1.29592046513976
154
1.29591512543839
157
1.29590978573703
170
1.29590444603566
163
1.2958991063343
161
1.29589376663294
171
1.29588842693157
149
1.29588308723021
153
1.29587774752884
150
1.29587240782748
157
1.29586706812612
149
1.29586172842475
142
1.29585638872339
154
1.29585104902202
142
1.29584570932066
176
1.2958403696193
152
1.29583502991793
160
1.29582969021657
159
1.29582435051521
153
1.29581901081384
155
1.29581367111248
169
1.29580833141111
156
1.29580299170975
154
1.29579765200839
157
1.29579231230702
160
1.29578697260566
167
1.29578163290429
164
1.29577629320293
151
1.29577095350157
162
1.2957656138002
158
1.29576027409884
159
1.29575493439747
162
1.29574959469611
148
1.29574425499475
154
1.29573891529338
148
1.29573357559202
170
1.29572823589066
153
1.29572289618929
153
1.29571755648793
165
1.29571221678656
157
1.2957068770852
166
1.29570153738384
142
1.29569619768247
145
1.29569085798111
157
1.29568551827974
164
1.29568017857838
149
1.29567483887702
152
1.29566949917565
177
1.29566415947429
173
1.29565881977292
175
1.29565348007156
173
1.2956481403702
178
1.29564280066883
172
1.29563746096747
163
1.2956321212661
163
1.29562678156474
175
1.29562144186338
174
1.29561610216201
180
1.29561076246065
187
1.29560542275929
177
1.29560008305792
191
1.29559474335656
162
1.29558940365519
157
1.29558406395383
154
1.29557872425247
138
1.2955733845511
172
1.29556804484974
179
1.29556270514837
166
1.29555736544701
154
1.29555202574565
176
1.29554668604428
160
1.29554134634292
170
1.29553600664155
172
1.29553066694019
182
1.29552532723883
188
1.29551998753746
182
1.2955146478361
167
1.29550930813473
163
1.29550396843337
172
1.29549862873201
163
1.29549328903064
172
1.29548794932928
169
1.29548260962792
178
1.29547726992655
166
1.29547193022519
167
1.29546659052382
189
1.29546125082246
183
1.2954559111211
175
1.29545057141973
170
1.29544523171837
188
1.295439892017
169
1.29543455231564
159
[...]
Ti3p

-1
Kinetic energy
eV
1437.69
0.1
2
Intensity
d
Transmission
d
pulse counting
0.199335548172757
5
0
1E+37
1E+37
1E+37
0
602
117
331
1.29361371415055
1.29521562455972
179
1.29521562455972
181
1.29521028485836
181
1.29520494515699
200
1.29519960545563
198
1.29519426575426
182
1.2951889260529
181
1.29518358635154
161
1.29517824665017
177
1.29517290694881
191
1.29516756724745
185
1.29516222754608
176
1.29515688784472
202
1.29515154814335
190
1.29514620844199
188
1.29514086874063
194
1.29513552903926
189
1.2951301893379
189
1.29512484963653
202
1.29511950993517
191
1.29511417023381
192
1.29510883053244
207
1.29510349083108
187
1.29509815112971
200
1.29509281142835
208
1.29508747172699
206
1.29508213202562
192
1.29507679232426
184
1.29507145262289
191
1.29506611292153
194
1.29506077322017
196
1.2950554335188
185
1.29505009381744
183
1.29504475411608
190
1.29503941441471
188
1.29503407471335
193
1.29502873501198
184
1.29502339531062
211
1.29501805560926
195
1.29501271590789
183
1.29500737620653
189
1.29500203650516
215
1.2949966968038
195
1.29499135710244
190
1.29498601740107
196
1.29498067769971
198
1.29497533799834
193
1.29496999829698
193
1.29496465859562
195
1.29495931889425
193
1.29495397919289
219
1.29494863949153
179
1.29494329979016
204
1.2949379600888
201
1.29493262038743
221
1.29492728068607
208
1.29492194098471
200
1.29491660128334
191
1.29491126158198
182
1.29490592188061
192
1.29490058217925
193
1.29489524247789
196
1.29488990277652
165
1.29488456307516
183
1.29487922337379
194
1.29487388367243
179
1.29486854397107
171
1.2948632042697
176
1.29485786456834
175
1.29485252486697
164
1.29484718516561
169
1.29484184546425
189
1.29483650576288
187
1.29483116606152
179
1.29482582636016
180
1.29482048665879
182
1.29481514695743
171
1.29480980725606
188
1.2948044675547
195
1.29479912785334
189
1.29479378815197
180
1.29478844845061
171
1.29478310874924
198
1.29477776904788
185
1.29477242934652
161
1.29476708964515
170
1.29476174994379
202
1.29475641024242
184
1.29475107054106
173
1.2947457308397
189
1.29474039113833
168
1.29473505143697
144
1.29472971173561
148
1.29472437203424
170
1.29471903233288
186
1.29471369263151
177
1.29470835293015
168
1.29470301322879
175
1.29469767352742
181
1.29469233382606
175
1.29468699412469
180
1.29468165442333
166
1.29467631472197
169
1.2946709750206
166
1.29466563531924
162
1.29466029561787
152
1.29465495591651
175
1.29464961621515
151
1.29464427651378
155
1.29463893681242
176
1.29463359711105
167
1.29462825740969
165
1.29462291770833
152
1.29461757800696
156
1.2946122383056
167
1.29460689860424
166
1.29460155890287
148
1.29459621920151
158
1.29459087950014
152
1.29458553979878
171
1.29458020009742
164
1.29457486039605
153
1.29456952069469
148
1.29456418099332
155
1.29455884129196
135
1.2945535015906
161
1.29454816188923
152
1.29454282218787
158
1.2945374824865
151
1.29453214278514
169
1.29452680308378
151
1.29452146338241
154
1.29451612368105
128
1.29451078397968
144
1.29450544427832
148
1.29450010457696
154
1.29449476487559
162
1.29448942517423
147
1.29448408547287
147
1.2944787457715
148
1.29447340607014
141
1.29446806636877
147
1.29446272666741
157
1.29445738696605
153
1.29445204726468
140
1.29444670756332
145
1.29444136786195
144
1.29443602816059
144
1.29443068845923
137
1.29442534875786
135
1.2944200090565
118
1.29441466935513
133
1.29440932965377
142
1.29440398995241
135
1.29439865025104
131
1.29439331054968
135
1.29438797084832
153
1.29438263114695
146
1.29437729144559
138
1.29437195174422
128
1.29436661204286
129
1.2943612723415
130
1.29435593264013
130
1.29435059293877
146
1.2943452532374
133
1.29433991353604
123
1.29433457383468
136
1.29432923413331
141
1.29432389443195
131
1.29431855473058
120
1.29431321502922
127
1.29430787532786
127
1.29430253562649
144
1.29429719592513
149
1.29429185622377
139
1.2942865165224
145
1.29428117682104
141
1.29427583711967
154
1.29427049741831
131
1.29426515771695
120
1.29425981801558
138
1.29425447831422
140
1.29424913861285
126
1.29424379891149
124
1.29423845921013
139
1.29423311950876
147
1.2942277798074
137
1.29422244010603
142
1.29421710040467
134
1.29421176070331
143
1.29420642100194
139
1.29420108130058
144
1.29419574159921
135
1.29419040189785
136
1.29418506219649
146
1.29417972249512
133
1.29417438279376
117
1.2941690430924
127
1.29416370339103
146
1.29415836368967
148
1.2941530239883
152
1.29414768428694
131
1.29414234458558
122
1.29413700488421
153
1.29413166518285
149
1.29412632548148
131
1.29412098578012
147
1.29411564607876
148
1.29411030637739
154
1.29410496667603
144
1.29409962697466
152
1.2940942872733
147
1.29408894757194
158
1.29408360787057
166
1.29407826816921
139
1.29407292846784
151
1.29406758876648
156
1.29406224906512
163
1.29405690936375
146
1.29405156966239
169
1.29404622996103
156
1.29404089025966
156
1.2940355505583
157
1.29403021085693
161
1.29402487115557
169
1.29401953145421
152
1.29401419175284
179
1.29400885205148
179
1.29400351235011
173
1.29399817264875
180
1.29399283294739
161
1.29398749324602
170
1.29398215354466
171
1.29397681384329
162
1.29397147414193
168
1.29396613444057
173
1.2939607947392
181
1.29395545503784
164
1.29395011533648
191
1.29394477563511
185
1.29393943593375
188
1.29393409623238
179
1.29392875653102
184
1.29392341682966
192
1.29391807712829
177
1.29391273742693
186
1.29390739772556
199
1.2939020580242
202
1.29389671832284
186
1.29389137862147
199
1.29388603892011
199
1.29388069921874
176
1.29387535951738
202
1.29387001981602
198
1.29386468011465
191
1.29385934041329
186
1.29385400071192
190
1.29384866101056
175
1.2938433213092
187
1.29383798160783
184
1.29383264190647
186
1.29382730220511
195
1.29382196250374
222
1.29381662280238
203
1.29381128310101
213
1.29380594339965
234
1.29380060369829
210
1.29379526399692
203
1.29378992429556
205
1.29378458459419
218
1.29377924489283
223
1.29377390519147
228
1.2937685654901
219
1.29376322578874
256
1.29375788608737
264
1.29375254638601
242
1.29374720668465
253
1.29374186698328
259
1.29373652728192
286
1.29373118758056
265
1.29372584787919
288
1.29372050817783
271
1.29371516847646
270
1.2937098287751
294
1.29370448907374
301
1.29369914937237
314
1.29369380967101
316
1.29368846996964
299
1.29368313026828
296
1.29367779056692
325
1.29367245086555
309
1.29366711116419
306
1.29366177146282
301
1.29365643176146
300
1.2936510920601
308
1.29364575235873
309
1.29364041265737
327
1.293635072956
327
1.29362973325464
330
1.29362439355328
328
1.29361905385191
331
1.29361371415055
Ti2s
HT CP 19 Ap
2023
5
9
19
57
45
2
41
Creation
Created by : XPSUser
Date created : 09/05/2023 19:57
Computer : DESKTOP-U3MGE2F
Location
Location ID : C1
Sample : HT CP 19 Ap
Description : (47.619,16.070,-0.852)mm
Tilt : 0.00
Charge Neutraliser : On
Filament Current : 0.53A
Filament Bias : 2.02V
Charge Balance : 5.02V
Settings
Excitation
Mode : XPS - monochromatic
Tuning : Spectroscopy
Emission current : 15.00mA
Anode library : Al
ESCA modes
Collimation : Slot
Lens : Hybrid
Resolution : 20.00
Scan
Deflection : (0.000, 0.000)mm
Ti2s : 907.690-937.690eV, Sweeps 10
Start : 907.690eV
End : 937.690eV
Centre : 922.690eV
Width : 30.000eV
Step size : 0.100eV
Number Steps : 300
Dwell time : 199ms
Sweep time : 60s
Sweeps : 10
Target quality : 200
Instrument Conditions
Work function : -4.50
Acquisition Conditions
X-ray Power : 225.00W
Quality : 9.91
XPS
9
47.6185
16.0701171875
-0.852359375
Al (mono)
1486.69
225
1E+37
1E+37
1E+37
1E+37
FAT
20
1E+37
-4.5
1E+37
1E+37
1E+37
1E+37
1E+37
Ti2s

-1
Kinetic energy
eV
907.69
0.1
2
Intensity
d
Transmission
d
pulse counting
0.199335548172757
10
0
1E+37
1E+37
1E+37
0
602
8245
8818
1.39835656853096
1.40786093570082
8479
1.40786093570082
8539
1.40783040092986
8583
1.40779986615891
8573
1.40776933138795
8651
1.40773879661699
8698
1.40770826184604
8497
1.40767772707508
8549
1.40764719230412
8538
1.40761665753316
8425
1.40758612276221
8476
1.40755558799125
8506
1.40752505322029
8524
1.40749451844934
8427
1.40746398367838
8438
1.40743344890742
8555
1.40740291413646
8456
1.40737237936551
8456
1.40734184459455
8481
1.40731130982359
8454
1.40728077505264
8523
1.40725024028168
8606
1.40721970551072
8460
1.40718917073976
8457
1.40715863596881
8537
1.40712698331307
8612
1.40709520644792
8468
1.40706342958277
8447
1.40703165271762
8450
1.40699987585246
8473
1.40696809898731
8534
1.40693632212216
8471
1.40690454525701
8580
1.40687276839185
8436
1.4068409915267
8463
1.40680921466155
8533
1.4067774377964
8552
1.40674566093124
8508
1.40671388406609
8498
1.40668210720094
8591
1.40665033033579
8517
1.40661855347063
8410
1.40658677660548
8560
1.40655499974033
8447
1.40652322287517
8511
1.40649144601002
8481
1.40645966914487
8423
1.40642789227972
8525
1.40639611541456
8541
1.40636433854941
8245
1.40633256168426
8459
1.40630078481911
8478
1.40626900795395
8574
1.4062372310888
8500
1.40620545422365
8526
1.4061736773585
8607
1.40614190049334
8472
1.40611012362819
8557
1.40607834676304
8687
1.40604656989789
8520
1.40601479303273
8608
1.40598301616758
8566
1.40595123930243
8529
1.40591946243728
8561
1.40588768557212
8544
1.40585590870697
8597
1.40582413184182
8456
1.40579235497667
8466
1.40576057811151
8512
1.40572880124636
8558
1.40569702438121
8656
1.40566524751605
8496
1.4056334706509
8492
1.40560169378575
8534
1.4055699169206
8622
1.40553814005544
8483
1.40550636319029
8457
1.40547458632514
8472
1.40544280945999
8633
1.40541103259483
8506
1.40537925572968
8630
1.40534747886453
8568
1.40531570199938
8522
1.40528392513422
8536
1.40525214826907
8471
1.40522037140392
8461
1.40518859453877
8496
1.40515681767361
8555
1.40512504080846
8600
1.40509326394331
8487
1.40506148707816
8521
1.405029710213
8583
1.40499793334785
8579
1.4049661564827
8593
1.40493437961755
8526
1.40490260275239
8625
1.40487082588724
8670
1.40483904902209
8539
1.40480727215694
8567
1.40477549529178
8505
1.40474371842663
8414
1.40471194156148
8493
1.40468016469632
8521
1.40464838783117
8577
1.40461661096602
8475
1.40458483410087
8537
1.40455305723571
8541
1.40452128037056
8574
1.40448950350541
8703
1.40445772664026
8428
1.4044259497751
8540
1.40439417290995
8497
1.4043623960448
8566
1.40433061917965
8687
1.40429884231449
8362
1.40426706544934
8383
1.40423528858419
8470
1.40420351171904
8528
1.40417173485388
8488
1.40413995798873
8516
1.40410818112358
8458
1.40407640425843
8466
1.40404462739327
8597
1.40401285052812
8604
1.40398107366297
8519
1.40394929679782
8439
1.40391751993266
8551
1.40388574306751
8567
1.40385396620236
8638
1.40382218933721
8573
1.40379041247205
8477
1.4037586356069
8438
1.40372685874175
8554
1.40369508187659
8442
1.40366330501144
8563
1.40363152814629
8718
1.40359975128114
8651
1.40356797441598
8593
1.40353619755083
8563
1.40350442068568
8469
1.40347264382053
8408
1.40344086695537
8512
1.40340909009022
8484
1.40337731322507
8465
1.40334553635992
8568
1.40331375949476
8541
1.40328198262961
8651
1.40325020576446
8617
1.40321842889931
8447
1.40318665203415
8417
1.403154875169
8700
1.40312309830385
8666
1.4030913214387
8547
1.40305954457354
8632
1.40302776770839
8651
1.40299599084324
8584
1.40296421397809
8651
1.40293243711293
8589
1.40290066024778
8526
1.40286888338263
8581
1.40283710651747
8565
1.40280532965232
8470
1.40277355278717
8478
1.40274177592202
8564
1.40270999905686
8564
1.40267822219171
8584
1.40264644532656
8703
1.40261466846141
8578
1.40258289159625
8464
1.4025511147311
8762
1.40251933786595
8546
1.4024875610008
8515
1.40245578413564
8614
1.40242400727049
8700
1.40239223040534
8612
1.40236045354019
8584
1.40232867667503
8561
1.40229689980988
8720
1.40226512294473
8818
1.40223334607958
8763
1.40220156921442
8741
1.40216979234927
8575
1.40213801548412
8591
1.40210623861897
8613
1.40207446175381
8690
1.40204268488866
8691
1.40201090802351
8692
1.40197913115836
8663
1.4019473542932
8636
1.40191557742805
8563
1.4018838005629
8587
1.40185202369774
8718
1.40182024683259
8784
1.40178846996744
8613
1.40175669310229
8580
1.40172491623713
8508
1.40169313937198
8685
1.40166136250683
8720
1.40162958564168
8755
1.40159780877652
8806
1.40156603191137
8607
1.40153425504622
8695
1.40150247818107
8654
1.40147070131591
8630
1.40143892445076
8614
1.40140714758561
8585
1.40137537072046
8597
1.4013435938553
8636
1.40131181699015
8719
1.401280040125
8608
1.40124826325985
8682
1.40121648639469
8655
1.40118470952954
8491
1.40115293266439
8660
1.40112115579924
8697
1.40108937893408
8704
1.40105760206893
8611
1.40102582520378
8640
1.40099404833863
8650
1.40096227147347
8724
1.40093049460832
8684
1.40089871774317
8620
1.40086694087801
8555
1.40083516401286
8508
1.40080338714771
8568
1.40077161028256
8643
1.4007398334174
8688
1.40070805655225
8581
1.4006762796871
8564
1.40064450282195
8683
1.40061272595679
8696
1.40058094909164
8700
1.40054917222649
8617
1.40051739536134
8633
1.40048561849618
8544
1.40045384163103
8636
1.40042206476588
8706
1.40039028790073
8700
1.40035851103557
8815
1.40032673417042
8599
1.40029495730527
8583
1.40026318044012
8751
1.40023140357496
8706
1.40019962670981
8575
1.40016784984466
8616
1.40013607297951
8600
1.40010429611435
8528
1.4000725192492
8617
1.40004074238405
8603
1.40000896551889
8728
1.39997718865374
8671
1.39994541178859
8618
1.39991363492344
8539
1.39988185805828
8637
1.39985008119313
8638
1.39981830432798
8526
1.39978652746283
8598
1.39975475059767
8492
1.39972297373252
8556
1.39969119686737
8701
1.39965942000222
8745
1.39962764313706
8661
1.39959586627191
8579
1.39956408940676
8608
1.39953231254161
8529
1.39950053567645
8556
1.3994687588113
8500
1.39943698194615
8680
1.399405205081
8747
1.39937342821584
8774
1.39934165135069
8592
1.39930987448554
8596
1.39927809762039
8520
1.39924632075523
8561
1.39921454389008
8601
1.39918276702493
8609
1.39915099015978
8694
1.39911921329462
8609
1.39908743642947
8602
1.39905565956432
8614
1.39902388269916
8665
1.39899210583401
8676
1.39896032896886
8650
1.39892855210371
8640
1.39889677523855
8565
1.3988649983734
8478
1.39883322150825
8600
1.3988014446431
8611
1.39876966777794
8521
1.39873789091279
8510
1.39870611404764
8435
1.39867433718249
8567
1.39864256031733
8560
1.39861078345218
8652
1.39857900658703
8520
1.39854722972188
8521
1.39851545285672
8539
1.39848367599157
8754
1.39845189912642
8661
1.39842012226127
8450
1.39838834539611
8593
1.39835656853096
Ti2p
HT CP 19 Ap
2023
5
9
19
57
45
2
41
Creation
Created by : XPSUser
Date created : 09/05/2023 19:57
Computer : DESKTOP-U3MGE2F
Location
Location ID : C1
Sample : HT CP 19 Ap
Description : (47.619,16.070,-0.852)mm
Tilt : 0.00
Charge Neutraliser : On
Filament Current : 0.53A
Filament Bias : 2.02V
Charge Balance : 5.02V
Settings
Excitation
Mode : XPS - monochromatic
Tuning : Spectroscopy
Emission current : 15.00mA
Anode library : Al
ESCA modes
Collimation : Slot
Lens : Hybrid
Resolution : 20.00
Scan
Deflection : (0.000, 0.000)mm
Ti2p : 1016.690-1036.690eV, Sweeps 10
Start : 1016.690eV
End : 1036.690eV
Centre : 1026.690eV
Width : 20.000eV
Step size : 0.100eV
Number Steps : 200
Dwell time : 299ms
Sweep time : 60s
Sweeps : 10
Target quality : 200
Instrument Conditions
Work function : -4.50
Acquisition Conditions
X-ray Power : 225.00W
Quality : 6.36
XPS
10
47.6185
16.0701171875
-0.852359375
Al (mono)
1486.69
225
1E+37
1E+37
1E+37
1E+37
FAT
20
1E+37
-4.5
1E+37
1E+37
1E+37
1E+37
1E+37
Ti2p

-1
Kinetic energy
eV
1016.69
0.1
2
Intensity
d
Transmission
d
pulse counting
0.298507462686567
10
0
1E+37
1E+37
1E+37
0
402
12489
12982
1.34818394035546
1.35812104677082
12600
1.35812104677082
12668
1.35807136123875
12829
1.35802167570667
12820
1.35797199017459
12742
1.35792230464252
12697
1.35787261911044
12700
1.35782293357836
12489
1.35777324804629
12679
1.35772356251421
12755
1.35767387698213
12590
1.35762419145005
12865
1.35757450591798
12771
1.3575248203859
12559
1.35747513485382
12749
1.35742544932175
12752
1.35737576378967
12860
1.35732607825759
12724
1.35727639272552
12712
1.35722670719344
12800
1.35717702166136
12673
1.35712733612929
12571
1.35707765059721
12796
1.35702796506513
12683
1.35697827953306
12568
1.35692859400098
12728
1.3568789084689
12724
1.35682922293683
12561
1.35677953740475
12714
1.35672985187267
12699
1.3566801663406
12634
1.35663048080852
12867
1.35658079527644
12790
1.35653110974437
12598
1.35648142421229
12821
1.35643173868021
12746
1.35638205314813
12632
1.35633236761606
12874
1.35628268208398
12917
1.3562329965519
12844
1.35618331101983
12831
1.35613362548775
12635
1.35608393995567
12627
1.3560342544236
12803
1.35598456889152
12979
1.35593488335944
12825
1.35588519782737
12722
1.35583551229529
12840
1.35578582676321
12779
1.35573614123114
12621
1.35568645569906
12770
1.35563677016698
12820
1.35558708463491
12741
1.35553739910283
12700
1.35548771357075
12814
1.35543802803868
12717
1.3553883425066
12734
1.35533865697452
12643
1.35528897144245
12748
1.35523928591037
12757
1.35518960037829
12709
1.35513991484622
12584
1.35509022931414
12731
1.35504054378206
12838
1.35499085824998
12827
1.35494117271791
12850
1.35489148718583
12839
1.35484180165375
12753
1.35479211612168
12722
1.3547424305896
12787
1.35469274505752
12764
1.35464305952545
12752
1.35459337399337
12798
1.35454368846129
12721
1.35449400292922
12884
1.35444431739714
12645
1.35439463186506
12804
1.35434494633299
12776
1.35429526080091
12909
1.35424557526883
12712
1.35419588973676
12717
1.35414620420468
12520
1.3540965186726
12820
1.35404683314053
12892
1.35399714760845
12744
1.35394746207637
12819
1.3538977765443
12851
1.35384809101222
12758
1.35379840548014
12714
1.35374871994806
12888
1.35369903441599
12866
1.35364934888391
12901
1.35359966335183
12836
1.35354997781976
12659
1.35350029228768
12830
1.3534506067556
12762
1.35340092122353
12774
1.35335123569145
12831
1.35330155015937
12770
1.3532518646273
12840
1.35320217909522
12857
1.35315249356314
12902
1.35310280803107
12752
1.35305312249899
12851
1.35300343696691
12619
1.35295375143484
12791
1.35290406590276
12728
1.35285438037068
12803
1.35280469483861
12871
1.35275500930653
12902
1.35270532377445
12682
1.35265563824238
12689
1.3526059527103
12786
1.35255626717822
12752
1.35250658164615
12641
1.35245689611407
12571
1.35240721058199
12635
1.35235752504991
12720
1.35230783951784
12840
1.35225815398576
12695
1.35220846845368
12775
1.35215878292161
12764
1.35210909738953
12770
1.35205941185745
12576
1.35200972632538
12614
1.3519600407933
12844
1.35191035526122
12684
1.35186066972915
12693
1.35181098419707
12718
1.35176129866499
12706
1.35171161313292
12656
1.35166192760084
12809
1.35161224206876
12910
1.35156255653669
12860
1.35151287100461
12839
1.35146318547253
12877
1.35141349994046
12862
1.35136381440838
12846
1.3513141288763
12690
1.35126444334423
12960
1.35121475781215
12725
1.35116507228007
12642
1.35111538674799
12730
1.35106570121592
12693
1.35101601568384
12802
1.35096633015176
12798
1.35091664461969
12825
1.35086695908761
12850
1.35081727355553
12837
1.35076758802346
12876
1.35071790249138
12942
1.3506682169593
12977
1.35061853142723
12798
1.35056884589515
12805
1.35051916036307
12906
1.350469474831
12930
1.35041978929892
12866
1.35037010376684
12750
1.35032041823477
12790
1.35027073270269
12803
1.35022104717061
12894
1.35017136163854
12967
1.35012167610646
12766
1.35007199057438
12771
1.35002230504231
12854
1.34997261951023
12827
1.34992293397815
12856
1.34987324844607
12698
1.349823562914
12741
1.34977387738192
12810
1.34972419184984
12657
1.34967450631777
12783
1.34962482078569
12982
1.34957513525361
12917
1.34952544972154
12792
1.34947576418946
12888
1.34942607865738
12853
1.34937639312531
12867
1.34932670759323
12833
1.34927702206115
12745
1.34922733652908
12826
1.349177650997
12699
1.34912796546492
12729
1.34907827993285
12793
1.34902859440077
12853
1.34897890886869
12824
1.34892922333662
12668
1.34887953780454
12954
1.34882985227246
12927
1.34878016674039
12819
1.34873048120831
12792
1.34868079567623
12813
1.34863111014416
12696
1.34858142461208
12666
1.34853173908
12888
1.34848205354792
12963
1.34843236801585
12819
1.34838268248377
12829
1.34833299695169
12909
1.34828331141962
12759
1.34823362588754
12912
1.34818394035546
end of experiment