File: XPS/Casa format/MX-HT 0p5 20Ap location H1 in image.vms
VAMAS Surface Chemical Analysis Standard Data Transfer Format 1988 May 4
Not specified
MI-600-BE9240AA
XPSUser
KTH Amireza_C-paper-Mxene-sample sent on 17 April2023.experiment
0
NORM
REGULAR
1
4
Index
d
PositionX [mm]
n
PositionY [mm]
n
PositionZ [mm]
n
0
0
0
0
10
wide
MX-HT 0p5 20Ap
2023
5
9
14
2
1
2
39
Creation
Created by : XPSUser
Date created : 09/05/2023 14:02
Computer : DESKTOP-U3MGE2F
Location
Location ID : H1
Sample : MX-HT 0p5 20Ap
Description : (24.612,15.667,-0.853)mm
Tilt : 0.00
Charge Neutraliser : On
Filament Current : 0.53A
Filament Bias : 2.02V
Charge Balance : 5.02V
Settings
Excitation
Mode : XPS - monochromatic
Tuning : Spectroscopy
Emission current : 15.00mA
Anode library : Al
ESCA modes
Collimation : Slot
Lens : Hybrid
Resolution : 160.00
Scan
Deflection : (0.000, 0.000)mm
wide : 286.690-1491.690eV, Sweeps 5
Start : 286.690eV
End : 1491.690eV
Centre : 889.190eV
Width : 1205.000eV
Step size : 1.000eV
Number Steps : 1205
Dwell time : 100ms
Sweep time : 120s
Sweeps : 5
Instrument Conditions
Work function : -4.50
Acquisition Conditions
X-ray Power : 225.00W
XPS
1
24.612
15.6667890625
-0.85346875
Al (mono)
1486.69
225
1E+37
1E+37
1E+37
1E+37
FAT
160
1E+37
-4.5
1E+37
1E+37
1E+37
1E+37
1E+37
wide

-1
Kinetic energy
eV
286.69
1
2
Intensity
d
Transmission
d
pulse counting
0.0995024875621891
0
1E+37
0
7
31.1899525550317
85947
86288
85804
86149
86656
86984
87147
87249
87393
87266
88074
88401
88360
88471
88906
89168
89255
89607
89747
90184
90388
90335
90923
91098
91681
91317
91718
92196
92611
92527
92579
93007
93439
93772
94211
94147
94402
95377
95112
95258
95850
96634
97222
97579
97774
98272
98930
98763
98369
99154
98493
98597
99018
99114
99422
99192
98863
98826
99468
99909
100322
100921
101325
101783
103012
104131
105498
106309
106973
107015
106464
106255
106625
106689
107118
108282
108898
108990
108248
107566
106524
105803
105940
106012
106555
107005
107719
109328
110736
112235
113614
115805
118504
120938
123376
126839
128967
127696
124132
120791
119163
117511
111456
101529
93116
88061
85155
82757
81258
80163
78660
77364
76905
76440
75752
75318
75384
75436
75371
75711
76405
76412
77277
78462
79636
80111
81874
83743
86312
89231
91467
92432
91175
88926
86533
82495
76087
71637
69493
68238
67250
66667
66292
65779
65586
65404
65558
65540
66004
65750
65281
65427
66002
65907
66178
66561
66514
67202
67017
67222
67608
68042
68419
68612
68916
69068
68299
67534
67404
66764
66658
66766
66470
66795
66707
66929
66743
66588
66626
67264
67223
66931
67354
67579
67475
67853
67767
67405
67476
67877
68229
68393
68714
68520
68633
68818
68945
68959
69435
69509
69719
69731
70370
71006
71573
71966
72534
72566
72642
72023
71219
69941
69882
70098
69848
69469
69288
69193
69599
69994
71023
72502
74235
76376
78753
80859
81786
82637
82970
79711
73353
69311
67241
65939
64712
64185
63666
63130
62660
62442
62335
61902
62028
62048
61975
62230
62270
62342
62316
62387
62409
62512
62676
62307
62641
62940
63071
62852
63365
63197
62892
63766
63771
63351
63607
63840
63658
63673
64367
64226
63903
64186
64370
64544
64853
64812
64676
64766
65154
65071
65238
65205
65305
65276
65104
65713
65877
65825
65855
66006
65751
65770
66063
66548
66267
66547
66759
66810
67053
66896
67093
67020
66851
67084
67315
67757
67550
67431
67570
67830
68062
67705
68129
68041
68697
68872
68542
69146
69288
69603
69638
69952
70230
69675
70568
70921
70612
70869
70715
70331
70209
69853
70040
69867
70071
70292
70022
70856
71184
71402
71525
72349
72650
73202
74160
75408
76044
75502
73923
71967
71645
71775
71830
72119
72697
72623
72033
71417
70955
71321
71476
72145
71857
72261
73417
74440
75750
76617
77370
78667
81523
84790
91100
91123
80133
71740
69725
69015
68928
68731
68762
68573
68664
68561
69517
69385
69226
69511
69472
69408
68728
69037
69084
68707
69007
68910
69332
69157
69325
69161
69530
70019
70008
69957
69871
69971
70322
70891
70645
70483
70432
70881
70943
71004
70705
70609
71077
71089
71584
71158
71406
71802
71425
71692
71809
71892
72093
72139
72050
72289
72069
72344
72443
72627
73178
73422
73345
73245
73287
73242
73495
73743
73629
73725
73986
74029
73663
74056
74386
74482
74337
74662
74616
74129
74686
74699
74810
74946
75315
75557
75307
75565
75813
76269
76014
76051
76331
76315
76441
76510
76271
76094
76542
76298
76153
76245
75951
76463
76631
76573
76504
77472
77298
77508
77775
77670
78416
78634
78695
78797
79986
79394
79822
79558
79437
78811
78717
78313
78285
78140
77906
77987
77828
77947
77961
77904
78378
78824
78633
78738
79239
80027
81518
85314
93991
113503
114398
92625
79949
77245
76125
76282
76554
76806
77064
76511
76661
77025
77026
76973
77101
77410
77369
77119
77393
77321
77991
77676
77841
77967
78167
78239
78424
78649
78651
78438
78970
79222
78973
79214
79561
79727
79777
79652
79872
79987
80025
80462
80113
79723
80441
80633
81042
81021
81396
81584
81499
81026
81895
81819
81705
82267
82195
82086
82435
82764
82503
82798
83300
83402
82913
83588
83797
83903
84273
84274
84582
84881
85014
85105
85655
85446
85515
85426
85508
85484
85888
85854
85617
85606
86336
86151
86011
86680
87008
87423
87913
87571
88586
89129
88935
90078
90829
90561
90778
91089
91352
91322
91702
92518
92540
92753
92918
93077
92930
93182
92849
92197
92109
91490
91375
92367
92837
95143
97838
101311
104219
107372
106836
104718
99543
93223
88417
85045
83168
81777
81006
80075
79261
78539
77990
78072
77966
78368
77946
78075
78117
77966
77418
76314
76283
75702
75216
75295
75493
77029
80398
86885
96202
106395
116505
110778
87150
73624
71217
70493
70466
70056
69779
69974
70214
70365
70272
70136
70652
71083
71032
71442
71762
71718
71964
72152
72599
72889
72396
72797
72642
72244
72151
71947
71676
71527
71570
71139
71198
71112
71953
71752
71855
72937
73331
74388
75330
76349
77616
78536
79198
80430
80992
81956
82649
82784
83664
84257
83629
83506
83603
83300
82636
82643
81220
80956
80138
80046
81711
85881
90292
97307
107741
114314
109266
103846
103901
112432
132328
140487
100851
51495
33442
30498
29152
28530
28433
28113
27753
27408
27611
27628
27698
27660
27580
27628
27633
27527
27540
27476
27478
27416
27441
27467
27376
27408
27619
27533
27592
27374
27574
27544
27546
27737
27719
27578
27580
27541
27548
27792
27810
27705
28089
27700
27527
27391
27714
27494
27458
27694
27762
27875
28397
28773
28591
28440
27874
27919
28082
27765
27671
27726
27693
27461
27525
27493
27535
27718
27643
27800
27760
27652
27742
27667
27600
27771
27872
27666
27720
27746
27760
27754
27825
27967
27926
27981
27804
28095
27956
27720
27694
27780
27741
27938
27851
27870
27862
28004
28042
28268
27999
28230
28216
28310
28289
28212
28343
28441
28663
28143
28183
28304
28363
28271
28502
28206
28228
27999
28140
28002
27999
27848
27629
27392
27381
27491
27862
27859
27598
27941
28058
28351
28825
28944
29085
29656
29617
29929
29836
29787
29824
30076
29908
29862
29444
28552
27996
27172
26054
25120
24121
22999
22112
20842
20024
19685
19306
19278
19528
20155
21240
22514
24190
26126
27343
28025
28774
31613
40858
66473
108665
83235
41275
30151
17466
9324
8030
7826
7745
7571
7577
7745
8104
8633
9261
9245
8432
7746
7410
7334
7208
7251
7178
7285
7251
7089
7287
7211
7194
7103
7163
7297
7218
7294
7361
7405
7259
7434
7401
7404
7438
7411
7323
7235
7251
7341
7202
7286
7453
7351
7358
7431
7265
7390
7489
7536
7573
7499
7615
7728
7694
7756
7655
7663
7813
7637
7816
7577
7565
7618
7698
7583
7702
7764
7577
7638
7683
7682
7610
7677
7875
7981
8425
9546
10703
11808
10694
8505
7595
7485
7411
7376
7479
7414
7357
7358
7352
7393
7538
7459
7526
7462
7542
7656
7533
7556
7654
7669
7678
7699
7601
7607
7659
7621
7552
7627
7687
7715
7708
7753
7721
7763
7692
7874
7871
7732
7853
7865
8040
8164
8332
8568
8530
8346
8179
8109
8102
7974
7966
8069
8115
8098
8161
8175
8203
8328
8265
8150
8231
8202
8412
8354
8333
8453
8456
8423
8479
8501
8524
8603
8616
8645
8543
8671
8571
8662
8595
8493
8719
8832
8800
8800
8843
8943
9030
8977
9018
8973
9140
9144
9269
9664
9617
9452
9227
9023
9063
9195
9204
9255
9207
9134
9182
9259
9480
9831
9819
10028
10069
10069
10148
10349
10234
10019
10058
10046
10040
10014
9890
9913
9693
9588
9548
9328
9289
9172
9272
9516
9696
10096
10949
11857
13084
14515
15768
15762
14091
11660
9949
9209
8966
8738
8800
8860
8765
8804
8811
8416
8324
8120
7954
8069
8164
8644
9088
10220
12182
14547
17177
19767
20276
15410
8472
5173
4638
4553
3917
3225
2863
2891
2963
3287
3741
3864
3428
2894
2575
2466
2314
2157
2053
2151
2264
2408
2381
2347
2532
2404
2458
2680
2503
1906
1310
739
330
132
35
9
9
7
31.1899525550317
C 1s
MX-HT 0p5 20Ap
2023
5
9
17
5
6
2
41
Creation
Created by : XPSUser
Date created : 09/05/2023 17:05
Computer : DESKTOP-U3MGE2F
Location
Location ID : H1
Sample : MX-HT 0p5 20Ap
Description : (24.612,15.667,-0.853)mm
Tilt : 0.00
Charge Neutraliser : On
Filament Current : 0.53A
Filament Bias : 2.02V
Charge Balance : 5.02V
Settings
Excitation
Mode : XPS - monochromatic
Tuning : Spectroscopy
Emission current : 15.00mA
Anode library : Al
ESCA modes
Collimation : Slot
Lens : Hybrid
Resolution : 20.00
Scan
Deflection : (0.000, 0.000)mm
C 1s : 1191.690-1209.690eV, Sweeps 1
Start : 1191.690eV
End : 1209.690eV
Centre : 1200.690eV
Width : 18.000eV
Step size : 0.100eV
Number Steps : 180
Dwell time : 331ms
Sweep time : 60s
Sweeps : 1
Target quality : 200
Instrument Conditions
Work function : -4.50
Acquisition Conditions
X-ray Power : 225.00W
Quality : 241.28
XPS
2
24.612
15.6667890625
-0.85346875
Al (mono)
1486.69
225
1E+37
1E+37
1E+37
1E+37
FAT
20
1E+37
-4.5
1E+37
1E+37
1E+37
1E+37
1E+37
C
1s
-1
Kinetic energy
eV
1191.69
0.1
2
Intensity
d
Transmission
d
pulse counting
0.331492
1
0
1E+37
1E+37
1E+37
0
362
220
12446
1.33571680812406
1.34279197206053
717
1.33571680812406
746
1.33575611459037
701
1.33579542105669
691
1.335834727523
707
1.33587403398932
723
1.33591334045563
710
1.33595264692194
723
1.33599195338826
730
1.33603125985457
744
1.33607056632088
755
1.3361098727872
722
1.33614917925351
751
1.33618848571983
732
1.33622779218614
720
1.33626709865245
745
1.33630640511877
784
1.33634571158508
759
1.33638501805139
754
1.33642432451771
762
1.33646363098402
752
1.33650293745034
756
1.33654224391665
776
1.33658155038296
797
1.33662085684928
820
1.33666016331559
833
1.3366994697819
801
1.33673877624822
800
1.33677808271453
808
1.33681738918085
801
1.33685669564716
809
1.33689600211347
810
1.33693530857979
846
1.3369746150461
838
1.33701392151241
897
1.33705322797873
886
1.33709253444504
900
1.33713184091135
952
1.33717114737767
930
1.33721045384398
864
1.3372497603103
901
1.33728906677661
937
1.33732837324292
908
1.33736767970924
954
1.33740698617555
922
1.33744629264186
946
1.33748559910818
927
1.33752490557449
932
1.33756421204081
961
1.33760351850712
912
1.33764282497343
940
1.33768213143975
926
1.33772143790606
886
1.33776074437237
882
1.33780005083869
913
1.337839357305
940
1.33787866377132
926
1.33791797023763
931
1.33795727670394
890
1.33799658317026
912
1.33803588963657
928
1.33807519610288
954
1.3381145025692
939
1.33815380903551
908
1.33819311550182
923
1.33823242196814
962
1.33827172843445
964
1.33831103490077
924
1.33835034136708
885
1.33838964783339
910
1.33842895429971
936
1.33846826076602
939
1.33850756723233
898
1.33854687369865
975
1.33858618016496
956
1.33862548663128
923
1.33866479309759
936
1.3387040995639
923
1.33874340603022
944
1.33878271249653
978
1.33882201896284
998
1.33886132542916
956
1.33890063189547
971
1.33893993836179
1057
1.3389792448281
1053
1.33901855129441
1113
1.33905785776073
1150
1.33909716422704
1152
1.33913647069335
1226
1.33917577715967
1291
1.33921508362598
1295
1.3392543900923
1324
1.33929369655861
1394
1.33933300302492
1420
1.33937230949124
1482
1.33941161595755
1503
1.33945092242386
1596
1.33949022889018
1758
1.33952953535649
1830
1.3395688418228
1905
1.33960814828912
2066
1.33964745475543
2053
1.33968676122175
2341
1.33972606768806
2517
1.33976537415437
2765
1.33980468062069
3204
1.339843987087
3980
1.33988329355331
5113
1.33992260001963
6802
1.33996190648594
9072
1.34000121295226
11266
1.34004051941857
12446
1.34007982588488
11495
1.3401191323512
8681
1.34015843881751
5484
1.34019774528382
3421
1.34023705175014
2277
1.34027635821645
1591
1.34031566468277
1271
1.34035497114908
1050
1.34039427761539
894
1.34043358408171
793
1.34047289054802
761
1.34051219701433
660
1.34055150348065
618
1.34059080994696
607
1.34063011641328
611
1.34066942287959
608
1.3407087293459
654
1.34074803581222
649
1.34078734227853
707
1.34082664874484
781
1.34086595521116
965
1.34090526167747
1235
1.34094456814378
1658
1.3409838746101
2097
1.34102318107641
2442
1.34106248754273
2331
1.34110179400904
1954
1.34114110047535
1376
1.34118040694167
946
1.34121971340798
619
1.34125901987429
454
1.34129832634061
395
1.34133763280692
323
1.34137693927324
288
1.34141624573955
293
1.34145555220586
317
1.34149485867218
284
1.34153416513849
271
1.3415734716048
252
1.34161277807112
267
1.34165208453743
261
1.34169139100375
256
1.34173069747006
266
1.34177000393637
249
1.34180931040269
252
1.341848616869
261
1.34188792333531
233
1.34192722980163
239
1.34196653626794
257
1.34200584273426
243
1.34204514920057
238
1.34208445566688
244
1.3421237621332
242
1.34216306859951
237
1.34220237506582
251
1.34224168153214
266
1.34228098799845
258
1.34232029446476
252
1.34235960093108
245
1.34239890739739
272
1.34243821386371
229
1.34247752033002
244
1.34251682679633
265
1.34255613326265
260
1.34259543972896
264
1.34263474619527
242
1.34267405266159
221
1.3427133591279
220
1.34275266559422
229
1.34279197206053
Cl2s
MX-HT 0p5 20Ap
2023
5
9
17
5
6
2
41
Creation
Created by : XPSUser
Date created : 09/05/2023 17:05
Computer : DESKTOP-U3MGE2F
Location
Location ID : H1
Sample : MX-HT 0p5 20Ap
Description : (24.612,15.667,-0.853)mm
Tilt : 0.00
Charge Neutraliser : On
Filament Current : 0.53A
Filament Bias : 2.02V
Charge Balance : 5.02V
Settings
Excitation
Mode : XPS - monochromatic
Tuning : Spectroscopy
Emission current : 15.00mA
Anode library : Al
ESCA modes
Collimation : Slot
Lens : Hybrid
Resolution : 20.00
Scan
Deflection : (0.000, 0.000)mm
Cl2s : 1201.690-1231.690eV, Sweeps 1
Start : 1201.690eV
End : 1231.690eV
Centre : 1216.690eV
Width : 30.000eV
Step size : 0.100eV
Number Steps : 300
Dwell time : 199ms
Sweep time : 60s
Sweeps : 1
Target quality : 200
Instrument Conditions
Work function : -4.50
Acquisition Conditions
X-ray Power : 225.00W
Quality : 367.32
XPS
3
24.612
15.6667890625
-0.85346875
Al (mono)
1486.69
225
1E+37
1E+37
1E+37
1E+37
FAT
20
1E+37
-4.5
1E+37
1E+37
1E+37
1E+37
1E+37
Cl2s

-1
Kinetic energy
eV
1201.69
0.1
2
Intensity
d
Transmission
d
pulse counting
0.199335548172757
1
0
1E+37
1E+37
1E+37
0
602
112
7308
1.33964745475543
1.35143939464955
1223
1.33964745475543
1309
1.33968676122175
1408
1.33972606768806
1588
1.33976537415437
1803
1.33980468062069
2115
1.339843987087
2596
1.33988329355331
3349
1.33992260001963
4400
1.33996190648594
5937
1.34000121295226
7111
1.34004051941857
7308
1.34007982588488
6311
1.3401191323512
4659
1.34015843881751
2929
1.34019774528382
1846
1.34023705175014
1271
1.34027635821645
966
1.34031566468277
708
1.34035497114908
584
1.34039427761539
518
1.34043358408171
466
1.34047289054802
428
1.34051219701433
402
1.34055150348065
380
1.34059080994696
400
1.34063011641328
376
1.34066942287959
367
1.3407087293459
390
1.34074803581222
402
1.34078734227853
447
1.34082664874484
496
1.34086595521116
602
1.34090526167747
786
1.34094456814378
1059
1.3409838746101
1362
1.34102318107641
1470
1.34106248754273
1382
1.34110179400904
1121
1.34114110047535
783
1.34118040694167
504
1.34121971340798
356
1.34125901987429
262
1.34129832634061
223
1.34133763280692
184
1.34137693927324
178
1.34141624573955
170
1.34145555220586
152
1.34149485867218
158
1.34153416513849
161
1.3415734716048
152
1.34161277807112
156
1.34165208453743
166
1.34169139100375
161
1.34173069747006
161
1.34177000393637
148
1.34180931040269
148
1.341848616869
147
1.34188792333531
145
1.34192722980163
149
1.34196653626794
147
1.34200584273426
146
1.34204514920057
158
1.34208445566688
136
1.3421237621332
142
1.34216306859951
142
1.34220237506582
137
1.34224168153214
138
1.34228098799845
155
1.34232029446476
157
1.34235960093108
154
1.34239890739739
141
1.34243821386371
152
1.34247752033002
141
1.34251682679633
143
1.34255613326265
140
1.34259543972896
147
1.34263474619527
143
1.34267405266159
148
1.3427133591279
142
1.34275266559422
131
1.34279197206053
127
1.34283127852684
133
1.34287058499316
151
1.34290989145947
137
1.34294919792578
147
1.3429885043921
157
1.34302781085841
139
1.34306711732473
129
1.34310642379104
130
1.34314573025735
134
1.34318503672367
151
1.34322434318998
133
1.34326364965629
143
1.34330295612261
140
1.34334226258892
163
1.34338156905524
145
1.34342087552155
140
1.34346018198786
167
1.34349948845418
141
1.34353879492049
151
1.3435781013868
147
1.34361740785312
150
1.34365671431943
162
1.34369602078574
157
1.34373532725206
153
1.34377463371837
157
1.34381394018469
144
1.343853246651
141
1.34389255311731
149
1.34393185958363
134
1.34397116604994
155
1.34401047251625
146
1.34404977898257
141
1.34408908544888
127
1.3441283919152
145
1.34416769838151
148
1.34420700484782
134
1.34424631131414
145
1.34428561778045
159
1.34432492424676
152
1.34436423071308
154
1.34440353717939
156
1.34444284364571
158
1.34448215011202
147
1.34452145657833
124
1.34456076304465
152
1.34460006951096
155
1.34463937597727
164
1.34467868244359
151
1.3447179889099
150
1.34475729537622
157
1.34479660184253
160
1.34483590830884
178
1.34487521477516
146
1.34491452124147
164
1.34495382770778
166
1.3449931341741
163
1.34503244064041
177
1.34507174710672
163
1.34511105357304
162
1.34515036003935
184
1.34518966650567
186
1.34522897297198
172
1.34526827943829
173
1.34530758590461
168
1.34534689237092
170
1.34538619883723
196
1.34542550530355
180
1.34546481176986
197
1.34550411823618
191
1.34554342470249
204
1.3455827311688
191
1.34562203763512
188
1.34566134410143
195
1.34570065056774
185
1.34573995703406
190
1.34577926350037
184
1.34581856996669
183
1.345857876433
207
1.34589718289931
179
1.34593648936563
192
1.34597579583194
182
1.34601510229825
177
1.34605440876457
159
1.34609371523088
156
1.34613302169719
167
1.34617232816351
169
1.34621163462982
167
1.34625094109614
154
1.34629024756245
165
1.34632955402876
150
1.34636886049508
158
1.34640816696139
133
1.3464474734277
155
1.34648677989402
150
1.34652608636033
150
1.34656539282665
139
1.34660469929296
148
1.34664400575927
149
1.34668331222559
150
1.3467226186919
156
1.34676192515821
158
1.34680123162453
155
1.34684053809084
140
1.34687984455716
157
1.34691915102347
149
1.34695845748978
142
1.3469977639561
145
1.34703707042241
146
1.34707637688872
161
1.34711568335504
152
1.34715498982135
133
1.34719429628767
144
1.34723360275398
145
1.34727290922029
146
1.34731221568661
145
1.34735152215292
141
1.34739082861923
149
1.34743013508555
160
1.34746944155186
154
1.34750874801817
128
1.34754805448449
127
1.3475873609508
133
1.34762666741712
135
1.34766597388343
159
1.34770528034974
144
1.34774458681606
158
1.34778389328237
144
1.34782319974868
132
1.347862506215
123
1.34790181268131
119
1.34794111914763
131
1.34798042561394
142
1.34801973208025
147
1.34805903854657
153
1.34809834501288
139
1.34813765147919
146
1.34817695794551
139
1.34821626441182
138
1.34825557087814
133
1.34829487734445
131
1.34833418381076
131
1.34837349027708
142
1.34841279674339
140
1.3484521032097
151
1.34849140967602
159
1.34853071614233
144
1.34857002260865
136
1.34860932907496
130
1.34864863554127
130
1.34868794200759
129
1.3487272484739
135
1.34876655494021
138
1.34880586140653
133
1.34884516787284
135
1.34888447433916
140
1.34892378080547
138
1.34896308727178
146
1.3490023937381
143
1.34904170020441
125
1.34908100667072
134
1.34912031313704
150
1.34915961960335
152
1.34919892606966
133
1.34923823253598
132
1.34927753900229
145
1.34931684546861
133
1.34935615193492
136
1.34939545840123
129
1.34943476486755
133
1.34947407133386
144
1.34951337780017
163
1.34955268426649
132
1.3495919907328
132
1.34963129719912
143
1.34967060366543
138
1.34970991013174
121
1.34974921659806
146
1.34978852306437
145
1.34982782953068
168
1.349867135997
157
1.34990644246331
169
1.34994574892963
158
1.34998505539594
145
1.35002436186225
145
1.35006366832857
154
1.35010297479488
146
1.35014228126119
144
1.35018158772751
142
1.35022089419382
142
1.35026020066013
147
1.35029950712645
139
1.35033881359276
150
1.35037812005908
138
1.35041742652539
131
1.3504567329917
151
1.35049603945802
147
1.35053534592433
135
1.35057465239064
151
1.35061395885696
129
1.35065326532327
143
1.35069257178959
146
1.3507318782559
149
1.35077118472221
149
1.35081049118853
139
1.35084979765484
154
1.35088910412115
135
1.35092841058747
112
1.35096771705378
138
1.3510070235201
156
1.35104632998641
144
1.35108563645272
142
1.35112494291904
144
1.35116424938535
137
1.35120355585166
145
1.35124286231798
135
1.35128216878429
131
1.35132147525061
140
1.35136078171692
139
1.35140008818323
136
1.35143939464955
Ti2p
MX-HT 0p5 20Ap
2023
5
9
17
5
6
2
41
Creation
Created by : XPSUser
Date created : 09/05/2023 17:05
Computer : DESKTOP-U3MGE2F
Location
Location ID : H1
Sample : MX-HT 0p5 20Ap
Description : (24.612,15.667,-0.853)mm
Tilt : 0.00
Charge Neutraliser : On
Filament Current : 0.53A
Filament Bias : 2.02V
Charge Balance : 5.02V
Settings
Excitation
Mode : XPS - monochromatic
Tuning : Spectroscopy
Emission current : 15.00mA
Anode library : Al
ESCA modes
Collimation : Slot
Lens : Hybrid
Resolution : 20.00
Scan
Deflection : (0.000, 0.000)mm
Ti2p : 1016.690-1036.690eV, Sweeps 3
Start : 1016.690eV
End : 1036.690eV
Centre : 1026.690eV
Width : 20.000eV
Step size : 0.100eV
Number Steps : 200
Dwell time : 299ms
Sweep time : 60s
Sweeps : 3
Target quality : 200
Instrument Conditions
Work function : -4.50
Acquisition Conditions
X-ray Power : 225.00W
Quality : 203.24
XPS
4
24.612
15.6667890625
-0.85346875
Al (mono)
1486.69
225
1E+37
1E+37
1E+37
1E+37
FAT
20
1E+37
-4.5
1E+37
1E+37
1E+37
1E+37
1E+37
Ti2p

-1
Kinetic energy
eV
1016.69
0.1
2
Intensity
d
Transmission
d
pulse counting
0.298507462686567
3
0
1E+37
1E+37
1E+37
0
402
2716
15559
1.34818394035546
1.35812104677082
7199
1.35812104677082
7291
1.35807136123875
7155
1.35802167570667
7248
1.35797199017459
7187
1.35792230464252
7162
1.35787261911044
7196
1.35782293357836
7132
1.35777324804629
7149
1.35772356251421
7146
1.35767387698213
7046
1.35762419145005
7039
1.35757450591798
6973
1.3575248203859
7050
1.35747513485382
7044
1.35742544932175
7045
1.35737576378967
7056
1.35732607825759
6979
1.35727639272552
7028
1.35722670719344
6994
1.35717702166136
6940
1.35712733612929
6920
1.35707765059721
6950
1.35702796506513
6833
1.35697827953306
6937
1.35692859400098
6910
1.3568789084689
6854
1.35682922293683
6895
1.35677953740475
6890
1.35672985187267
6890
1.3566801663406
6934
1.35663048080852
6918
1.35658079527644
6929
1.35653110974437
6953
1.35648142421229
7043
1.35643173868021
6996
1.35638205314813
7073
1.35633236761606
7020
1.35628268208398
6978
1.3562329965519
7090
1.35618331101983
7070
1.35613362548775
7084
1.35608393995567
7087
1.3560342544236
7168
1.35598456889152
7368
1.35593488335944
7286
1.35588519782737
7198
1.35583551229529
7380
1.35578582676321
7498
1.35573614123114
7620
1.35568645569906
7630
1.35563677016698
7592
1.35558708463491
7639
1.35553739910283
7571
1.35548771357075
7691
1.35543802803868
7793
1.3553883425066
7800
1.35533865697452
7896
1.35528897144245
7881
1.35523928591037
7840
1.35518960037829
7846
1.35513991484622
8036
1.35509022931414
7981
1.35504054378206
7937
1.35499085824998
8006
1.35494117271791
8013
1.35489148718583
8202
1.35484180165375
8033
1.35479211612168
8180
1.3547424305896
8345
1.35469274505752
8481
1.35464305952545
8603
1.35459337399337
8570
1.35454368846129
8738
1.35449400292922
8895
1.35444431739714
9047
1.35439463186506
9089
1.35434494633299
9119
1.35429526080091
9403
1.35424557526883
9534
1.35419588973676
9672
1.35414620420468
9885
1.3540965186726
10130
1.35404683314053
10153
1.35399714760845
10180
1.35394746207637
10502
1.3538977765443
10433
1.35384809101222
10531
1.35379840548014
10749
1.35374871994806
11076
1.35369903441599
11038
1.35364934888391
10891
1.35359966335183
10846
1.35354997781976
10619
1.35350029228768
10743
1.3534506067556
10471
1.35340092122353
10215
1.35335123569145
9886
1.35330155015937
9496
1.3532518646273
9216
1.35320217909522
8916
1.35315249356314
8706
1.35310280803107
8555
1.35305312249899
8551
1.35300343696691
8500
1.35295375143484
8640
1.35290406590276
8681
1.35285438037068
8870
1.35280469483861
9168
1.35275500930653
9448
1.35270532377445
9733
1.35265563824238
9891
1.3526059527103
9910
1.35255626717822
9982
1.35250658164615
10063
1.35245689611407
9900
1.35240721058199
9466
1.35235752504991
9112
1.35230783951784
9053
1.35225815398576
8733
1.35220846845368
8393
1.35215878292161
8274
1.35210909738953
8215
1.35205941185745
8066
1.35200972632538
8173
1.3519600407933
8304
1.35191035526122
8384
1.35186066972915
8573
1.35181098419707
8842
1.35176129866499
8984
1.35171161313292
9260
1.35166192760084
9655
1.35161224206876
9879
1.35156255653669
10208
1.35151287100461
10603
1.35146318547253
11010
1.35141349994046
11447
1.35136381440838
11719
1.3513141288763
12050
1.35126444334423
12470
1.35121475781215
12678
1.35116507228007
13115
1.35111538674799
13541
1.35106570121592
13753
1.35101601568384
14115
1.35096633015176
14423
1.35091664461969
14543
1.35086695908761
15078
1.35081727355553
15381
1.35076758802346
15435
1.35071790249138
15559
1.3506682169593
15499
1.35061853142723
15217
1.35056884589515
15149
1.35051916036307
14754
1.350469474831
14455
1.35041978929892
13801
1.35037010376684
12877
1.35032041823477
11183
1.35027073270269
8969
1.35022104717061
6979
1.35017136163854
5409
1.35012167610646
4538
1.35007199057438
4077
1.35002230504231
3629
1.34997261951023
3429
1.34992293397815
3386
1.34987324844607
3255
1.349823562914
3237
1.34977387738192
3142
1.34972419184984
3011
1.34967450631777
3076
1.34962482078569
3039
1.34957513525361
3028
1.34952544972154
3016
1.34947576418946
2913
1.34942607865738
2932
1.34937639312531
2938
1.34932670759323
2911
1.34927702206115
2909
1.34922733652908
2859
1.349177650997
2879
1.34912796546492
2796
1.34907827993285
2837
1.34902859440077
2899
1.34897890886869
2903
1.34892922333662
2770
1.34887953780454
2867
1.34882985227246
2824
1.34878016674039
2771
1.34873048120831
2787
1.34868079567623
2882
1.34863111014416
2807
1.34858142461208
2777
1.34853173908
2716
1.34848205354792
2741
1.34843236801585
2842
1.34838268248377
2761
1.34833299695169
2815
1.34828331141962
2808
1.34823362588754
2796
1.34818394035546
F1s
MX-HT 0p5 20Ap
2023
5
9
17
5
6
2
41
Creation
Created by : XPSUser
Date created : 09/05/2023 17:05
Computer : DESKTOP-U3MGE2F
Location
Location ID : H1
Sample : MX-HT 0p5 20Ap
Description : (24.612,15.667,-0.853)mm
Tilt : 0.00
Charge Neutraliser : On
Filament Current : 0.53A
Filament Bias : 2.02V
Charge Balance : 5.02V
Settings
Excitation
Mode : XPS - monochromatic
Tuning : Spectroscopy
Emission current : 15.00mA
Anode library : Al
ESCA modes
Collimation : Slot
Lens : Hybrid
Resolution : 20.00
Scan
Deflection : (0.000, 0.000)mm
F1s : 791.690-811.690eV, Sweeps 5
Start : 791.690eV
End : 811.690eV
Centre : 801.690eV
Width : 20.000eV
Step size : 0.100eV
Number Steps : 200
Dwell time : 299ms
Sweep time : 60s
Sweeps : 5
Target quality : 200
Instrument Conditions
Work function : -4.50
Acquisition Conditions
X-ray Power : 225.00W
Quality : 154.56
XPS
5
24.612
15.6667890625
-0.85346875
Al (mono)
1486.69
225
1E+37
1E+37
1E+37
1E+37
FAT
20
1E+37
-4.5
1E+37
1E+37
1E+37
1E+37
1E+37
F1s

-1
Kinetic energy
eV
791.69
0.1
2
Intensity
d
Transmission
d
pulse counting
0.298507462686567
5
0
1E+37
1E+37
1E+37
0
402
12318
25594
1.45714403256293
1.46809980524165
12792
1.46809980524165
12734
1.46804594968559
12816
1.46799209412953
12752
1.46793823857347
12822
1.46788438301742
12802
1.46783052746136
12702
1.4677766719053
12762
1.46772281634924
12784
1.46766896079318
12694
1.46761510523713
12911
1.46756124968107
12849
1.46750739412501
12721
1.46745353856895
12887
1.46739968301289
12875
1.46734582745684
12905
1.46729197190078
12839
1.46723811634472
12958
1.46718426078866
12923
1.4671304052326
12754
1.46707654967654
12932
1.46702269412049
12909
1.46696883856443
12852
1.46691498300837
12839
1.46686112745231
12637
1.46680727189625
12768
1.4667534163402
12705
1.46669956078414
12850
1.46664570522808
12891
1.46659184967202
12924
1.46653799411596
13084
1.46648413855991
12862
1.46643028300385
12997
1.46637642744779
12872
1.46632257189173
12825
1.46626871633567
12780
1.46621486077962
12847
1.46616100522356
12903
1.4661071496675
12711
1.46605329411144
12688
1.46599943855538
12730
1.46594558299933
12694
1.46589172744327
12864
1.46583787188721
12932
1.46578401633115
12854
1.46573016077509
12769
1.46567630521904
12866
1.46562244966298
12972
1.46556859410692
12983
1.46551473855086
12950
1.4654608829948
12773
1.46540702743874
12946
1.46535317188269
13063
1.46529931632663
12920
1.46524546077057
13015
1.46519160521451
13172
1.46513774965845
13033
1.4650838941024
12863
1.46503003854634
12891
1.46497618299028
12912
1.46492232743422
12802
1.46486847187816
13092
1.46481461632211
12966
1.46476076076605
12938
1.46470690520999
12965
1.46465304965393
12950
1.46459919409787
13034
1.46454533854182
13162
1.46449148298576
13233
1.4644376274297
13127
1.46438377187364
12968
1.46432991631758
13115
1.46427606076153
13182
1.46422220520547
13108
1.46416834964941
13288
1.46411449409335
13157
1.46406063853729
13326
1.46400678298124
13345
1.46395292742518
13512
1.46389907186912
13506
1.46384521631306
13559
1.463791360757
13709
1.46373750520094
13581
1.46368364964489
13751
1.46362979408883
13760
1.46357593853277
13723
1.46352208297671
14083
1.46346822742065
14416
1.4634143718646
14387
1.46336051630854
14555
1.46330666075248
14808
1.46325280519642
14906
1.46319894964036
15012
1.46314509408431
15273
1.46309123852825
15647
1.46303738297219
16078
1.46298352741613
16703
1.46292967186007
17239
1.46287581630402
18187
1.46282196074796
19313
1.4627681051919
20931
1.46271424963584
21664
1.46266039407978
23217
1.46260653852373
24502
1.46255268296767
25371
1.46249882741161
25594
1.46244497185555
25412
1.46239111629949
24313
1.46233726074344
22896
1.46228340518738
21549
1.46222954963132
19781
1.46217569407526
18202
1.4621218385192
16913
1.46206798296314
15848
1.46201412740709
15037
1.46196027185103
14485
1.46190641629497
14025
1.46185256073891
13651
1.46179870518285
13409
1.4617448496268
13288
1.46169099407074
13053
1.46163713851468
12935
1.46158328295862
12913
1.46152942740256
12860
1.46147557184651
12804
1.46142171629045
12766
1.46136786073439
12734
1.46131400517833
12772
1.46126014962227
12627
1.46120629406622
12542
1.46115243851016
12446
1.4610985829541
12643
1.46104472739804
12443
1.46099087184198
12564
1.46093701628593
12647
1.46088316072987
12572
1.46082930517381
12559
1.46077544961775
12692
1.46072159406169
12688
1.46066773850564
12632
1.46061388294958
12549
1.46056002739352
12614
1.46050617183746
12435
1.4604523162814
12505
1.46039846072534
12547
1.46034460516929
12699
1.46029074961323
12692
1.46023689405717
12646
1.46018303850111
12521
1.46012918294505
12580
1.460075327389
12690
1.46002147183294
12510
1.45996761627688
12583
1.45991376072082
12477
1.45985990516476
12454
1.45980604960871
12563
1.45975219405265
12550
1.45969833849659
12549
1.45964448294053
12530
1.45959062738447
12671
1.45953677182842
12586
1.45948291627236
12479
1.4594290607163
12588
1.45937520516024
12516
1.45932134960418
12511
1.45926749404813
12443
1.45921363849207
12354
1.45915978293601
12565
1.45910592737995
12482
1.45905207182389
12645
1.45899821626783
12601
1.45894436071178
12474
1.45889050515572
12462
1.45883664959966
12461
1.4587827940436
12681
1.45872893848754
12500
1.45867508293149
12721
1.45862122737543
12665
1.45856737181937
12500
1.45851351626331
12624
1.45845966070725
12585
1.4584058051512
12592
1.45835194959514
12471
1.45829809403908
12318
1.45824423848302
12625
1.45818054888434
12618
1.45811576661425
12532
1.45805098434416
12611
1.45798620207407
12577
1.45792141980398
12576
1.4578566375339
12482
1.45779185526381
12398
1.45772707299372
12447
1.45766229072363
12511
1.45759750845354
12619
1.45753272618346
12499
1.45746794391337
12472
1.45740316164328
12636
1.45733837937319
12724
1.4572735971031
12593
1.45720881483302
12656
1.45714403256293
O1s
MX-HT 0p5 20Ap
2023
5
9
17
5
6
2
41
Creation
Created by : XPSUser
Date created : 09/05/2023 17:05
Computer : DESKTOP-U3MGE2F
Location
Location ID : H1
Sample : MX-HT 0p5 20Ap
Description : (24.612,15.667,-0.853)mm
Tilt : 0.00
Charge Neutraliser : On
Filament Current : 0.53A
Filament Bias : 2.02V
Charge Balance : 5.02V
Settings
Excitation
Mode : XPS - monochromatic
Tuning : Spectroscopy
Emission current : 15.00mA
Anode library : Al
ESCA modes
Collimation : Slot
Lens : Hybrid
Resolution : 20.00
Scan
Deflection : (0.000, 0.000)mm
O1s : 946.690-961.690eV, Sweeps 5
Start : 946.690eV
End : 961.690eV
Centre : 954.190eV
Width : 15.000eV
Step size : 0.100eV
Number Steps : 150
Dwell time : 397ms
Sweep time : 60s
Sweeps : 5
Target quality : 200
Instrument Conditions
Work function : -4.50
Acquisition Conditions
X-ray Power : 225.00W
Quality : 142.32
XPS
6
24.612
15.6667890625
-0.85346875
Al (mono)
1486.69
225
1E+37
1E+37
1E+37
1E+37
FAT
20
1E+37
-4.5
1E+37
1E+37
1E+37
1E+37
1E+37
O1s

-1
Kinetic energy
eV
946.69
0.1
2
Intensity
d
Transmission
d
pulse counting
0.397351
5
0
1E+37
1E+37
1E+37
0
302
14258
28218
1.39073012089434
1.39549665066723
15875
1.39549665066723
15759
1.39546487380208
15787
1.39543309693692
15623
1.39540132007177
15560
1.39536954320662
15487
1.39533776634147
15532
1.39530598947631
15542
1.39527421261116
15492
1.39524243574601
15503
1.39521065888085
15670
1.3951788820157
15409
1.39514710515055
15344
1.3951153282854
15476
1.39508355142024
15356
1.39505177455509
15372
1.39501999768994
15396
1.39498822082479
15574
1.39495644395963
15423
1.39492466709448
15352
1.39489289022933
15363
1.39486111336418
15384
1.39482933649902
15523
1.39479755963387
15415
1.39476578276872
15480
1.39473400590357
15269
1.39470222903841
15343
1.39467045217326
15381
1.39463867530811
15431
1.39460689844296
15574
1.3945751215778
15416
1.39454334471265
15434
1.3945115678475
15341
1.39447979098235
15565
1.39444801411719
15473
1.39441623725204
15476
1.39438446038689
15382
1.39435268352174
15271
1.39432090665658
15333
1.39428912979143
15351
1.39425735292628
15371
1.39422557606112
15555
1.39419379919597
15533
1.39416202233082
15311
1.39413024546567
15254
1.39409846860051
15403
1.39406669173536
15489
1.39403491487021
15410
1.39400313800506
15449
1.3939713611399
15638
1.39393958427475
15667
1.3939078074096
15534
1.39387603054445
15620
1.39384425367929
15424
1.39381247681414
15634
1.39378069994899
15876
1.39374892308384
15746
1.39371714621868
15777
1.39368536935353
15754
1.39365359248838
16077
1.39362181562323
16111
1.39359003875807
16120
1.39355826189292
16416
1.39352648502777
16567
1.39349470816262
16615
1.39346293129746
16754
1.39343115443231
16955
1.39339937756716
17295
1.393367600702
17485
1.39333582383685
17656
1.3933040469717
18035
1.39327227010655
18455
1.39324049324139
18706
1.39320871637624
19040
1.39317693951109
19414
1.39314516264594
19553
1.39311338578078
19655
1.39308160891563
20173
1.39304983205048
20373
1.39301805518533
20395
1.39298627832017
20876
1.39295450145502
21022
1.39292272458987
21302
1.39289094772472
21307
1.39285917085956
21616
1.39282739399441
21758
1.39279561712926
22082
1.39276384026411
22220
1.39273206339895
22387
1.3927002865338
22496
1.39266850966865
23024
1.3926367328035
23155
1.39260495593834
23505
1.39257317907319
24337
1.39254140220804
24816
1.39250962534289
25481
1.39247784847773
26326
1.39244607161258
26908
1.39241429474743
26749
1.39238251788227
26651
1.39235074101712
26662
1.39231896415197
26457
1.39228718728682
26310
1.39225541042166
26528
1.39222363355651
26798
1.39219185669136
27301
1.39216007982621
27818
1.39212830296105
28105
1.3920965260959
28218
1.39206474923075
27425
1.3920329723656
25657
1.39200119550044
23432
1.39196941863529
21080
1.39193764177014
19075
1.39190586490499
17566
1.39187408803983
16611
1.39184231117468
15998
1.39181053430953
15438
1.39177875744438
15074
1.39174698057922
15022
1.39171520371407
14833
1.39168342684892
14882
1.39165164998377
14805
1.39161987311861
14768
1.39158809625346
14694
1.39155631938831
14679
1.39152454252316
14733
1.391492765658
14623
1.39146098879285
14604
1.3914292119277
14488
1.39139743506254
14686
1.39136565819739
14541
1.39133388133224
14656
1.39130210446709
14553
1.39127032760193
14657
1.39123855073678
14540
1.39120677387163
14421
1.39117499700648
14571
1.39114322014132
14715
1.39111144327617
14456
1.39107966641102
14299
1.39104788954587
14569
1.39101611268071
14624
1.39098433581556
14258
1.39095255895041
14393
1.39092078208526
14439
1.3908890052201
14529
1.39085722835495
14567
1.3908254514898
14533
1.39079367462465
14519
1.39076189775949
14542
1.39073012089434
Cl2p
MX-HT 0p5 20Ap
2023
5
9
17
5
6
2
41
Creation
Created by : XPSUser
Date created : 09/05/2023 17:05
Computer : DESKTOP-U3MGE2F
Location
Location ID : H1
Sample : MX-HT 0p5 20Ap
Description : (24.612,15.667,-0.853)mm
Tilt : 0.00
Charge Neutraliser : On
Filament Current : 0.53A
Filament Bias : 2.02V
Charge Balance : 5.02V
Settings
Excitation
Mode : XPS - monochromatic
Tuning : Spectroscopy
Emission current : 15.00mA
Anode library : Al
ESCA modes
Collimation : Slot
Lens : Hybrid
Resolution : 20.00
Scan
Deflection : (0.000, 0.000)mm
Cl2p : 1278.690-1291.690eV, Sweeps 5
Start : 1278.690eV
End : 1291.690eV
Centre : 1285.190eV
Width : 13.000eV
Step size : 0.100eV
Number Steps : 130
Dwell time : 458ms
Sweep time : 60s
Sweeps : 5
Target quality : 200
Instrument Conditions
Work function : -4.50
Acquisition Conditions
X-ray Power : 225.00W
Quality : 57.64
XPS
7
24.612
15.6667890625
-0.85346875
Al (mono)
1486.69
225
1E+37
1E+37
1E+37
1E+37
FAT
20
1E+37
-4.5
1E+37
1E+37
1E+37
1E+37
1E+37
Cl2p

-1
Kinetic energy
eV
1278.69
0.1
2
Intensity
d
Transmission
d
pulse counting
0.458015267175573
5
0
1E+37
1E+37
1E+37
0
262
1613
3698
1.34975176565477
1.35099769238123
1772
1.35099769238123
1721
1.35098810832949
1750
1.35097852427775
1742
1.35096894022601
1745
1.35095935617426
1695
1.35094977212252
1781
1.35094018807078
1660
1.35093060401904
1741
1.3509210199673
1696
1.35091143591555
1731
1.35090185186381
1736
1.35089226781207
1690
1.35088268376033
1688
1.35087309970859
1749
1.35086351565684
1704
1.3508539316051
1710
1.35084434755336
1721
1.35083476350162
1705
1.35082517944988
1743
1.35081559539813
1737
1.35080601134639
1737
1.35079642729465
1675
1.35078684324291
1708
1.35077725919117
1732
1.35076767513942
1674
1.35075809108768
1695
1.35074850703594
1773
1.3507389229842
1741
1.35072933893246
1658
1.35071975488071
1705
1.35071017082897
1723
1.35070058677723
1721
1.35069100272549
1734
1.35068141867375
1716
1.350671834622
1729
1.35066225057026
1765
1.35065266651852
1770
1.35064308246678
1690
1.35063349841504
1784
1.35062391436329
1720
1.35061433031155
1731
1.35060474625981
1744
1.35059516220807
1718
1.35058557815633
1725
1.35057599410458
1776
1.35056641005284
1739
1.3505568260011
1754
1.35054724194936
1681
1.35053765789762
1778
1.35052807384587
1843
1.35051848979413
1753
1.35050890574239
1740
1.35049932169065
1733
1.35048973763891
1744
1.35048015358716
1801
1.35047056953542
1704
1.35046098548368
1821
1.35045140143194
1767
1.3504418173802
1749
1.35043223332845
1816
1.35042264927671
1860
1.35041306522497
1814
1.35040348117323
1874
1.35039389712149
1902
1.35038431306974
1875
1.350374729018
1906
1.35036514496626
1939
1.35035556091452
1924
1.35034597686278
2024
1.35033639281103
2004
1.35032680875929
2066
1.35031722470755
2194
1.35030764065581
2276
1.35029805660407
2507
1.35028847255232
2700
1.35027888850058
2834
1.35026930444884
2923
1.3502597203971
2937
1.35025013634536
2775
1.35024055229361
2645
1.35023096824187
2525
1.35022138419013
2349
1.35021180013839
2300
1.35020221608665
2216
1.3501926320349
2202
1.35018304798316
2215
1.35017346393142
2276
1.35016387987968
2437
1.35015429582794
2711
1.35014471177619
2965
1.35013512772445
3203
[...]
942
1.29604861797249
983
1.29604327827113
999
1.29603793856976
1022
1.2960325988684
1025
1.29602725916703
1042
1.29602191946567
1046
1.29601657976431
1034
1.29601124006294
1032
1.29600590036158
1040
1.29600056066021
1076
1.29599522095885
1085
1.29598988125749
1076
1.29598454155612
1067
1.29597920185476
1084
1.29597386215339
1177
1.29596852245203
1186
1.29596318275067
1202
1.2959578430493
1156
1.29595250334794
1197
1.29594716364658
1171
1.29594182394521
1177
1.29593648424385
1219
1.29593114454248
1285
1.29592580484112
1311
1.29592046513976
1328
1.29591512543839
1310
1.29590978573703
1266
1.29590444603566
1320
1.2958991063343
1327
1.29589376663294
1343
1.29588842693157
1324
1.29588308723021
1340
1.29587774752884
1364
1.29587240782748
1400
1.29586706812612
1490
1.29586172842475
1439
1.29585638872339
1429
1.29585104902202
1456
1.29584570932066
1470
1.2958403696193
1525
1.29583502991793
1546
1.29582969021657
1520
1.29582435051521
1587
1.29581901081384
1621
1.29581367111248
1586
1.29580833141111
1623
1.29580299170975
1571
1.29579765200839
1619
1.29579231230702
1640
1.29578697260566
1650
1.29578163290429
1615
1.29577629320293
1652
1.29577095350157
1671
1.2957656138002
1617
1.29576027409884
1610
1.29575493439747
1639
1.29574959469611
1619
1.29574425499475
1557
1.29573891529338
1541
1.29573357559202
1535
1.29572823589066
1561
1.29572289618929
1439
1.29571755648793
1377
1.29571221678656
1323
1.2957068770852
1321
1.29570153738384
1288
1.29569619768247
1225
1.29569085798111
1191
1.29568551827974
1173
1.29568017857838
1147
1.29567483887702
1130
1.29566949917565
1128
1.29566415947429
1061
1.29565881977292
1055
1.29565348007156
1031
1.2956481403702
1006
1.29564280066883
1026
1.29563746096747
972
1.2956321212661
961
1.29562678156474
993
1.29562144186338
946
1.29561610216201
905
1.29561076246065
923
1.29560542275929
907
1.29560008305792
922
1.29559474335656
931
1.29558940365519
907
1.29558406395383
919
1.29557872425247
891
1.2955733845511
931
1.29556804484974
892
1.29556270514837
831
1.29555736544701
866
1.29555202574565
835
1.29554668604428
837
1.29554134634292
879
1.29553600664155
865
1.29553066694019
890
1.29552532723883
871
1.29551998753746
868
1.2955146478361
889
1.29550930813473
825
1.29550396843337
888
1.29549862873201
848
1.29549328903064
875
1.29548794932928
828
1.29548260962792
783
1.29547726992655
843
1.29547193022519
848
1.29546659052382
840
1.29546125082246
845
1.2954559111211
823
1.29545057141973
851
1.29544523171837
858
1.295439892017
896
1.29543455231564
863
1.29542921261428
830
1.29542387291291
800
1.29541853321155
819
1.29541319351018
866
1.29540785380882
827
1.29540251410746
822
1.29539717440609
870
1.29539183470473
800
1.29538649500337
859
1.295381155302
846
1.29537581560064
793
1.29537047589927
790
1.29536513619791
851
1.29535979649655
860
1.29535445679518
812
1.29534911709382
861
1.29534377739245
825
1.29533843769109
850
1.29533309798973
845
1.29532775828836
882
1.295322418587
863
1.29531707888563
811
1.29531173918427
818
1.29530639948291
876
1.29530105978154
870
1.29529572008018
832
1.29529038037881
819
1.29528504067745
869
1.29527970097609
840
1.29527436127472
823
1.29526902157336
862
1.295263681872
862
1.29525834217063
867
1.29525300246927
837
1.2952476627679
866
1.29524232306654
845
1.29523698336518
855
1.29523164366381
827
1.29522630396245
815
1.29522096426108
855
1.29521562455972
826
1.29521028485836
868
1.29520494515699
814
1.29519960545563
840
1.29519426575426
829
1.2951889260529
812
1.29518358635154
806
1.29517824665017
819
1.29517290694881
815
1.29516756724745
792
1.29516222754608
785
1.29515688784472
820
1.29515154814335
834
1.29514620844199
851
1.29514086874063
804
1.29513552903926
825
1.2951301893379
869
1.29512484963653
807
1.29511950993517
786
1.29511417023381
793
1.29510883053244
783
1.29510349083108
804
1.29509815112971
807
1.29509281142835
856
1.29508747172699
842
1.29508213202562
797
1.29507679232426
804
1.29507145262289
816
1.29506611292153
747
1.29506077322017
797
1.2950554335188
822
1.29505009381744
802
1.29504475411608
801
1.29503941441471
747
1.29503407471335
772
1.29502873501198
768
1.29502339531062
754
1.29501805560926
790
1.29501271590789
788
1.29500737620653
747
1.29500203650516
765
1.2949966968038
766
1.29499135710244
752
1.29498601740107
762
1.29498067769971
712
1.29497533799834
757
1.29496999829698
792
1.29496465859562
745
1.29495931889425
742
1.29495397919289
745
1.29494863949153
Ti3p
MX-HT 0p5 20Ap
2023
5
9
17
5
6
2
41
Creation
Created by : XPSUser
Date created : 09/05/2023 17:05
Computer : DESKTOP-U3MGE2F
Location
Location ID : H1
Sample : MX-HT 0p5 20Ap
Description : (24.612,15.667,-0.853)mm
Tilt : 0.00
Charge Neutraliser : On
Filament Current : 0.53A
Filament Bias : 2.02V
Charge Balance : 5.02V
Settings
Excitation
Mode : XPS - monochromatic
Tuning : Spectroscopy
Emission current : 15.00mA
Anode library : Al
ESCA modes
Collimation : Slot
Lens : Hybrid
Resolution : 20.00
Scan
Deflection : (0.000, 0.000)mm
Ti3p : 1437.690-1467.690eV, Sweeps 5
Start : 1437.690eV
End : 1467.690eV
Centre : 1452.690eV
Width : 30.000eV
Step size : 0.100eV
Number Steps : 300
Dwell time : 199ms
Sweep time : 60s
Sweeps : 5
Target quality : 200
Instrument Conditions
Work function : -4.50
Acquisition Conditions
X-ray Power : 225.00W
Quality : 112.32
XPS
9
24.612
15.6667890625
-0.85346875
Al (mono)
1486.69
225
1E+37
1E+37
1E+37
1E+37
FAT
20
1E+37
-4.5
1E+37
1E+37
1E+37
1E+37
1E+37
Ti3p

-1
Kinetic energy
eV
1437.69
0.1
2
Intensity
d
Transmission
d
pulse counting
0.199335548172757
5
0
1E+37
1E+37
1E+37
0
602
240
2267
1.29361371415055
1.29521562455972
860
1.29521562455972
848
1.29521028485836
847
1.29520494515699
824
1.29519960545563
831
1.29519426575426
845
1.2951889260529
861
1.29518358635154
852
1.29517824665017
806
1.29517290694881
806
1.29516756724745
836
1.29516222754608
791
1.29515688784472
835
1.29515154814335
846
1.29514620844199
821
1.29514086874063
852
1.29513552903926
831
1.2951301893379
801
1.29512484963653
821
1.29511950993517
837
1.29511417023381
834
1.29510883053244
819
1.29510349083108
836
1.29509815112971
818
1.29509281142835
753
1.29508747172699
790
1.29508213202562
841
1.29507679232426
825
1.29507145262289
797
1.29506611292153
831
1.29506077322017
806
1.2950554335188
826
1.29505009381744
826
1.29504475411608
780
1.29503941441471
780
1.29503407471335
788
1.29502873501198
794
1.29502339531062
794
1.29501805560926
785
1.29501271590789
750
1.29500737620653
766
1.29500203650516
765
1.2949966968038
808
1.29499135710244
730
1.29498601740107
722
1.29498067769971
754
1.29497533799834
759
1.29496999829698
755
1.29496465859562
754
1.29495931889425
798
1.29495397919289
754
1.29494863949153
740
1.29494329979016
747
1.2949379600888
746
1.29493262038743
750
1.29492728068607
724
1.29492194098471
729
1.29491660128334
756
1.29491126158198
753
1.29490592188061
733
1.29490058217925
712
1.29489524247789
711
1.29488990277652
729
1.29488456307516
738
1.29487922337379
714
1.29487388367243
743
1.29486854397107
772
1.2948632042697
773
1.29485786456834
738
1.29485252486697
753
1.29484718516561
765
1.29484184546425
724
1.29483650576288
741
1.29483116606152
738
1.29482582636016
725
1.29482048665879
740
1.29481514695743
808
1.29480980725606
765
1.2948044675547
781
1.29479912785334
797
1.29479378815197
795
1.29478844845061
759
1.29478310874924
753
1.29477776904788
779
1.29477242934652
774
1.29476708964515
775
1.29476174994379
772
1.29475641024242
813
1.29475107054106
791
1.2947457308397
826
1.29474039113833
819
1.29473505143697
836
1.29472971173561
841
1.29472437203424
875
1.29471903233288
903
1.29471369263151
891
1.29470835293015
879
1.29470301322879
911
1.29469767352742
912
1.29469233382606
953
1.29468699412469
930
1.29468165442333
988
1.29467631472197
986
1.2946709750206
986
1.29466563531924
1042
1.29466029561787
1081
1.29465495591651
1116
1.29464961621515
1088
1.29464427651378
1107
1.29463893681242
1134
1.29463359711105
1193
1.29462825740969
1220
1.29462291770833
1299
1.29461757800696
1319
1.2946122383056
1321
1.29460689860424
1417
1.29460155890287
1426
1.29459621920151
1451
1.29459087950014
1507
1.29458553979878
1450
1.29458020009742
1464
1.29457486039605
1454
1.29456952069469
1514
1.29456418099332
1522
1.29455884129196
1509
1.2945535015906
1560
1.29454816188923
1600
1.29454282218787
1504
1.2945374824865
1592
1.29453214278514
1579
1.29452680308378
1645
1.29452146338241
1729
1.29451612368105
1759
1.29451078397968
1802
1.29450544427832
1815
1.29450010457696
1898
1.29449476487559
1849
1.29448942517423
2000
1.29448408547287
2089
1.2944787457715
2081
1.29447340607014
2071
1.29446806636877
2083
1.29446272666741
2208
1.29445738696605
2187
1.29445204726468
2263
1.29444670756332
2223
1.29444136786195
2228
1.29443602816059
2201
1.29443068845923
2267
1.29442534875786
2246
1.2944200090565
2187
1.29441466935513
2252
1.29440932965377
2190
1.29440398995241
2105
1.29439865025104
1988
1.29439331054968
1903
1.29438797084832
1771
1.29438263114695
1688
1.29437729144559
1564
1.29437195174422
1414
1.29436661204286
1208
1.2943612723415
1152
1.29435593264013
950
1.29435059293877
845
1.2943452532374
772
1.29433991353604
690
1.29433457383468
605
1.29432923413331
537
1.29432389443195
555
1.29431855473058
526
1.29431321502922
491
1.29430787532786
471
1.29430253562649
435
1.29429719592513
429
1.29429185622377
415
1.2942865165224
420
1.29428117682104
409
1.29427583711967
405
1.29427049741831
397
1.29426515771695
382
1.29425981801558
401
1.29425447831422
396
1.29424913861285
407
1.29424379891149
404
1.29423845921013
393
1.29423311950876
382
1.2942277798074
397
1.29422244010603
410
1.29421710040467
423
1.29421176070331
394
1.29420642100194
441
1.29420108130058
457
1.29419574159921
429
1.29419040189785
462
1.29418506219649
463
1.29417972249512
489
1.29417438279376
460
1.2941690430924
476
1.29416370339103
465
1.29415836368967
495
1.2941530239883
497
1.29414768428694
456
1.29414234458558
434
1.29413700488421
431
1.29413166518285
397
1.29412632548148
417
1.29412098578012
405
1.29411564607876
353
1.29411030637739
351
1.29410496667603
359
1.29409962697466
337
1.2940942872733
297
1.29408894757194
302
1.29408360787057
328
1.29407826816921
292
1.29407292846784
318
1.29406758876648
285
1.29406224906512
281
1.29405690936375
270
1.29405156966239
249
1.29404622996103
285
1.29404089025966
266
1.2940355505583
268
1.29403021085693
295
1.29402487115557
264
1.29401953145421
270
1.29401419175284
277
1.29400885205148
270
1.29400351235011
243
1.29399817264875
248
1.29399283294739
240
1.29398749324602
258
1.29398215354466
266
1.29397681384329
248
1.29397147414193
267
1.29396613444057
272
1.2939607947392
285
1.29395545503784
281
1.29395011533648
286
1.29394477563511
272
1.29393943593375
259
1.29393409623238
259
1.29392875653102
288
1.29392341682966
268
1.29391807712829
271
1.29391273742693
266
1.29390739772556
267
1.2939020580242
272
1.29389671832284
264
1.29389137862147
267
1.29388603892011
285
1.29388069921874
297
1.29387535951738
307
1.29387001981602
303
1.29386468011465
294
1.29385934041329
302
1.29385400071192
296
1.29384866101056
305
1.2938433213092
307
1.29383798160783
318
1.29383264190647
350
1.29382730220511
338
1.29382196250374
331
1.29381662280238
356
1.29381128310101
369
1.29380594339965
390
1.29380060369829
378
1.29379526399692
375
1.29378992429556
383
1.29378458459419
368
1.29377924489283
373
1.29377390519147
414
1.2937685654901
401
1.29376322578874
412
1.29375788608737
424
1.29375254638601
432
1.29374720668465
419
1.29374186698328
408
1.29373652728192
442
1.29373118758056
413
1.29372584787919
391
1.29372050817783
381
1.29371516847646
385
1.2937098287751
376
1.29370448907374
379
1.29369914937237
359
1.29369380967101
359
1.29368846996964
361
1.29368313026828
335
1.29367779056692
343
1.29367245086555
337
1.29366711116419
312
1.29366177146282
322
1.29365643176146
303
1.2936510920601
325
1.29364575235873
266
1.29364041265737
297
1.293635072956
282
1.29362973325464
271
1.29362439355328
290
1.29361905385191
282
1.29361371415055
Ti2s
MX-HT 0p5 20Ap
2023
5
9
17
5
6
2
41
Creation
Created by : XPSUser
Date created : 09/05/2023 17:05
Computer : DESKTOP-U3MGE2F
Location
Location ID : H1
Sample : MX-HT 0p5 20Ap
Description : (24.612,15.667,-0.853)mm
Tilt : 0.00
Charge Neutraliser : On
Filament Current : 0.53A
Filament Bias : 2.02V
Charge Balance : 5.02V
Settings
Excitation
Mode : XPS - monochromatic
Tuning : Spectroscopy
Emission current : 15.00mA
Anode library : Al
ESCA modes
Collimation : Slot
Lens : Hybrid
Resolution : 20.00
Scan
Deflection : (0.000, 0.000)mm
Ti2s : 907.690-937.690eV, Sweeps 10
Start : 907.690eV
End : 937.690eV
Centre : 922.690eV
Width : 30.000eV
Step size : 0.100eV
Number Steps : 300
Dwell time : 199ms
Sweep time : 60s
Sweeps : 10
Target quality : 200
Instrument Conditions
Work function : -4.50
Acquisition Conditions
X-ray Power : 225.00W
Quality : 71.50
XPS
10
24.612
15.6667890625
-0.85346875
Al (mono)
1486.69
225
1E+37
1E+37
1E+37
1E+37
FAT
20
1E+37
-4.5
1E+37
1E+37
1E+37
1E+37
1E+37
Ti2s

-1
Kinetic energy
eV
907.69
0.1
2
Intensity
d
Transmission
d
pulse counting
0.199335548172757
10
0
1E+37
1E+37
1E+37
0
602
16146
22722
1.39835656853096
1.40786093570082
19632
1.40786093570082
19596
1.40783040092986
19571
1.40779986615891
19583
1.40776933138795
19413
1.40773879661699
19375
1.40770826184604
19454
1.40767772707508
19630
1.40764719230412
19481
1.40761665753316
19635
1.40758612276221
19435
1.40755558799125
19603
1.40752505322029
19618
1.40749451844934
19416
1.40746398367838
19532
1.40743344890742
19516
1.40740291413646
19641
1.40737237936551
19575
1.40734184459455
19559
1.40731130982359
19669
1.40728077505264
19462
1.40725024028168
19542
1.40721970551072
19557
1.40718917073976
19535
1.40715863596881
19584
1.40712698331307
19588
1.40709520644792
19495
1.40706342958277
19595
1.40703165271762
19565
1.40699987585246
19464
1.40696809898731
19461
1.40693632212216
19321
1.40690454525701
19462
1.40687276839185
19584
1.4068409915267
19377
1.40680921466155
19450
1.4067774377964
19460
1.40674566093124
19500
1.40671388406609
19531
1.40668210720094
19580
1.40665033033579
19438
1.40661855347063
19357
1.40658677660548
19508
1.40655499974033
19300
1.40652322287517
19391
1.40649144601002
19246
1.40645966914487
19462
1.40642789227972
19285
1.40639611541456
19245
1.40636433854941
19269
1.40633256168426
19518
1.40630078481911
19241
1.40626900795395
19294
1.4062372310888
19345
1.40620545422365
19347
1.4061736773585
19161
1.40614190049334
19196
1.40611012362819
19159
1.40607834676304
19221
1.40604656989789
19095
1.40601479303273
19245
1.40598301616758
19188
1.40595123930243
19338
1.40591946243728
19223
1.40588768557212
19143
1.40585590870697
19044
1.40582413184182
18948
1.40579235497667
19102
1.40576057811151
19120
1.40572880124636
18960
1.40569702438121
19027
1.40566524751605
19021
1.4056334706509
18960
1.40560169378575
18850
1.4055699169206
19029
1.40553814005544
18837
1.40550636319029
18976
1.40547458632514
19037
1.40544280945999
19075
1.40541103259483
19007
1.40537925572968
19029
1.40534747886453
19061
1.40531570199938
19136
1.40528392513422
18809
1.40525214826907
18904
1.40522037140392
18820
1.40518859453877
18938
1.40515681767361
19094
1.40512504080846
18891
1.40509326394331
19152
1.40506148707816
18958
1.405029710213
18834
1.40499793334785
18809
1.4049661564827
18902
1.40493437961755
18967
1.40490260275239
18959
1.40487082588724
18978
1.40483904902209
19031
1.40480727215694
19239
1.40477549529178
19156
1.40474371842663
19201
1.40471194156148
19271
1.40468016469632
18916
1.40464838783117
19196
1.40461661096602
19215
1.40458483410087
19098
1.40455305723571
19364
1.40452128037056
19307
1.40448950350541
19198
1.40445772664026
19358
1.4044259497751
19256
1.40439417290995
19452
1.4043623960448
19347
1.40433061917965
19408
1.40429884231449
19562
1.40426706544934
19626
1.40423528858419
19629
1.40420351171904
19570
1.40417173485388
19830
1.40413995798873
19841
1.40410818112358
19961
1.40407640425843
19811
1.40404462739327
19975
1.40401285052812
19965
1.40398107366297
20015
1.40394929679782
20025
1.40391751993266
20099
1.40388574306751
20322
1.40385396620236
20444
1.40382218933721
20365
1.40379041247205
20314
1.4037586356069
20244
1.40372685874175
20336
1.40369508187659
20651
1.40366330501144
20712
1.40363152814629
20562
1.40359975128114
20968
1.40356797441598
20904
1.40353619755083
20912
1.40350442068568
20787
1.40347264382053
21119
1.40344086695537
21353
1.40340909009022
21310
1.40337731322507
21467
1.40334553635992
21444
1.40331375949476
21308
1.40328198262961
21538
1.40325020576446
21428
1.40321842889931
21804
1.40318665203415
21727
1.403154875169
21577
1.40312309830385
21511
1.4030913214387
21840
1.40305954457354
22022
1.40302776770839
21994
1.40299599084324
22004
1.40296421397809
21998
1.40293243711293
22129
1.40290066024778
22268
1.40286888338263
22138
1.40283710651747
22506
1.40280532965232
22440
1.40277355278717
22675
1.40274177592202
22508
1.40270999905686
22498
1.40267822219171
22649
1.40264644532656
22696
1.40261466846141
22706
1.40258289159625
22613
1.4025511147311
22464
1.40251933786595
22455
1.4024875610008
22695
1.40245578413564
22616
1.40242400727049
22672
1.40239223040534
22689
1.40236045354019
22333
1.40232867667503
22722
1.40229689980988
22547
1.40226512294473
22346
1.40223334607958
22294
1.40220156921442
21911
1.40216979234927
21912
1.40213801548412
21761
1.40210623861897
21854
1.40207446175381
21751
1.40204268488866
21497
1.40201090802351
21447
1.40197913115836
21391
1.4019473542932
21078
1.40191557742805
20979
1.4018838005629
20748
1.40185202369774
20378
1.40182024683259
20297
1.40178846996744
20075
1.40175669310229
19763
1.40172491623713
19932
1.40169313937198
19751
1.40166136250683
19391
1.40162958564168
19561
1.40159780877652
19395
1.40156603191137
19335
1.40153425504622
19176
1.40150247818107
19075
1.40147070131591
19038
1.40143892445076
18950
1.40140714758561
18657
1.40137537072046
18523
1.4013435938553
18582
1.40131181699015
18365
1.401280040125
18359
1.40124826325985
18237
1.40121648639469
18294
1.40118470952954
18037
1.40115293266439
18071
1.40112115579924
18142
1.40108937893408
17867
1.40105760206893
17911
1.40102582520378
17774
1.40099404833863
17751
1.40096227147347
17647
1.40093049460832
17538
1.40089871774317
17455
1.40086694087801
17459
1.40083516401286
17555
1.40080338714771
17486
1.40077161028256
17286
1.4007398334174
17283
1.40070805655225
17504
1.4006762796871
17450
1.40064450282195
17217
1.40061272595679
17338
1.40058094909164
17341
1.40054917222649
17183
1.40051739536134
17117
1.40048561849618
17148
1.40045384163103
17030
1.40042206476588
17052
1.40039028790073
17146
1.40035851103557
17114
1.40032673417042
17178
1.40029495730527
17237
1.40026318044012
17102
1.40023140357496
16999
1.40019962670981
17063
1.40016784984466
16852
1.40013607297951
16827
1.40010429611435
17091
1.4000725192492
16994
1.40004074238405
16873
1.40000896551889
16745
1.39997718865374
16731
1.39994541178859
16841
1.39991363492344
17005
1.39988185805828
16903
1.39985008119313
16966
1.39981830432798
16729
1.39978652746283
16666
1.39975475059767
16749
1.39972297373252
16655
1.39969119686737
16914
1.39965942000222
16776
1.39962764313706
16772
1.39959586627191
16801
1.39956408940676
16812
1.39953231254161
16795
1.39950053567645
16695
1.3994687588113
16521
1.39943698194615
16530
1.399405205081
16610
1.39937342821584
16815
1.39934165135069
16614
1.39930987448554
16680
1.39927809762039
16547
1.39924632075523
16579
1.39921454389008
16640
1.39918276702493
16592
1.39915099015978
16556
1.39911921329462
16599
1.39908743642947
16675
1.39905565956432
16795
1.39902388269916
16599
1.39899210583401
16471
1.39896032896886
16390
1.39892855210371
16559
1.39889677523855
16298
1.3988649983734
16413
1.39883322150825
16485
1.3988014446431
16365
1.39876966777794
16386
1.39873789091279
16475
1.39870611404764
16271
1.39867433718249
16322
1.39864256031733
16306
1.39861078345218
16267
1.39857900658703
16370
1.39854722972188
16510
1.39851545285672
16349
1.39848367599157
16288
1.39845189912642
16146
1.39842012226127
16396
1.39838834539611
16447
1.39835656853096
end of experiment