File: XPS/Casa format/MX-HT 0p1 20Ap location X1 in image.vms
VAMAS Surface Chemical Analysis Standard Data Transfer Format 1988 May 4
Not specified
MI-600-BE9240AA
XPSUser
KTH Amireza_C-paper-Mxene-sample sent on 17 April2023.experiment
0
NORM
REGULAR
1
4
Index
d
PositionX [mm]
n
PositionY [mm]
n
PositionZ [mm]
n
0
0
0
0
10
wide
MX-HT 0p1 20Ap
2023
5
9
14
56
9
2
39
Creation
Created by : XPSUser
Date created : 09/05/2023 14:56
Computer : DESKTOP-U3MGE2F
Location
Location ID : X1
Sample : MX-HT 0p1 20Ap
Description : (55.384,14.627,-0.798)mm
Tilt : 0.00
Charge Neutraliser : On
Filament Current : 0.53A
Filament Bias : 2.02V
Charge Balance : 5.02V
Settings
Excitation
Mode : XPS - monochromatic
Tuning : Spectroscopy
Emission current : 15.00mA
Anode library : Al
ESCA modes
Collimation : Slot
Lens : Hybrid
Resolution : 160.00
Scan
Deflection : (0.000, 0.000)mm
wide : 286.690-1491.690eV, Sweeps 5
Start : 286.690eV
End : 1491.690eV
Centre : 889.190eV
Width : 1205.000eV
Step size : 1.000eV
Number Steps : 1205
Dwell time : 100ms
Sweep time : 120s
Sweeps : 5
Instrument Conditions
Work function : -4.50
Acquisition Conditions
X-ray Power : 225.00W
XPS
1
55.38425
14.626890625
-0.7984765625
Al (mono)
1486.69
225
1E+37
1E+37
1E+37
1E+37
FAT
160
1E+37
-4.5
1E+37
1E+37
1E+37
1E+37
1E+37
wide

-1
Kinetic energy
eV
286.69
1
2
Intensity
d
Transmission
d
pulse counting
0.0995024875621891
0
1E+37
0
6
31.1899525550317
55185
55063
55182
55186
55484
55123
54944
55441
56002
55734
55981
55913
56250
56327
56280
56594
56877
56442
56841
57456
57237
57499
57894
58221
57953
58398
58601
58101
57991
58428
58767
58915
58469
58732
59133
59451
59975
60100
60450
60374
60315
60603
61156
61473
61860
61605
62164
62234
61910
61559
62331
62243
62304
62310
62510
62163
62161
62306
62739
62860
62767
62689
63140
63893
64367
65243
65687
66028
66384
66309
66303
66196
65529
66061
66677
66875
67143
66947
67612
67028
66394
65579
65498
65523
65623
66378
67067
67234
68184
69074
69760
70546
71326
73005
74473
75773
77278
76871
75131
73553
72015
71248
68870
64487
60472
57446
55962
54830
54037
53088
52665
52303
51837
51896
51525
51148
51231
50968
51347
51740
51506
51989
52159
52784
53244
53699
54587
55113
56124
57680
58947
59459
59236
58419
57009
54874
52094
49671
48787
47804
47491
47121
47122
46979
46630
46942
47167
46780
46859
46829
46884
46947
47361
47535
47293
47499
47593
47821
47762
47878
47921
47984
48591
48758
49053
48741
48638
48237
48419
48188
48039
48034
48114
48023
48150
48248
48351
48471
48248
48699
48715
48786
49090
49282
48826
49362
49694
49520
49310
49432
49460
49639
49753
49950
50157
50330
50197
50589
50985
51362
51634
51713
51915
52385
52516
52554
52938
52650
52555
52219
51668
51287
51217
50861
50714
51048
50995
50902
51531
51789
52473
53216
54455
56091
58075
59301
59953
59525
59188
57343
54569
51546
50180
48755
47874
47242
46370
45962
45780
45825
45402
45365
45384
45391
45408
45589
45182
45660
45420
45471
45416
45953
45859
46137
45588
45813
45646
45621
45767
45804
45861
46252
46094
46419
46046
46306
46344
46330
46160
46367
46895
46660
46837
46756
46668
46668
47173
46955
46677
47154
47565
47295
47357
47259
47714
47784
47437
47796
47596
47544
47963
47923
47797
47971
47929
47903
48303
48150
47916
48419
48786
48343
48506
48329
48424
48710
49093
49197
48980
48691
49186
48897
49133
49366
49464
49506
49589
49493
49755
49964
49763
50255
50043
50443
50423
50666
50942
50660
50584
50788
50546
50274
50036
50286
50315
50310
50414
50838
50781
50808
51023
51397
51988
52165
52742
53171
53592
52943
52121
51797
51306
50965
51016
51762
51998
51917
51697
51533
51374
51369
51190
51389
51605
52040
52488
52915
53512
53943
54196
55264
56539
58126
60759
61622
57053
52206
50819
50408
50011
49577
49597
50328
50245
49946
50062
50299
50469
50644
50324
50177
50542
50536
50203
50319
51089
50917
50425
50539
50350
50956
50741
50669
50806
51227
51121
51130
51242
50819
51190
51189
51203
51134
51464
51551
51819
51501
51317
51436
51594
51805
51939
52074
52032
52150
51867
52001
52246
52136
52360
52447
52507
52480
52487
52511
52466
52583
53089
53018
52774
52982
53162
53132
53071
52979
53578
53399
53534
53682
53334
53391
53516
53572
53681
53744
53705
53952
53832
54119
54394
54212
54489
54239
54354
54772
54596
54536
54856
55097
54988
54898
55085
55081
55064
54963
54959
55005
54632
54878
54972
54891
55299
55558
55489
55221
55879
55919
56102
56255
56228
56409
56652
56941
57052
56932
56943
56684
56680
56362
56006
55963
55499
55829
56037
56233
56324
55689
55869
55977
56201
56365
56504
57083
57794
59232
62709
71799
75384
66688
58316
56141
55507
55343
55597
55612
55827
55784
55378
55547
55848
55754
55643
55615
56066
56379
56370
56251
56376
56329
56511
56551
56610
56751
56895
56674
57144
56852
57225
57092
57174
57391
57051
57309
57594
57353
57345
57668
57718
57759
57887
57901
58320
58089
58398
58361
58165
58405
58579
58328
58602
59263
59417
59132
59369
59444
59467
59454
59589
59431
59453
60005
59864
59978
60002
60210
60346
60561
61045
60848
60752
60806
60976
60937
60456
61307
61224
61086
61243
61228
61278
61134
61354
61664
62277
62065
62357
62309
62383
62654
62573
62716
63142
63473
63561
63575
64229
64510
64578
64833
64828
65076
65083
65302
65465
65468
65090
64967
65001
64840
65069
64755
64790
65028
65598
66976
68028
69811
70828
72120
72160
71817
69587
66848
64221
62593
61467
60875
60502
59944
59704
59747
58867
58450
58491
58716
58696
58886
58797
58690
58331
58022
57853
57910
57556
57732
58561
59522
62065
67338
74386
80268
84385
79630
66271
57099
54694
54336
54526
54510
53911
53967
54345
54121
54037
54259
54362
54420
54401
55042
54809
54976
55321
55176
55510
55584
55594
55545
55924
56043
55399
55655
55373
55374
55490
54962
55084
55347
56034
55788
55746
56297
57012
56725
57479
58057
58232
58845
59304
60009
59966
60464
60817
61175
61192
61335
61483
61357
61208
61076
61251
61047
60310
59682
59206
59849
60602
62783
65444
67579
71288
74994
75104
73537
73387
73520
80615
87295
74748
50850
38405
35904
35528
35224
35173
34692
34682
34574
34645
34626
34776
34706
34755
34543
34535
34859
34650
34683
34585
34841
34777
34668
34641
34859
34940
34940
34719
34676
34913
34838
34957
35108
34927
34927
34976
34955
34869
34785
34975
35311
34941
34795
35008
35006
34740
35195
35236
35418
35644
35579
36013
36239
36309
36070
35694
35477
35404
35247
35218
35143
35084
35281
35405
35173
35330
35387
35579
35479
35558
35427
35570
35610
35722
35444
35500
35735
35765
35920
35891
35761
35469
35812
35916
35672
35853
35887
35810
35585
35950
35892
35708
35833
36002
35486
35704
35945
36332
36279
36015
36297
36660
36836
36794
36904
36816
36959
36794
36981
37199
36929
36916
37114
37173
36598
36249
35998
35885
35883
35281
35289
35318
34888
34757
35238
34999
35129
35726
36045
36780
37219
37579
38257
38953
39499
39790
40332
40473
40066
40410
40202
40090
39927
38896
37898
36244
34255
32480
31086
29125
27690
25858
24253
22755
22027
21324
21459
21829
22773
24516
26582
29370
33056
36015
37086
38424
42130
53920
87351
166501
150699
58658
21125
12719
6917
5391
4866
4659
4417
4425
4462
4479
4761
5128
5109
4904
4484
4315
4191
4109
4123
4187
4159
4074
4068
4143
4161
4185
4206
4246
4254
4119
4142
4191
4283
4189
4113
4246
4274
4212
4293
4224
4248
4091
4199
4204
4143
4109
4140
4173
4314
4345
4238
4313
4330
4229
4291
4390
4473
4390
4392
4372
4257
4344
4435
4408
4324
4424
4291
4298
4397
4372
4331
4300
4342
4396
4344
4326
4340
4398
4545
4670
5107
5806
6133
6117
5102
4455
4283
4219
4195
4328
4304
4236
4318
4331
4264
4274
4245
4236
4297
4317
4348
4315
4357
4448
4438
4414
4336
4329
4451
4349
4399
4517
4384
4521
4390
4414
4479
4442
4511
4581
4553
4568
4574
4558
4476
4555
4688
4836
4902
4945
4874
4737
4686
4528
4515
4582
4607
4685
4638
4653
4735
4758
4767
4735
4699
4650
4733
4780
4818
4857
4788
4795
4769
4752
4780
4875
4841
4950
4892
4835
4983
4869
4877
4997
5061
4950
5084
5110
5107
5033
5075
5027
5074
5142
5204
5130
5237
5194
5363
5565
5549
5565
5328
5172
5236
5094
5101
5183
5109
5329
5455
5541
5465
5592
5650
5704
5809
5708
5706
5732
5750
5792
5740
5662
5735
5660
5656
5704
5617
5410
5458
5349
5348
5294
5356
5494
5763
6007
6549
7133
7762
8274
8616
7896
6717
5855
5496
5291
5259
5280
5338
5247
5288
5211
5022
5127
5032
4996
4767
4823
5128
5320
5752
6827
8052
9126
10129
10586
8811
5509
3509
3012
2996
2847
2585
2328
2308
2429
2602
2994
3250
3227
2975
2839
2686
2678
2458
2249
2243
2215
2142
2049
1991
1933
1776
1634
1649
1468
1128
777
475
193
84
33
11
6
6
31.1899525550317
C 1s
MX-HT 0p1 20Ap
2023
5
9
20
58
22
2
41
Creation
Created by : XPSUser
Date created : 09/05/2023 20:58
Computer : DESKTOP-U3MGE2F
Location
Location ID : X1
Sample : MX-HT 0p1 20Ap
Description : (55.384,14.627,-0.798)mm
Tilt : 0.00
Charge Neutraliser : On
Filament Current : 0.53A
Filament Bias : 2.02V
Charge Balance : 5.02V
Settings
Excitation
Mode : XPS - monochromatic
Tuning : Spectroscopy
Emission current : 15.00mA
Anode library : Al
ESCA modes
Collimation : Slot
Lens : Hybrid
Resolution : 20.00
Scan
Deflection : (0.000, 0.000)mm
C 1s : 1191.690-1209.690eV, Sweeps 1
Start : 1191.690eV
End : 1209.690eV
Centre : 1200.690eV
Width : 18.000eV
Step size : 0.100eV
Number Steps : 180
Dwell time : 331ms
Sweep time : 60s
Sweeps : 1
Target quality : 200
Instrument Conditions
Work function : -4.50
Acquisition Conditions
X-ray Power : 225.00W
Quality : 302.94
XPS
2
55.38425
14.626890625
-0.7984765625
Al (mono)
1486.69
225
1E+37
1E+37
1E+37
1E+37
FAT
20
1E+37
-4.5
1E+37
1E+37
1E+37
1E+37
1E+37
C
1s
-1
Kinetic energy
eV
1191.69
0.1
2
Intensity
d
Transmission
d
pulse counting
0.331492
1
0
1E+37
1E+37
1E+37
0
362
138
20348
1.33571680812406
1.34279197206053
867
1.33571680812406
804
1.33575611459037
804
1.33579542105669
836
1.335834727523
812
1.33587403398932
827
1.33591334045563
824
1.33595264692194
822
1.33599195338826
889
1.33603125985457
906
1.33607056632088
841
1.3361098727872
862
1.33614917925351
897
1.33618848571983
888
1.33622779218614
878
1.33626709865245
923
1.33630640511877
929
1.33634571158508
915
1.33638501805139
873
1.33642432451771
913
1.33646363098402
931
1.33650293745034
940
1.33654224391665
934
1.33658155038296
981
1.33662085684928
944
1.33666016331559
957
1.3366994697819
998
1.33673877624822
990
1.33677808271453
1049
1.33681738918085
1034
1.33685669564716
1068
1.33689600211347
1073
1.33693530857979
1098
1.3369746150461
1079
1.33701392151241
1109
1.33705322797873
1131
1.33709253444504
1169
1.33713184091135
1190
1.33717114737767
1194
1.33721045384398
1178
1.3372497603103
1249
1.33728906677661
1287
1.33732837324292
1276
1.33736767970924
1268
1.33740698617555
1291
1.33744629264186
1264
1.33748559910818
1272
1.33752490557449
1303
1.33756421204081
1298
1.33760351850712
1241
1.33764282497343
1262
1.33768213143975
1237
1.33772143790606
1294
1.33776074437237
1270
1.33780005083869
1223
1.337839357305
1210
1.33787866377132
1272
1.33791797023763
1215
1.33795727670394
1196
1.33799658317026
1207
1.33803588963657
1162
1.33807519610288
1191
1.3381145025692
1195
1.33815380903551
1190
1.33819311550182
1150
1.33823242196814
1184
1.33827172843445
1211
1.33831103490077
1174
1.33835034136708
1193
1.33838964783339
1201
1.33842895429971
1201
1.33846826076602
1241
1.33850756723233
1207
1.33854687369865
1249
1.33858618016496
1259
1.33862548663128
1219
1.33866479309759
1229
1.3387040995639
1252
1.33874340603022
1278
1.33878271249653
1301
1.33882201896284
1292
1.33886132542916
1326
1.33890063189547
1451
1.33893993836179
1439
1.3389792448281
1465
1.33901855129441
1543
1.33905785776073
1554
1.33909716422704
1629
1.33913647069335
1686
1.33917577715967
1793
1.33921508362598
1787
1.3392543900923
1810
1.33929369655861
1868
1.33933300302492
2045
1.33937230949124
2169
1.33941161595755
2214
1.33945092242386
2261
1.33949022889018
2320
1.33952953535649
2517
1.3395688418228
2591
1.33960814828912
2791
1.33964745475543
2903
1.33968676122175
3155
1.33972606768806
3444
1.33976537415437
3838
1.33980468062069
4391
1.339843987087
5409
1.33988329355331
6891
1.33992260001963
9289
1.33996190648594
12296
1.34000121295226
16014
1.34004051941857
19520
1.34007982588488
20348
1.3401191323512
17837
1.34015843881751
12697
1.34019774528382
8139
1.34023705175014
4609
1.34027635821645
2825
1.34031566468277
1966
1.34035497114908
1443
1.34039427761539
1067
1.34043358408171
868
1.34047289054802
740
1.34051219701433
639
1.34055150348065
531
1.34059080994696
493
1.34063011641328
466
1.34066942287959
418
1.3407087293459
423
1.34074803581222
420
1.34078734227853
433
1.34082664874484
452
1.34086595521116
553
1.34090526167747
660
1.34094456814378
814
1.3409838746101
994
1.34102318107641
1158
1.34106248754273
1169
1.34110179400904
1026
1.34114110047535
835
1.34118040694167
552
1.34121971340798
414
1.34125901987429
299
1.34129832634061
247
1.34133763280692
186
1.34137693927324
186
1.34141624573955
183
1.34145555220586
171
1.34149485867218
176
1.34153416513849
175
1.3415734716048
168
1.34161277807112
180
1.34165208453743
188
1.34169139100375
159
1.34173069747006
153
1.34177000393637
155
1.34180931040269
172
1.341848616869
152
1.34188792333531
146
1.34192722980163
149
1.34196653626794
170
1.34200584273426
167
1.34204514920057
147
1.34208445566688
139
1.3421237621332
139
1.34216306859951
162
1.34220237506582
168
1.34224168153214
159
1.34228098799845
148
1.34232029446476
148
1.34235960093108
151
1.34239890739739
163
1.34243821386371
158
1.34247752033002
139
1.34251682679633
138
1.34255613326265
145
1.34259543972896
157
1.34263474619527
162
1.34267405266159
163
1.3427133591279
141
1.34275266559422
147
1.34279197206053
Cl2s
MX-HT 0p1 20Ap
2023
5
9
20
58
22
2
41
Creation
Created by : XPSUser
Date created : 09/05/2023 20:58
Computer : DESKTOP-U3MGE2F
Location
Location ID : X1
Sample : MX-HT 0p1 20Ap
Description : (55.384,14.627,-0.798)mm
Tilt : 0.00
Charge Neutraliser : On
Filament Current : 0.53A
Filament Bias : 2.02V
Charge Balance : 5.02V
Settings
Excitation
Mode : XPS - monochromatic
Tuning : Spectroscopy
Emission current : 15.00mA
Anode library : Al
ESCA modes
Collimation : Slot
Lens : Hybrid
Resolution : 20.00
Scan
Deflection : (0.000, 0.000)mm
Cl2s : 1201.690-1231.690eV, Sweeps 1
Start : 1201.690eV
End : 1231.690eV
Centre : 1216.690eV
Width : 30.000eV
Step size : 0.100eV
Number Steps : 300
Dwell time : 199ms
Sweep time : 60s
Sweeps : 1
Target quality : 200
Instrument Conditions
Work function : -4.50
Acquisition Conditions
X-ray Power : 225.00W
Quality : 480.29
XPS
3
55.38425
14.626890625
-0.7984765625
Al (mono)
1486.69
225
1E+37
1E+37
1E+37
1E+37
FAT
20
1E+37
-4.5
1E+37
1E+37
1E+37
1E+37
1E+37
Cl2s

-1
Kinetic energy
eV
1201.69
0.1
2
Intensity
d
Transmission
d
pulse counting
0.199335548172757
1
0
1E+37
1E+37
1E+37
0
602
68
12615
1.33964745475543
1.35143939464955
1754
1.33964745475543
1933
1.33968676122175
2076
1.33972606768806
2295
1.33976537415437
2762
1.33980468062069
3311
1.339843987087
4161
1.33988329355331
5689
1.33992260001963
7707
1.33996190648594
10255
1.34000121295226
12183
1.34004051941857
12615
1.34007982588488
10728
1.3401191323512
7543
1.34015843881751
4757
1.34019774528382
2657
1.34023705175014
1629
1.34027635821645
1163
1.34031566468277
870
1.34035497114908
663
1.34039427761539
544
1.34043358408171
460
1.34047289054802
374
1.34051219701433
349
1.34055150348065
300
1.34059080994696
286
1.34063011641328
275
1.34066942287959
257
1.3407087293459
256
1.34074803581222
258
1.34078734227853
258
1.34082664874484
312
1.34086595521116
339
1.34090526167747
419
1.34094456814378
497
1.3409838746101
620
1.34102318107641
713
1.34106248754273
708
1.34110179400904
579
1.34114110047535
384
1.34118040694167
247
1.34121971340798
225
1.34125901987429
152
1.34129832634061
118
1.34133763280692
119
1.34137693927324
102
1.34141624573955
104
1.34145555220586
103
1.34149485867218
94
1.34153416513849
109
1.3415734716048
95
1.34161277807112
97
1.34165208453743
92
1.34169139100375
107
1.34173069747006
100
1.34177000393637
105
1.34180931040269
111
1.341848616869
97
1.34188792333531
95
1.34192722980163
106
1.34196653626794
90
1.34200584273426
88
1.34204514920057
93
1.34208445566688
90
1.3421237621332
105
1.34216306859951
89
1.34220237506582
102
1.34224168153214
93
1.34228098799845
96
1.34232029446476
98
1.34235960093108
96
1.34239890739739
96
1.34243821386371
91
1.34247752033002
81
1.34251682679633
76
1.34255613326265
79
1.34259543972896
78
1.34263474619527
92
1.34267405266159
83
1.3427133591279
83
1.34275266559422
102
1.34279197206053
94
1.34283127852684
89
1.34287058499316
94
1.34290989145947
89
1.34294919792578
98
1.3429885043921
97
1.34302781085841
94
1.34306711732473
92
1.34310642379104
77
1.34314573025735
85
1.34318503672367
81
1.34322434318998
76
1.34326364965629
83
1.34330295612261
102
1.34334226258892
90
1.34338156905524
93
1.34342087552155
77
1.34346018198786
81
1.34349948845418
80
1.34353879492049
83
1.3435781013868
90
1.34361740785312
108
1.34365671431943
99
1.34369602078574
90
1.34373532725206
104
1.34377463371837
82
1.34381394018469
84
1.343853246651
85
1.34389255311731
80
1.34393185958363
79
1.34397116604994
69
1.34401047251625
74
1.34404977898257
91
1.34408908544888
94
1.3441283919152
88
1.34416769838151
77
1.34420700484782
90
1.34424631131414
88
1.34428561778045
88
1.34432492424676
101
1.34436423071308
87
1.34440353717939
94
1.34444284364571
98
1.34448215011202
93
1.34452145657833
94
1.34456076304465
77
1.34460006951096
82
1.34463937597727
83
1.34467868244359
95
1.3447179889099
90
1.34475729537622
84
1.34479660184253
99
1.34483590830884
110
1.34487521477516
109
1.34491452124147
91
1.34495382770778
88
1.3449931341741
109
1.34503244064041
91
1.34507174710672
99
1.34511105357304
110
1.34515036003935
100
1.34518966650567
123
1.34522897297198
102
1.34526827943829
109
1.34530758590461
116
1.34534689237092
102
1.34538619883723
98
1.34542550530355
102
1.34546481176986
91
1.34550411823618
114
1.34554342470249
122
1.3455827311688
94
1.34562203763512
109
1.34566134410143
121
1.34570065056774
111
1.34573995703406
119
1.34577926350037
102
1.34581856996669
107
1.345857876433
113
1.34589718289931
100
1.34593648936563
95
1.34597579583194
104
1.34601510229825
99
1.34605440876457
104
1.34609371523088
99
1.34613302169719
99
1.34617232816351
100
1.34621163462982
86
1.34625094109614
105
1.34629024756245
91
1.34632955402876
81
1.34636886049508
90
1.34640816696139
98
1.3464474734277
76
1.34648677989402
80
1.34652608636033
91
1.34656539282665
82
1.34660469929296
95
1.34664400575927
77
1.34668331222559
75
1.3467226186919
84
1.34676192515821
84
1.34680123162453
89
1.34684053809084
93
1.34687984455716
83
1.34691915102347
85
1.34695845748978
88
1.3469977639561
85
1.34703707042241
73
1.34707637688872
70
1.34711568335504
82
1.34715498982135
96
1.34719429628767
81
1.34723360275398
75
1.34727290922029
84
1.34731221568661
85
1.34735152215292
83
1.34739082861923
70
1.34743013508555
82
1.34746944155186
91
1.34750874801817
81
1.34754805448449
88
1.3475873609508
88
1.34762666741712
79
1.34766597388343
101
1.34770528034974
87
1.34774458681606
71
1.34778389328237
85
1.34782319974868
93
1.347862506215
85
1.34790181268131
77
1.34794111914763
84
1.34798042561394
79
1.34801973208025
88
1.34805903854657
88
1.34809834501288
80
1.34813765147919
99
1.34817695794551
81
1.34821626441182
76
1.34825557087814
85
1.34829487734445
89
1.34833418381076
94
1.34837349027708
92
1.34841279674339
78
1.3484521032097
76
1.34849140967602
96
1.34853071614233
89
1.34857002260865
83
1.34860932907496
99
1.34864863554127
92
1.34868794200759
80
1.3487272484739
84
1.34876655494021
82
1.34880586140653
75
1.34884516787284
69
1.34888447433916
84
1.34892378080547
82
1.34896308727178
92
1.3490023937381
89
1.34904170020441
76
1.34908100667072
83
1.34912031313704
94
1.34915961960335
93
1.34919892606966
87
1.34923823253598
90
1.34927753900229
90
1.34931684546861
85
1.34935615193492
85
1.34939545840123
98
1.34943476486755
85
1.34947407133386
70
1.34951337780017
77
1.34955268426649
75
1.3495919907328
89
1.34963129719912
87
1.34967060366543
83
1.34970991013174
97
1.34974921659806
75
1.34978852306437
85
1.34982782953068
86
1.349867135997
68
1.34990644246331
85
1.34994574892963
86
1.34998505539594
86
1.35002436186225
90
1.35006366832857
82
1.35010297479488
90
1.35014228126119
86
1.35018158772751
81
1.35022089419382
79
1.35026020066013
83
1.35029950712645
84
1.35033881359276
82
1.35037812005908
91
1.35041742652539
103
1.3504567329917
93
1.35049603945802
95
1.35053534592433
95
1.35057465239064
89
1.35061395885696
74
1.35065326532327
83
1.35069257178959
90
1.3507318782559
80
1.35077118472221
84
1.35081049118853
86
1.35084979765484
78
1.35088910412115
83
1.35092841058747
87
1.35096771705378
88
1.3510070235201
89
1.35104632998641
92
1.35108563645272
90
1.35112494291904
93
1.35116424938535
88
1.35120355585166
79
1.35124286231798
85
1.35128216878429
88
1.35132147525061
80
1.35136078171692
82
1.35140008818323
81
1.35143939464955
F1s
MX-HT 0p1 20Ap
2023
5
9
20
58
22
2
41
Creation
Created by : XPSUser
Date created : 09/05/2023 20:58
Computer : DESKTOP-U3MGE2F
Location
Location ID : X1
Sample : MX-HT 0p1 20Ap
Description : (55.384,14.627,-0.798)mm
Tilt : 0.00
Charge Neutraliser : On
Filament Current : 0.53A
Filament Bias : 2.02V
Charge Balance : 5.02V
Settings
Excitation
Mode : XPS - monochromatic
Tuning : Spectroscopy
Emission current : 15.00mA
Anode library : Al
ESCA modes
Collimation : Slot
Lens : Hybrid
Resolution : 20.00
Scan
Deflection : (0.000, 0.000)mm
F1s : 791.690-811.690eV, Sweeps 5
Start : 791.690eV
End : 811.690eV
Centre : 801.690eV
Width : 20.000eV
Step size : 0.100eV
Number Steps : 200
Dwell time : 299ms
Sweep time : 60s
Sweeps : 5
Target quality : 200
Instrument Conditions
Work function : -4.50
Acquisition Conditions
X-ray Power : 225.00W
Quality : 101.70
XPS
4
55.38425
14.626890625
-0.7984765625
Al (mono)
1486.69
225
1E+37
1E+37
1E+37
1E+37
FAT
20
1E+37
-4.5
1E+37
1E+37
1E+37
1E+37
1E+37
F1s

-1
Kinetic energy
eV
791.69
0.1
2
Intensity
d
Transmission
d
pulse counting
0.298507462686567
5
0
1E+37
1E+37
1E+37
0
402
9388
16364
1.45714403256293
1.46809980524165
9624
1.46809980524165
9714
1.46804594968559
9744
1.46799209412953
9714
1.46793823857347
9772
1.46788438301742
9824
1.46783052746136
9774
1.4677766719053
9802
1.46772281634924
9814
1.46766896079318
9720
1.46761510523713
9724
1.46756124968107
9859
1.46750739412501
9855
1.46745353856895
9636
1.46739968301289
9860
1.46734582745684
9707
1.46729197190078
9697
1.46723811634472
9738
1.46718426078866
9704
1.4671304052326
9762
1.46707654967654
9771
1.46702269412049
9635
1.46696883856443
9726
1.46691498300837
9885
1.46686112745231
9747
1.46680727189625
9728
1.4667534163402
9700
1.46669956078414
9628
1.46664570522808
9681
1.46659184967202
9950
1.46653799411596
9670
1.46648413855991
9916
1.46643028300385
9822
1.46637642744779
9686
1.46632257189173
9697
1.46626871633567
9811
1.46621486077962
9774
1.46616100522356
9820
1.4661071496675
9870
1.46605329411144
9684
1.46599943855538
9731
1.46594558299933
9800
1.46589172744327
9757
1.46583787188721
9627
1.46578401633115
9810
1.46573016077509
9846
1.46567630521904
9850
1.46562244966298
9783
1.46556859410692
9825
1.46551473855086
9799
1.4654608829948
9796
1.46540702743874
9863
1.46535317188269
9844
1.46529931632663
9872
1.46524546077057
9803
1.46519160521451
9785
1.46513774965845
9917
1.4650838941024
9874
1.46503003854634
9896
1.46497618299028
9900
1.46492232743422
9871
1.46486847187816
9889
1.46481461632211
9873
1.46476076076605
9833
1.46470690520999
9660
1.46465304965393
9831
1.46459919409787
9854
1.46454533854182
9767
1.46449148298576
9783
1.4644376274297
9840
1.46438377187364
9955
1.46432991631758
9773
1.46427606076153
9881
1.46422220520547
10022
1.46416834964941
9976
1.46411449409335
9903
1.46406063853729
10007
1.46400678298124
9984
1.46395292742518
9975
1.46389907186912
9923
1.46384521631306
10058
1.463791360757
10183
1.46373750520094
10302
1.46368364964489
10198
1.46362979408883
10136
1.46357593853277
10264
1.46352208297671
10370
1.46346822742065
10506
1.4634143718646
10507
1.46336051630854
10576
1.46330666075248
10741
1.46325280519642
10710
1.46319894964036
10879
1.46314509408431
11059
1.46309123852825
11221
1.46303738297219
11132
1.46298352741613
11453
1.46292967186007
11750
1.46287581630402
11960
1.46282196074796
12449
1.4627681051919
12937
1.46271424963584
13706
1.46266039407978
14641
1.46260653852373
15307
1.46255268296767
15986
1.46249882741161
16127
1.46244497185555
16329
1.46239111629949
16364
1.46233726074344
15961
1.46228340518738
15338
1.46222954963132
14649
1.46217569407526
13816
1.4621218385192
12825
1.46206798296314
12179
1.46201412740709
11696
1.46196027185103
11114
1.46190641629497
10713
1.46185256073891
10507
1.46179870518285
10506
1.4617448496268
10291
1.46169099407074
10105
1.46163713851468
9945
1.46158328295862
9826
1.46152942740256
9897
1.46147557184651
9795
1.46142171629045
9725
1.46136786073439
9728
1.46131400517833
9701
1.46126014962227
9706
1.46120629406622
9607
1.46115243851016
9623
1.4610985829541
9474
1.46104472739804
9570
1.46099087184198
9728
1.46093701628593
9612
1.46088316072987
9615
1.46082930517381
9649
1.46077544961775
9800
1.46072159406169
9806
1.46066773850564
9760
1.46061388294958
9751
1.46056002739352
9645
1.46050617183746
9677
1.4604523162814
9735
1.46039846072534
9665
1.46034460516929
9723
1.46029074961323
9698
1.46023689405717
9814
1.46018303850111
9761
1.46012918294505
9643
1.460075327389
9675
1.46002147183294
9388
1.45996761627688
9590
1.45991376072082
9648
1.45985990516476
9726
1.45980604960871
9553
1.45975219405265
9540
1.45969833849659
9686
1.45964448294053
9564
1.45959062738447
9735
1.45953677182842
9696
1.45948291627236
9647
1.4594290607163
9597
1.45937520516024
9649
1.45932134960418
9790
1.45926749404813
9644
1.45921363849207
9685
1.45915978293601
9680
1.45910592737995
9622
1.45905207182389
9647
1.45899821626783
9735
1.45894436071178
9611
1.45889050515572
9625
1.45883664959966
9721
1.4587827940436
9632
1.45872893848754
9636
1.45867508293149
9678
1.45862122737543
9631
1.45856737181937
9534
1.45851351626331
9690
1.45845966070725
9597
1.4584058051512
9660
1.45835194959514
9857
1.45829809403908
9702
1.45824423848302
9696
1.45818054888434
9715
1.45811576661425
9727
1.45805098434416
9486
1.45798620207407
9576
1.45792141980398
9627
1.4578566375339
9468
1.45779185526381
9543
1.45772707299372
9615
1.45766229072363
9771
1.45759750845354
9649
1.45753272618346
9742
1.45746794391337
9614
1.45740316164328
9652
1.45733837937319
9659
1.4572735971031
9739
1.45720881483302
9735
1.45714403256293
O1s
MX-HT 0p1 20Ap
2023
5
9
20
58
22
2
41
Creation
Created by : XPSUser
Date created : 09/05/2023 20:58
Computer : DESKTOP-U3MGE2F
Location
Location ID : X1
Sample : MX-HT 0p1 20Ap
Description : (55.384,14.627,-0.798)mm
Tilt : 0.00
Charge Neutraliser : On
Filament Current : 0.53A
Filament Bias : 2.02V
Charge Balance : 5.02V
Settings
Excitation
Mode : XPS - monochromatic
Tuning : Spectroscopy
Emission current : 15.00mA
Anode library : Al
ESCA modes
Collimation : Slot
Lens : Hybrid
Resolution : 20.00
Scan
Deflection : (0.000, 0.000)mm
O1s : 946.690-961.690eV, Sweeps 5
Start : 946.690eV
End : 961.690eV
Centre : 954.190eV
Width : 15.000eV
Step size : 0.100eV
Number Steps : 150
Dwell time : 397ms
Sweep time : 60s
Sweeps : 5
Target quality : 200
Instrument Conditions
Work function : -4.50
Acquisition Conditions
X-ray Power : 225.00W
Quality : 114.84
XPS
5
55.38425
14.626890625
-0.7984765625
Al (mono)
1486.69
225
1E+37
1E+37
1E+37
1E+37
FAT
20
1E+37
-4.5
1E+37
1E+37
1E+37
1E+37
1E+37
O1s

-1
Kinetic energy
eV
946.69
0.1
2
Intensity
d
Transmission
d
pulse counting
0.397351
5
0
1E+37
1E+37
1E+37
0
302
11804
20866
1.39073012089434
1.39549665066723
12775
1.39549665066723
12864
1.39546487380208
12678
1.39543309693692
12686
1.39540132007177
12719
1.39536954320662
12555
1.39533776634147
12461
1.39530598947631
12686
1.39527421261116
12554
1.39524243574601
12584
1.39521065888085
12757
1.3951788820157
12770
1.39514710515055
12737
1.3951153282854
12651
1.39508355142024
12741
1.39505177455509
12697
1.39501999768994
12615
1.39498822082479
12540
1.39495644395963
12659
1.39492466709448
12653
1.39489289022933
12656
1.39486111336418
12506
1.39482933649902
12543
1.39479755963387
12768
1.39476578276872
12517
1.39473400590357
12626
1.39470222903841
12626
1.39467045217326
12589
1.39463867530811
12709
1.39460689844296
12813
1.3945751215778
12799
1.39454334471265
12686
1.3945115678475
12669
1.39447979098235
12732
1.39444801411719
12781
1.39441623725204
12581
1.39438446038689
12560
1.39435268352174
12648
1.39432090665658
12746
1.39428912979143
12694
1.39425735292628
12698
1.39422557606112
12669
1.39419379919597
12850
1.39416202233082
12852
1.39413024546567
12761
1.39409846860051
12818
1.39406669173536
12913
1.39403491487021
12745
1.39400313800506
12772
1.3939713611399
13004
1.39393958427475
12978
1.3939078074096
12798
1.39387603054445
12919
1.39384425367929
12812
1.39381247681414
12989
1.39378069994899
13044
1.39374892308384
13021
1.39371714621868
12998
1.39368536935353
12980
1.39365359248838
13163
1.39362181562323
13414
1.39359003875807
13467
1.39355826189292
13520
1.39352648502777
13823
1.39349470816262
13790
1.39346293129746
13990
1.39343115443231
14225
1.39339937756716
14315
1.393367600702
14724
1.39333582383685
14930
1.3933040469717
15124
1.39327227010655
15254
1.39324049324139
15832
1.39320871637624
16146
1.39317693951109
16083
1.39314516264594
16305
1.39311338578078
16639
1.39308160891563
17003
1.39304983205048
17061
1.39301805518533
17293
1.39298627832017
17399
1.39295450145502
17609
1.39292272458987
17803
1.39289094772472
17880
1.39285917085956
18068
1.39282739399441
17932
1.39279561712926
18114
1.39276384026411
18258
1.39273206339895
18521
1.3927002865338
18347
1.39266850966865
18475
1.3926367328035
18787
1.39260495593834
19127
1.39257317907319
19346
1.39254140220804
19626
1.39250962534289
19928
1.39247784847773
20347
1.39244607161258
20587
1.39241429474743
20732
1.39238251788227
20866
1.39235074101712
20488
1.39231896415197
20335
1.39228718728682
20052
1.39225541042166
19570
1.39222363355651
19368
1.39219185669136
19031
1.39216007982621
18968
1.39212830296105
19069
1.3920965260959
18941
1.39206474923075
18970
1.3920329723656
18596
1.39200119550044
17709
1.39196941863529
16762
1.39193764177014
15457
1.39190586490499
14533
1.39187408803983
13792
1.39184231117468
13236
1.39181053430953
12888
1.39177875744438
12514
1.39174698057922
12359
1.39171520371407
12191
1.39168342684892
12112
1.39165164998377
12205
1.39161987311861
12168
1.39158809625346
12306
1.39155631938831
12253
1.39152454252316
12031
1.391492765658
12021
1.39146098879285
11985
1.3914292119277
12026
1.39139743506254
12001
1.39136565819739
11985
1.39133388133224
11804
1.39130210446709
12055
1.39127032760193
11993
1.39123855073678
12010
1.39120677387163
11917
1.39117499700648
11903
1.39114322014132
11855
1.39111144327617
11961
1.39107966641102
11849
1.39104788954587
11837
1.39101611268071
11852
1.39098433581556
11815
1.39095255895041
11838
1.39092078208526
11852
1.3908890052201
11909
1.39085722835495
11908
1.3908254514898
11909
1.39079367462465
11841
1.39076189775949
11903
1.39073012089434
Cl2p
MX-HT 0p1 20Ap
2023
5
9
20
58
22
2
41
Creation
Created by : XPSUser
Date created : 09/05/2023 20:58
Computer : DESKTOP-U3MGE2F
Location
Location ID : X1
Sample : MX-HT 0p1 20Ap
Description : (55.384,14.627,-0.798)mm
Tilt : 0.00
Charge Neutraliser : On
Filament Current : 0.53A
Filament Bias : 2.02V
Charge Balance : 5.02V
Settings
Excitation
Mode : XPS - monochromatic
Tuning : Spectroscopy
Emission current : 15.00mA
Anode library : Al
ESCA modes
Collimation : Slot
Lens : Hybrid
Resolution : 20.00
Scan
Deflection : (0.000, 0.000)mm
Cl2p : 1278.690-1291.690eV, Sweeps 5
Start : 1278.690eV
End : 1291.690eV
Centre : 1285.190eV
Width : 13.000eV
Step size : 0.100eV
Number Steps : 130
Dwell time : 458ms
Sweep time : 60s
Sweeps : 5
Target quality : 200
Instrument Conditions
Work function : -4.50
Acquisition Conditions
X-ray Power : 225.00W
Quality : 45.89
XPS
6
55.38425
14.626890625
-0.7984765625
Al (mono)
1486.69
225
1E+37
1E+37
1E+37
1E+37
FAT
20
1E+37
-4.5
1E+37
1E+37
1E+37
1E+37
1E+37
Cl2p

-1
Kinetic energy
eV
1278.69
0.1
2
Intensity
d
Transmission
d
pulse counting
0.458015267175573
5
0
1E+37
1E+37
1E+37
0
262
947
2031
1.34975176565477
1.35099769238123
952
1.35099769238123
1005
1.35098810832949
1037
1.35097852427775
1020
1.35096894022601
1051
1.35095935617426
1028
1.35094977212252
962
1.35094018807078
1000
1.35093060401904
1038
1.3509210199673
1026
1.35091143591555
1054
1.35090185186381
1036
1.35089226781207
1047
1.35088268376033
1027
1.35087309970859
1035
1.35086351565684
991
1.3508539316051
1040
1.35084434755336
974
1.35083476350162
1018
1.35082517944988
1033
1.35081559539813
1049
1.35080601134639
1035
1.35079642729465
1036
1.35078684324291
1036
1.35077725919117
1019
1.35076767513942
1041
1.35075809108768
1051
1.35074850703594
1000
1.3507389229842
1065
1.35072933893246
1075
1.35071975488071
1051
1.35071017082897
1054
1.35070058677723
1019
1.35069100272549
980
1.35068141867375
965
1.350671834622
1000
1.35066225057026
1005
1.35065266651852
1039
1.35064308246678
1048
1.35063349841504
1042
1.35062391436329
997
1.35061433031155
1029
1.35060474625981
1045
1.35059516220807
992
1.35058557815633
988
1.35057599410458
1026
1.35056641005284
1029
1.3505568260011
1042
1.35054724194936
1086
1.35053765789762
1049
1.35052807384587
1019
1.35051848979413
1051
1.35050890574239
1066
1.35049932169065
1077
1.35048973763891
1075
1.35048015358716
1017
1.35047056953542
1017
1.35046098548368
1020
1.35045140143194
1085
1.3504418173802
1052
1.35043223332845
1016
1.35042264927671
1080
1.35041306522497
1054
1.35040348117323
1057
1.35039389712149
1052
1.35038431306974
1100
1.350374729018
1117
1.35036514496626
1118
1.35035556091452
1165
1.35034597686278
1151
1.35033639281103
1239
1.35032680875929
1185
1.35031722470755
1213
1.35030764065581
1274
1.35029805660407
1320
1.35028847255232
1389
1.35027888850058
1473
1.35026930444884
1544
1.3502597203971
1500
1.35025013634536
1520
1.35024055229361
1502
1.35023096824187
1492
1.35022138419013
1385
1.35021180013839
1356
1.35020221608665
1326
1.3501926320349
1243
1.35018304798316
1211
1.35017346393142
1257
1.35016387987968
1363
1.35015429582794
1466
1.35014471177619
1522
1.35013512772445
1683
1.35012554367271
1766
1.35011595962097
1867
1.35010637556923
2031
1.35009679151748
1911
1.35008720746574
1872
1.350077623414
1726
1.35006803936226
1534
1.35005845531052
1409
1.35004887125877
1235
1.35003928720703
1177
1.35002970315529
1125
1.35002011910355
1027
1.35001053505181
1017
1.35000095100006
1005
1.34999136694832
1068
1.34998178289658
1019
1.34997219884484
1013
1.3499626147931
996
1.34995303074135
1038
1.34994344668961
1001
1.34993386263787
1006
1.34992427858613
1001
1.34991469453439
986
1.34990511048264
981
1.3498955264309
1010
1.34988594237916
1022
1.34987635832742
1022
1.34986677427568
994
1.34985719022393
1026
1.34984760617219
1027
1.34983802212045
1032
1.34982843806871
996
1.34981885401697
989
1.34980926996522
961
1.34979968591348
1006
1.34979010186174
1040
1.34978051781
975
1.34977093375826
947
1.34976134970651
960
1.34975176565477
Ti3s
MX-HT 0p1 20Ap
2023
5
9
20
58
22
2
41
Creation
Created by : XPSUser
Date created : 09/05/2023 20:58
Computer : DESKTOP-U3MGE2F
Location
Location ID : X1
Sample : MX-HT 0p1 20Ap
Description : (55.384,14.627,-0.798)mm
Tilt : 0.00
Charge Neutraliser : On
Filament Current : 0.53A
Filament Bias : 2.02V
Charge Balance : 5.02V
Settings
Excitation
Mode : XPS - monochromatic
Tuning : Spectroscopy
Emission current : 15.00mA
Anode library : Al
ESCA modes
Collimation : Slot
Lens : Hybrid
Resolution : 20.00
Scan
Deflection : (0.000, 0.000)mm
Ti3s : 1412.690-1442.690eV, Sweeps 5
Start : 1412.690eV
End : 1442.690eV
Centre : 1427.690eV
Width : 30.000eV
Step size : 0.100eV
Number Steps : 300
Dwell time : 199ms
Sweep time : 60s
Sweeps : 5
Target quality : 200
Instrument Conditions
Work function : -4.50
Acquisition Conditions
X-ray Power : 225.00W
Quality : 31.29
XPS
7
55.38425
14.626890625
-0.7984765625
Al (mono)
1486.69
225
1E+37
1E+37
1E+37
1E+37
FAT
20
1E+37
-4.5
1E+37
1E+37
1E+37
1E+37
1E+37
Ti3s

-1
Kinetic energy
eV
1412.69
0.1
2
Intensity
d
Transmission
d
pulse counting
0.199335548172757
5
0
1E+37
1E+37
1E+37
0
602
432
924
1.29494863949153
1.2965505499007
569
1.2965505499007
558
1.29654521019933
594
1.29653987049797
567
1.2965345307966
574
1.29652919109524
568
1.29652385139388
535
1.29651851169251
584
1.29651317199115
558
1.29650783228978
538
1.29650249258842
544
1.29649715288706
561
1.29649181318569
570
1.29648647348433
526
1.29648113378297
545
1.2964757940816
552
1.29647045438024
576
1.29646511467887
571
1.29645977497751
556
1.29645443527615
544
1.29644909557478
548
1.29644375587342
534
1.29643841617205
519
1.29643307647069
546
1.29642773676933
542
1.29642239706796
512
1.2964170573666
546
1.29641171766523
520
1.29640637796387
555
1.29640103826251
528
1.29639569856114
537
1.29639035885978
547
1.29638501915842
533
1.29637967945705
545
1.29637433975569
545
1.29636900005432
535
1.29636366035296
561
1.2963583206516
540
1.29635298095023
580
1.29634764124887
548
1.2963423015475
530
1.29633696184614
519
1.29633162214478
529
1.29632628244341
529
1.29632094274205
578
1.29631560304068
555
1.29631026333932
516
1.29630492363796
515
1.29629958393659
525
1.29629424423523
502
1.29628890453386
514
1.2962835648325
503
1.29627822513114
500
1.29627288542977
509
1.29626754572841
475
1.29626220602705
514
1.29625686632568
507
1.29625152662432
519
1.29624618692295
531
1.29624084722159
531
1.29623550752023
522
1.29623016781886
521
1.2962248281175
529
1.29621948841613
527
1.29621414871477
504
1.29620880901341
508
1.29620346931204
499
1.29619812961068
521
1.29619278990931
515
1.29618745020795
485
1.29618211050659
513
1.29617677080522
530
1.29617143110386
547
1.2961660914025
523
1.29616075170113
494
1.29615541199977
533
1.2961500722984
537
1.29614473259704
527
1.29613939289568
525
1.29613405319431
544
1.29612871349295
554
1.29612337379158
520
1.29611803409022
537
1.29611269438886
532
1.29610735468749
542
1.29610201498613
555
1.29609667528476
529
1.2960913355834
544
1.29608599588204
537
1.29608065618067
539
1.29607531647931
542
1.29606997677794
534
1.29606463707658
569
1.29605929737522
567
1.29605395767385
561
1.29604861797249
577
1.29604327827113
569
1.29603793856976
565
1.2960325988684
579
1.29602725916703
587
1.29602191946567
598
1.29601657976431
597
1.29601124006294
622
1.29600590036158
615
1.29600056066021
590
1.29599522095885
582
1.29598988125749
613
1.29598454155612
606
1.29597920185476
651
1.29597386215339
672
1.29596852245203
670
1.29596318275067
634
1.2959578430493
646
1.29595250334794
694
1.29594716364658
696
1.29594182394521
701
1.29593648424385
723
1.29593114454248
706
1.29592580484112
747
1.29592046513976
732
1.29591512543839
770
1.29590978573703
769
1.29590444603566
736
1.2958991063343
768
1.29589376663294
788
1.29588842693157
774
1.29588308723021
801
1.29587774752884
751
1.29587240782748
749
1.29586706812612
793
1.29586172842475
793
1.29585638872339
744
1.29585104902202
790
1.29584570932066
794
1.2958403696193
793
1.29583502991793
823
1.29582969021657
835
1.29582435051521
838
1.29581901081384
833
1.29581367111248
837
1.29580833141111
858
1.29580299170975
854
1.29579765200839
924
1.29579231230702
905
1.29578697260566
851
1.29578163290429
862
1.29577629320293
865
1.29577095350157
879
1.2957656138002
897
1.29576027409884
857
1.29575493439747
914
1.29574959469611
884
1.29574425499475
858
1.29573891529338
869
1.29573357559202
869
1.29572823589066
838
1.29572289618929
823
1.29571755648793
832
1.29571221678656
796
1.2957068770852
788
1.29570153738384
720
1.29569619768247
685
1.29569085798111
700
1.29568551827974
681
1.29568017857838
649
1.29567483887702
684
1.29566949917565
648
1.29566415947429
654
1.29565881977292
629
1.29565348007156
624
1.2956481403702
612
1.29564280066883
582
1.29563746096747
572
1.2956321212661
556
1.29562678156474
535
1.29562144186338
547
1.29561610216201
545
1.29561076246065
554
1.29560542275929
576
1.29560008305792
553
1.29559474335656
533
1.29558940365519
543
1.29558406395383
541
1.29557872425247
506
1.2955733845511
543
1.29556804484974
547
1.29556270514837
535
1.29555736544701
498
1.29555202574565
528
1.29554668604428
515
1.29554134634292
496
[...]
502
1.29517290694881
526
1.29516756724745
522
1.29516222754608
512
1.29515688784472
487
1.29515154814335
494
1.29514620844199
465
1.29514086874063
495
1.29513552903926
497
1.2951301893379
481
1.29512484963653
479
1.29511950993517
498
1.29511417023381
491
1.29510883053244
501
1.29510349083108
520
1.29509815112971
480
1.29509281142835
504
1.29508747172699
499
1.29508213202562
501
1.29507679232426
502
1.29507145262289
499
1.29506611292153
485
1.29506077322017
502
1.2950554335188
495
1.29505009381744
465
1.29504475411608
492
1.29503941441471
484
1.29503407471335
512
1.29502873501198
497
1.29502339531062
507
1.29501805560926
488
1.29501271590789
511
1.29500737620653
496
1.29500203650516
471
1.2949966968038
473
1.29499135710244
489
1.29498601740107
458
1.29498067769971
488
1.29497533799834
465
1.29496999829698
449
1.29496465859562
449
1.29495931889425
444
1.29495397919289
447
1.29494863949153
451
1.29494329979016
459
1.2949379600888
459
1.29493262038743
419
1.29492728068607
445
1.29492194098471
478
1.29491660128334
465
1.29491126158198
470
1.29490592188061
453
1.29490058217925
443
1.29489524247789
455
1.29488990277652
461
1.29488456307516
453
1.29487922337379
464
1.29487388367243
481
1.29486854397107
448
1.2948632042697
434
1.29485786456834
452
1.29485252486697
456
1.29484718516561
476
1.29484184546425
450
1.29483650576288
463
1.29483116606152
489
1.29482582636016
448
1.29482048665879
449
1.29481514695743
477
1.29480980725606
456
1.2948044675547
465
1.29479912785334
481
1.29479378815197
471
1.29478844845061
494
1.29478310874924
501
1.29477776904788
466
1.29477242934652
466
1.29476708964515
488
1.29476174994379
513
1.29475641024242
508
1.29475107054106
529
1.2947457308397
529
1.29474039113833
500
1.29473505143697
504
1.29472971173561
517
1.29472437203424
548
1.29471903233288
520
1.29471369263151
525
1.29470835293015
542
1.29470301322879
522
1.29469767352742
551
1.29469233382606
530
1.29468699412469
567
1.29468165442333
552
1.29467631472197
575
1.2946709750206
581
1.29466563531924
579
1.29466029561787
616
1.29465495591651
662
1.29464961621515
619
1.29464427651378
674
1.29463893681242
712
1.29463359711105
739
1.29462825740969
750
1.29462291770833
737
1.29461757800696
746
1.2946122383056
760
1.29460689860424
781
1.29460155890287
786
1.29459621920151
826
1.29459087950014
863
1.29458553979878
815
1.29458020009742
853
1.29457486039605
880
1.29456952069469
888
1.29456418099332
889
1.29455884129196
903
1.2945535015906
859
1.29454816188923
877
1.29454282218787
892
1.2945374824865
856
1.29453214278514
884
1.29452680308378
886
1.29452146338241
839
1.29451612368105
926
1.29451078397968
949
1.29450544427832
949
1.29450010457696
928
1.29449476487559
978
1.29448942517423
1001
1.29448408547287
963
1.2944787457715
1015
1.29447340607014
1075
1.29446806636877
1096
1.29446272666741
1133
1.29445738696605
1123
1.29445204726468
1173
1.29444670756332
1124
1.29444136786195
1153
1.29443602816059
1172
1.29443068845923
1191
1.29442534875786
1150
1.2944200090565
1170
1.29441466935513
1139
1.29440932965377
1122
1.29440398995241
1070
1.29439865025104
1114
1.29439331054968
1025
1.29438797084832
970
1.29438263114695
950
1.29437729144559
880
1.29437195174422
808
1.29436661204286
767
1.2943612723415
708
1.29435593264013
650
1.29435059293877
527
1.2943452532374
488
1.29433991353604
459
1.29433457383468
417
1.29432923413331
378
1.29432389443195
389
1.29431855473058
320
1.29431321502922
317
1.29430787532786
312
1.29430253562649
297
1.29429719592513
284
1.29429185622377
287
1.2942865165224
293
1.29428117682104
275
1.29427583711967
282
1.29427049741831
273
1.29426515771695
280
1.29425981801558
280
1.29425447831422
262
1.29424913861285
279
1.29424379891149
292
1.29423845921013
273
1.29423311950876
264
1.2942277798074
253
1.29422244010603
295
1.29421710040467
276
1.29421176070331
289
1.29420642100194
294
1.29420108130058
311
1.29419574159921
302
1.29419040189785
277
1.29418506219649
297
1.29417972249512
320
1.29417438279376
323
1.2941690430924
307
1.29416370339103
318
1.29415836368967
292
1.2941530239883
317
1.29414768428694
335
1.29414234458558
322
1.29413700488421
311
1.29413166518285
288
1.29412632548148
274
1.29412098578012
309
1.29411564607876
279
1.29411030637739
275
1.29410496667603
252
1.29409962697466
261
1.2940942872733
270
1.29408894757194
265
1.29408360787057
255
1.29407826816921
245
1.29407292846784
235
1.29406758876648
236
1.29406224906512
233
1.29405690936375
222
1.29405156966239
213
1.29404622996103
223
1.29404089025966
249
1.2940355505583
222
1.29403021085693
222
1.29402487115557
227
1.29401953145421
224
1.29401419175284
213
1.29400885205148
210
1.29400351235011
223
1.29399817264875
217
1.29399283294739
227
1.29398749324602
228
1.29398215354466
223
1.29397681384329
223
1.29397147414193
236
1.29396613444057
241
1.2939607947392
199
1.29395545503784
236
1.29395011533648
250
1.29394477563511
219
1.29393943593375
235
1.29393409623238
241
1.29392875653102
230
1.29392341682966
253
1.29391807712829
235
1.29391273742693
232
1.29390739772556
250
1.2939020580242
234
1.29389671832284
225
1.29389137862147
257
1.29388603892011
259
1.29388069921874
230
1.29387535951738
247
1.29387001981602
254
1.29386468011465
279
1.29385934041329
298
1.29385400071192
267
1.29384866101056
281
1.2938433213092
258
1.29383798160783
282
1.29383264190647
295
1.29382730220511
281
1.29382196250374
270
1.29381662280238
293
1.29381128310101
295
1.29380594339965
301
1.29380060369829
310
1.29379526399692
313
1.29378992429556
300
1.29378458459419
326
1.29377924489283
338
1.29377390519147
330
1.2937685654901
328
1.29376322578874
336
1.29375788608737
345
1.29375254638601
358
1.29374720668465
363
1.29374186698328
355
1.29373652728192
366
1.29373118758056
371
1.29372584787919
355
1.29372050817783
357
1.29371516847646
357
1.2937098287751
368
1.29370448907374
367
1.29369914937237
333
1.29369380967101
353
1.29368846996964
333
1.29368313026828
323
1.29367779056692
307
1.29367245086555
309
1.29366711116419
307
1.29366177146282
311
1.29365643176146
336
1.2936510920601
332
1.29364575235873
373
1.29364041265737
329
1.293635072956
334
1.29362973325464
335
1.29362439355328
301
1.29361905385191
309
1.29361371415055
Ti2s
MX-HT 0p1 20Ap
2023
5
9
20
58
22
2
41
Creation
Created by : XPSUser
Date created : 09/05/2023 20:58
Computer : DESKTOP-U3MGE2F
Location
Location ID : X1
Sample : MX-HT 0p1 20Ap
Description : (55.384,14.627,-0.798)mm
Tilt : 0.00
Charge Neutraliser : On
Filament Current : 0.53A
Filament Bias : 2.02V
Charge Balance : 5.02V
Settings
Excitation
Mode : XPS - monochromatic
Tuning : Spectroscopy
Emission current : 15.00mA
Anode library : Al
ESCA modes
Collimation : Slot
Lens : Hybrid
Resolution : 20.00
Scan
Deflection : (0.000, 0.000)mm
Ti2s : 907.690-937.690eV, Sweeps 10
Start : 907.690eV
End : 937.690eV
Centre : 922.690eV
Width : 30.000eV
Step size : 0.100eV
Number Steps : 300
Dwell time : 199ms
Sweep time : 60s
Sweeps : 10
Target quality : 200
Instrument Conditions
Work function : -4.50
Acquisition Conditions
X-ray Power : 225.00W
Quality : 41.27
XPS
9
55.38425
14.626890625
-0.7984765625
Al (mono)
1486.69
225
1E+37
1E+37
1E+37
1E+37
FAT
20
1E+37
-4.5
1E+37
1E+37
1E+37
1E+37
1E+37
Ti2s

-1
Kinetic energy
eV
907.69
0.1
2
Intensity
d
Transmission
d
pulse counting
0.199335548172757
10
0
1E+37
1E+37
1E+37
0
602
12938
16374
1.39835656853096
1.40786093570082
14740
1.40786093570082
14585
1.40783040092986
14614
1.40779986615891
14724
1.40776933138795
14682
1.40773879661699
14651
1.40770826184604
14654
1.40767772707508
14702
1.40764719230412
14758
1.40761665753316
14933
1.40758612276221
14723
1.40755558799125
14522
1.40752505322029
14660
1.40749451844934
14742
1.40746398367838
14686
1.40743344890742
14650
1.40740291413646
14771
1.40737237936551
14800
1.40734184459455
14625
1.40731130982359
14709
1.40728077505264
14718
1.40725024028168
14686
1.40721970551072
14618
1.40718917073976
14488
1.40715863596881
14417
1.40712698331307
14660
1.40709520644792
14560
1.40706342958277
14763
1.40703165271762
14706
1.40699987585246
14613
1.40696809898731
14598
1.40693632212216
14753
1.40690454525701
14599
1.40687276839185
14674
1.4068409915267
14617
1.40680921466155
14494
1.4067774377964
14451
1.40674566093124
14614
1.40671388406609
14597
1.40668210720094
14471
1.40665033033579
14738
1.40661855347063
14707
1.40658677660548
14571
1.40655499974033
14645
1.40652322287517
14567
1.40649144601002
14391
1.40645966914487
14616
1.40642789227972
14781
1.40639611541456
14669
1.40636433854941
14630
1.40633256168426
14614
1.40630078481911
14546
1.40626900795395
14370
1.4062372310888
14616
1.40620545422365
14501
1.4061736773585
14732
1.40614190049334
14635
1.40611012362819
14441
1.40607834676304
14623
1.40604656989789
14700
1.40601479303273
14659
1.40598301616758
14582
1.40595123930243
14559
1.40591946243728
14537
1.40588768557212
14476
1.40585590870697
14435
1.40582413184182
14383
1.40579235497667
14517
1.40576057811151
14436
1.40572880124636
14322
1.40569702438121
14368
1.40566524751605
14377
1.4056334706509
14302
1.40560169378575
14261
1.4055699169206
14316
1.40553814005544
14513
1.40550636319029
14377
1.40547458632514
14347
1.40544280945999
14487
1.40541103259483
14257
1.40537925572968
14228
1.40534747886453
14354
1.40531570199938
14428
1.40528392513422
14393
1.40525214826907
14250
1.40522037140392
14255
1.40518859453877
14258
1.40515681767361
14246
1.40512504080846
14437
1.40509326394331
14296
1.40506148707816
14327
1.405029710213
14438
1.40499793334785
14427
1.4049661564827
14476
1.40493437961755
14392
1.40490260275239
14508
1.40487082588724
14432
1.40483904902209
14430
1.40480727215694
14302
1.40477549529178
14443
1.40474371842663
14543
1.40471194156148
14395
1.40468016469632
14451
1.40464838783117
14265
1.40461661096602
14339
1.40458483410087
14419
1.40455305723571
14350
1.40452128037056
14484
1.40448950350541
14423
1.40445772664026
14626
1.4044259497751
14584
1.40439417290995
14468
1.4043623960448
14745
1.40433061917965
14766
1.40429884231449
14609
1.40426706544934
14758
1.40423528858419
14579
1.40420351171904
14721
1.40417173485388
14739
1.40413995798873
15127
1.40410818112358
14897
1.40407640425843
14997
1.40404462739327
14747
1.40401285052812
14796
1.40398107366297
14890
1.40394929679782
14963
1.40391751993266
15000
1.40388574306751
15097
1.40385396620236
15074
1.40382218933721
15056
1.40379041247205
15327
1.4037586356069
15273
1.40372685874175
15021
1.40369508187659
15198
1.40366330501144
15397
1.40363152814629
15419
1.40359975128114
15419
1.40356797441598
15584
1.40353619755083
15502
1.40350442068568
15624
1.40347264382053
15646
1.40344086695537
15653
1.40340909009022
15528
1.40337731322507
15502
1.40334553635992
15735
1.40331375949476
15608
1.40328198262961
15640
1.40325020576446
15574
1.40321842889931
15736
1.40318665203415
15684
1.403154875169
15729
1.40312309830385
15823
1.4030913214387
15836
1.40305954457354
15933
1.40302776770839
15921
1.40299599084324
15864
1.40296421397809
16057
1.40293243711293
15722
1.40290066024778
16114
1.40286888338263
16217
1.40283710651747
16059
1.40280532965232
16053
1.40277355278717
15953
1.40274177592202
15945
1.40270999905686
16044
1.40267822219171
16142
1.40264644532656
16068
1.40261466846141
16216
1.40258289159625
16340
1.4025511147311
16374
1.40251933786595
16349
1.4024875610008
16182
1.40245578413564
16145
1.40242400727049
16195
1.40239223040534
16141
1.40236045354019
16316
1.40232867667503
16368
1.40229689980988
16088
1.40226512294473
15883
1.40223334607958
15882
1.40220156921442
15837
1.40216979234927
15971
1.40213801548412
15826
1.40210623861897
15760
1.40207446175381
15777
1.40204268488866
15674
1.40201090802351
15524
1.40197913115836
15529
1.4019473542932
15658
1.40191557742805
15531
1.4018838005629
15258
1.40185202369774
15321
1.40182024683259
15291
1.40178846996744
15002
1.40175669310229
15055
1.40172491623713
14945
1.40169313937198
14839
1.40166136250683
14911
1.40162958564168
14871
1.40159780877652
14610
1.40156603191137
14551
1.40153425504622
14479
1.40150247818107
14558
1.40147070131591
14650
1.40143892445076
14358
1.40140714758561
14315
1.40137537072046
14370
1.4013435938553
14256
1.40131181699015
14318
1.401280040125
14142
1.40124826325985
14268
1.40121648639469
14195
1.40118470952954
13928
1.40115293266439
13990
1.40112115579924
13938
1.40108937893408
13701
1.40105760206893
13785
1.40102582520378
14086
1.40099404833863
13815
1.40096227147347
13772
1.40093049460832
13935
1.40089871774317
13873
1.40086694087801
13707
1.40083516401286
13834
1.40080338714771
13734
1.40077161028256
13834
1.4007398334174
13773
1.40070805655225
13592
1.4006762796871
13640
1.40064450282195
13544
1.40061272595679
13500
1.40058094909164
13571
1.40054917222649
13715
1.40051739536134
13645
1.40048561849618
13583
1.40045384163103
13590
1.40042206476588
13500
1.40039028790073
13472
1.40035851103557
13453
1.40032673417042
13522
1.40029495730527
13573
1.40026318044012
13471
1.40023140357496
13526
1.40019962670981
13442
1.40016784984466
13362
1.40013607297951
13484
1.40010429611435
13478
1.4000725192492
13487
1.40004074238405
13418
1.40000896551889
13355
1.39997718865374
13311
1.39994541178859
13331
1.39991363492344
13277
1.39988185805828
13448
1.39985008119313
13417
1.39981830432798
13222
1.39978652746283
13328
1.39975475059767
13322
1.39972297373252
13440
1.39969119686737
13443
1.39965942000222
13125
1.39962764313706
13321
1.39959586627191
13238
1.39956408940676
13236
1.39953231254161
13237
1.39950053567645
13374
1.3994687588113
13134
1.39943698194615
13304
1.399405205081
13308
1.39937342821584
13325
1.39934165135069
13428
1.39930987448554
13342
1.39927809762039
13218
1.39924632075523
13260
1.39921454389008
13328
1.39918276702493
13305
1.39915099015978
13177
1.39911921329462
13096
1.39908743642947
13070
1.39905565956432
13112
1.39902388269916
13295
1.39899210583401
13198
1.39896032896886
12989
1.39892855210371
13011
1.39889677523855
13217
1.3988649983734
13000
1.39883322150825
12938
1.3988014446431
13225
1.39876966777794
13179
1.39873789091279
13189
1.39870611404764
13097
1.39867433718249
12986
1.39864256031733
13311
1.39861078345218
13153
1.39857900658703
13296
1.39854722972188
13178
1.39851545285672
13142
1.39848367599157
13189
1.39845189912642
13229
1.39842012226127
13119
1.39838834539611
13208
1.39835656853096
Ti2p
MX-HT 0p1 20Ap
2023
5
9
20
58
22
2
41
Creation
Created by : XPSUser
Date created : 09/05/2023 20:58
Computer : DESKTOP-U3MGE2F
Location
Location ID : X1
Sample : MX-HT 0p1 20Ap
Description : (55.384,14.627,-0.798)mm
Tilt : 0.00
Charge Neutraliser : On
Filament Current : 0.53A
Filament Bias : 2.02V
Charge Balance : 5.02V
Settings
Excitation
Mode : XPS - monochromatic
Tuning : Spectroscopy
Emission current : 15.00mA
Anode library : Al
ESCA modes
Collimation : Slot
Lens : Hybrid
Resolution : 20.00
Scan
Deflection : (0.000, 0.000)mm
Ti2p : 1016.690-1036.690eV, Sweeps 10
Start : 1016.690eV
End : 1036.690eV
Centre : 1026.690eV
Width : 20.000eV
Step size : 0.100eV
Number Steps : 200
Dwell time : 299ms
Sweep time : 60s
Sweeps : 10
Target quality : 200
Instrument Conditions
Work function : -4.50
Acquisition Conditions
X-ray Power : 225.00W
Quality : 185.44
XPS
10
55.38425
14.626890625
-0.7984765625
Al (mono)
1486.69
225
1E+37
1E+37
1E+37
1E+37
FAT
20
1E+37
-4.5
1E+37
1E+37
1E+37
1E+37
1E+37
Ti2p

-1
Kinetic energy
eV
1016.69
0.1
2
Intensity
d
Transmission
d
pulse counting
0.298507462686567
10
0
1E+37
1E+37
1E+37
0
402
11529
32402
1.34818394035546
1.35812104677082
19120
1.35812104677082
19185
1.35807136123875
18963
1.35802167570667
18836
1.35797199017459
19113
1.35792230464252
19047
1.35787261911044
19025
1.35782293357836
18926
1.35777324804629
18858
1.35772356251421
18868
1.35767387698213
18854
1.35762419145005
19087
1.35757450591798
18797
1.3575248203859
18613
1.35747513485382
18858
1.35742544932175
18737
1.35737576378967
18878
1.35732607825759
18783
1.35727639272552
18746
1.35722670719344
18813
1.35717702166136
18714
1.35712733612929
18762
1.35707765059721
18783
1.35702796506513
18777
1.35697827953306
18726
1.35692859400098
18683
1.3568789084689
18645
1.35682922293683
18820
1.35677953740475
18644
1.35672985187267
18630
1.3566801663406
18631
1.35663048080852
18756
1.35658079527644
18678
1.35653110974437
18718
1.35648142421229
18780
1.35643173868021
18858
1.35638205314813
18862
1.35633236761606
18839
1.35628268208398
18736
1.3562329965519
18904
1.35618331101983
18959
1.35613362548775
19061
1.35608393995567
19305
1.3560342544236
19216
1.35598456889152
19181
1.35593488335944
19454
1.35588519782737
19604
1.35583551229529
19666
1.35578582676321
20016
1.35573614123114
20175
1.35568645569906
20089
1.35563677016698
20470
1.35558708463491
20760
1.35553739910283
20610
1.35548771357075
20555
1.35543802803868
20382
1.3553883425066
20647
1.35533865697452
20647
1.35528897144245
20831
1.35523928591037
20667
1.35518960037829
20607
1.35513991484622
20659
1.35509022931414
20878
1.35504054378206
20651
1.35499085824998
20590
1.35494117271791
20608
1.35489148718583
20744
1.35484180165375
20664
1.35479211612168
20685
1.3547424305896
20694
1.35469274505752
20780
1.35464305952545
21026
1.35459337399337
21125
1.35454368846129
21274
1.35449400292922
21637
1.35444431739714
21864
1.35439463186506
21877
1.35434494633299
22286
1.35429526080091
22313
1.35424557526883
22615
1.35419588973676
22469
1.35414620420468
23044
1.3540965186726
23018
1.35404683314053
23595
1.35399714760845
23515
1.35394746207637
23988
1.3538977765443
24067
1.35384809101222
24418
1.35379840548014
24634
1.35374871994806
24662
1.35369903441599
24995
1.35364934888391
24951
1.35359966335183
24643
1.35354997781976
25086
1.35350029228768
25221
1.3534506067556
25053
1.35340092122353
24837
1.35335123569145
24244
1.35330155015937
23959
1.3532518646273
23336
1.35320217909522
22943
1.35315249356314
22433
1.35310280803107
21919
1.35305312249899
21822
1.35300343696691
21815
1.35295375143484
21918
1.35290406590276
22127
1.35285438037068
22829
1.35280469483861
23164
1.35275500930653
23708
1.35270532377445
24592
1.35265563824238
25366
1.3526059527103
25531
1.35255626717822
25740
1.35250658164615
25831
1.35245689611407
25736
1.35240721058199
25464
1.35235752504991
24871
1.35230783951784
23902
1.35225815398576
23113
1.35220846845368
22268
1.35215878292161
21643
1.35210909738953
21419
1.35205941185745
20893
1.35200972632538
20611
1.3519600407933
20549
1.35191035526122
20506
1.35186066972915
20867
1.35181098419707
21054
1.35176129866499
21180
1.35171161313292
21551
1.35166192760084
22251
1.35161224206876
22603
1.35156255653669
23158
1.35151287100461
23539
1.35146318547253
23984
1.35141349994046
24427
1.35136381440838
25041
1.3513141288763
25741
1.35126444334423
26377
1.35121475781215
26843
1.35116507228007
27501
1.35111538674799
28059
1.35106570121592
28625
1.35101601568384
29394
1.35096633015176
29472
1.35091664461969
30337
1.35086695908761
30711
1.35081727355553
31212
1.35076758802346
31557
1.35071790249138
31977
1.3506682169593
32152
1.35061853142723
32402
1.35056884589515
32154
1.35051916036307
31890
1.350469474831
31434
1.35041978929892
30893
1.35037010376684
30153
1.35032041823477
28802
1.35027073270269
26429
1.35022104717061
23064
1.35017136163854
19633
1.35012167610646
16888
1.35007199057438
15025
1.35002230504231
13894
1.34997261951023
13188
1.34992293397815
12763
1.34987324844607
12574
1.349823562914
12392
1.34977387738192
12416
1.34972419184984
12366
1.34967450631777
12138
1.34962482078569
12067
1.34957513525361
12092
1.34952544972154
12020
1.34947576418946
11880
1.34942607865738
11736
1.34937639312531
11947
1.34932670759323
11853
1.34927702206115
11840
1.34922733652908
11828
1.349177650997
11817
1.34912796546492
11860
1.34907827993285
11815
1.34902859440077
11681
1.34897890886869
11820
1.34892922333662
11704
1.34887953780454
11545
1.34882985227246
11808
1.34878016674039
11609
1.34873048120831
11585
1.34868079567623
11605
1.34863111014416
11570
1.34858142461208
11642
1.34853173908
11634
1.34848205354792
11736
1.34843236801585
11614
1.34838268248377
11660
1.34833299695169
11682
1.34828331141962
11652
1.34823362588754
11529
1.34818394035546
end of experiment