File: XPS/Casa format/MX-UT 0p1 20Ap location M1 in image.vms
VAMAS Surface Chemical Analysis Standard Data Transfer Format 1988 May 4
Not specified
MI-600-BE9240AA
XPSUser
KTH Amireza_C-paper-Mxene-sample sent on 17 April2023.experiment
0
NORM
REGULAR
1
4
Index
d
PositionX [mm]
n
PositionY [mm]
n
PositionZ [mm]
n
0
0
0
0
10
wide
MX-UT 0p1 20Ap
2023
5
9
13
48
25
2
39
Creation
Created by : XPSUser
Date created : 09/05/2023 13:48
Computer : DESKTOP-U3MGE2F
Location
Location ID : M1
Sample : MX-UT 0p1 20Ap
Description : (15.979,18.402,-0.833)mm
Tilt : 0.00
Charge Neutraliser : On
Filament Current : 0.53A
Filament Bias : 2.02V
Charge Balance : 5.02V
Settings
Excitation
Mode : XPS - monochromatic
Tuning : Spectroscopy
Emission current : 15.00mA
Anode library : Al
ESCA modes
Collimation : Slot
Lens : Hybrid
Resolution : 160.00
Scan
Deflection : (0.000, 0.000)mm
wide : 286.690-1491.690eV, Sweeps 5
Start : 286.690eV
End : 1491.690eV
Centre : 889.190eV
Width : 1205.000eV
Step size : 1.000eV
Number Steps : 1205
Dwell time : 100ms
Sweep time : 120s
Sweeps : 5
Instrument Conditions
Work function : -4.50
Acquisition Conditions
X-ray Power : 225.00W
XPS
1
15.97875
18.401640625
-0.8333359375
Al (mono)
1486.69
225
1E+37
1E+37
1E+37
1E+37
FAT
160
1E+37
-4.5
1E+37
1E+37
1E+37
1E+37
1E+37
wide

-1
Kinetic energy
eV
286.69
1
2
Intensity
d
Transmission
d
pulse counting
0.0995024875621891
0
1E+37
0
4
31.1899525550317
36440
36222
36472
36416
36387
36525
36530
36438
36789
36835
36831
37040
36950
36965
36945
37386
37330
37354
37610
37671
37594
37680
37907
38191
38028
38452
38472
38313
38308
38618
38656
38528
38540
38564
38570
38748
38794
38765
39039
39183
39262
39348
39432
39926
39869
39669
39707
39990
39758
39616
40228
40082
39770
40052
40209
40264
40101
40207
40191
40092
40409
40162
40614
40890
40832
40936
41789
41904
42036
41880
41656
41686
41658
41836
41972
42127
42347
42250
42224
41726
41622
41407
41441
41362
41393
41422
41564
41733
42104
42101
42194
42983
43212
43911
44591
45270
45666
45506
44839
43977
44110
43745
42645
40658
39318
38046
37591
36945
36821
36343
36047
35737
35561
35702
35655
35634
35438
35402
35627
35567
35609
35342
35385
35883
36096
36187
36240
36830
37717
38457
38968
39071
38515
38198
38047
37020
35741
34908
34681
34369
34448
34272
34114
34174
33861
34124
34492
34222
34353
33918
34004
34178
34574
34355
34409
34422
34280
34494
34663
34664
34691
34856
34895
35460
35325
35562
35272
35094
35252
34731
35083
35003
34911
35253
35408
35302
35027
35361
35395
35568
35534
35732
35743
35713
35694
35867
36055
35547
35831
36030
36006
35953
35955
36032
36086
36343
36260
36782
36844
36916
36917
36935
37231
37035
37043
37154
37351
37508
37256
36947
37137
36742
36989
36838
36940
37206
36912
37175
37239
37273
37356
37888
38036
38926
39458
39428
39804
40516
40631
39717
38325
37385
36886
36657
36558
36011
35679
35829
35653
35672
35499
35550
35632
35999
35577
35606
35982
35978
35869
35812
36076
35943
35819
35798
35958
35711
36109
36052
36025
36124
36080
36164
36134
36395
36409
36439
36537
36888
36915
36703
36387
36487
36554
36545
36847
36809
37152
36936
37075
36848
36697
36794
37170
37308
37523
37267
37176
37383
37360
37227
37446
37393
37711
37642
37617
37442
37516
37840
37595
37852
37869
37686
38086
37956
38071
38116
38000
38126
38239
38243
38071
38334
38146
38083
38140
38476
38614
38642
38426
38644
39230
39002
39100
39008
38852
38963
39533
39513
39439
39447
39019
38822
38743
39000
38971
39166
39491
39524
39350
39331
39740
39869
39828
40096
40552
40476
40478
40474
39964
39875
39642
39641
39540
39580
39837
40063
39577
39136
39276
39663
39386
39322
39861
39747
40017
40270
40596
40828
40879
41257
41848
42214
43774
43938
41640
39911
39153
39187
39180
39406
39295
39158
39251
39467
39326
39635
39510
39728
39576
39359
39572
39848
39891
39952
39594
39611
39706
40013
40046
39820
39878
39596
39861
39899
39778
40155
40209
40125
40316
40089
40149
40465
40275
40467
40189
39942
40441
40435
40614
40589
40457
40624
40662
40545
40754
40854
40831
40747
41184
40670
40676
40969
41069
41120
41165
40939
41304
40806
41342
41274
41266
41315
41494
41190
41067
41292
41810
41700
41487
41444
41712
41754
41749
41883
41935
41826
41874
41862
42123
42160
41795
41886
42126
42445
42421
42217
42307
42465
42506
42508
42552
42438
42721
42629
42534
42547
42383
42783
42569
42455
42804
42501
42864
43169
42891
42824
42945
43536
43471
43372
43517
43555
43500
43575
43656
43163
43264
43360
42894
43357
43119
43471
43350
43438
42738
43054
43140
42844
43050
43325
43590
43531
43990
44903
46726
51762
51334
45993
43342
43084
42906
42911
42870
43090
42734
42799
43037
42917
42849
42894
43565
43276
43603
43406
43553
43542
43417
43531
43816
43532
43597
43726
43593
43538
43591
43504
43400
43903
43999
44168
44422
44321
44359
44548
44601
44324
44393
44307
44567
44720
44508
44556
44758
44931
44499
44600
44917
44494
44652
44873
45000
45051
44824
45122
45187
44668
45278
45275
45127
44996
45321
45239
45140
45389
45395
45697
45688
45516
45568
46068
45993
45912
45859
45934
46074
46268
46161
46197
46297
46159
46184
46178
45807
46071
46251
46154
46612
46819
46793
46939
47508
47537
47113
47167
47635
47941
47385
47843
47697
47553
47530
48194
48195
48051
48128
47967
48017
48051
47727
47577
47540
48066
47833
48407
48745
49294
50400
51422
51723
51324
50096
48362
47509
46739
46112
45693
45623
45576
45422
45372
45256
45059
44772
45090
45161
44994
45119
44733
44716
44414
44409
44570
44301
44177
44810
45434
46701
49408
52605
53067
52779
51777
47348
44189
43652
43645
43791
43544
43463
43534
43868
43618
43559
44001
43732
43820
44064
43839
44215
44349
44404
44400
44473
44637
44841
45026
44997
44630
44578
44623
44626
44578
44396
44502
44161
44377
44651
44784
44831
44596
45044
45244
45740
45841
45922
46142
46300
46736
46589
46725
47190
47096
47412
47404
47434
47084
46898
46688
46858
46697
46151
46068
45861
45632
45871
46441
47284
49388
52586
54286
51989
49407
49689
53921
60221
62636
52007
39913
35667
34898
34718
34660
34778
34409
34533
34586
34374
34395
34286
34572
34480
34637
34494
34656
34640
34674
34708
34850
34741
34408
34477
34704
34782
34489
34597
34944
34939
34840
35199
35177
35262
34924
34869
34952
35018
35079
35164
35014
35032
34959
35073
35437
35365
35364
35401
35058
35351
35544
35564
35904
36004
35920
35856
35649
35687
35807
35481
35464
35488
35277
35474
35586
35506
35633
35992
35610
35604
35649
36031
35977
35767
36123
36203
36197
36140
36384
36317
36099
36254
36394
36492
36259
36334
36485
36284
36372
36158
35952
36305
36298
36393
36360
36291
36592
36770
36767
36648
37124
37218
37296
37578
37452
37404
37461
37469
37347
37688
37980
37878
37602
37228
37300
37213
36955
36407
36459
36059
35761
35744
35513
35440
35389
35571
35846
36293
36765
37345
37583
38275
38626
39616
39940
40342
40701
41334
41396
41569
41504
41217
40904
39838
38767
37085
35085
33533
31815
30293
28254
26411
24730
23372
22384
21579
21284
21436
22254
23539
25612
28170
31295
33632
34625
36700
42343
59625
112525
190616
133615
38531
13452
7789
4899
3848
3462
3308
3242
3170
3103
3204
3299
3539
3447
3240
3012
2977
2842
2871
2906
2842
2906
2834
2851
2861
2880
2871
2849
2909
2838
2867
2800
2846
2932
2837
2925
2917
2846
2904
2988
2950
2907
2910
2931
2913
2908
2911
2868
2976
3018
3122
2993
2906
2948
2953
2973
3012
2981
3027
3004
2996
2934
2996
3055
2987
2938
2980
2975
2968
2924
2911
2972
2900
2848
2911
2948
2970
2906
3021
3045
3167
3438
3704
4000
3749
3201
2925
2883
2924
2947
2850
2869
2976
2892
2882
2942
2867
2854
2829
2875
2955
2913
2932
2899
2927
3087
3047
2937
2917
3006
2952
2900
3005
3019
3105
3015
3014
3053
3030
3063
3007
3058
3083
3082
2896
2971
2988
2996
2990
3117
3082
3138
3138
3071
3033
3121
3040
3087
3060
2982
3138
3101
3098
3083
3135
3206
3191
3149
3193
3173
3210
3181
3179
3181
3128
3247
3242
3226
3251
3240
3265
3247
3231
3279
3225
3240
3268
3323
3312
3306
3356
3379
3295
3275
3312
3398
3325
3380
3411
3424
3465
3516
3434
3379
3411
3366
3492
3392
3363
3442
3463
3455
3535
3557
3626
3605
3631
3632
3740
3689
3623
3696
3768
3793
3699
3706
3651
3692
3543
3558
3516
3543
3462
3471
3503
3516
3467
3509
3571
3908
4173
4524
5002
4979
4586
4060
3651
3384
3279
3210
3243
3293
3277
3286
3363
3256
3329
3296
3094
3100
3156
3219
3272
3389
3694
4179
4944
5910
6110
4853
3143
2210
2006
1931
1868
1709
1649
1634
1746
1922
2178
2395
2554
2602
2592
2557
2431
2251
2074
2052
1933
1749
1554
1417
1370
1197
1064
1008
869
707
495
263
119
60
19
7
6
4
31.1899525550317
C 1s
MX-UT 0p1 20Ap
2023
5
9
16
4
28
2
41
Creation
Created by : XPSUser
Date created : 09/05/2023 16:04
Computer : DESKTOP-U3MGE2F
Location
Location ID : M1
Sample : MX-UT 0p1 20Ap
Description : (15.979,18.402,-0.833)mm
Tilt : 0.00
Charge Neutraliser : On
Filament Current : 0.53A
Filament Bias : 2.02V
Charge Balance : 5.02V
Settings
Excitation
Mode : XPS - monochromatic
Tuning : Spectroscopy
Emission current : 15.00mA
Anode library : Al
ESCA modes
Collimation : Slot
Lens : Hybrid
Resolution : 20.00
Scan
Deflection : (0.000, 0.000)mm
C 1s : 1191.690-1209.690eV, Sweeps 1
Start : 1191.690eV
End : 1209.690eV
Centre : 1200.690eV
Width : 18.000eV
Step size : 0.100eV
Number Steps : 180
Dwell time : 331ms
Sweep time : 60s
Sweeps : 1
Target quality : 200
Instrument Conditions
Work function : -4.50
Acquisition Conditions
X-ray Power : 225.00W
Quality : 313.69
XPS
2
15.97875
18.401640625
-0.8333359375
Al (mono)
1486.69
225
1E+37
1E+37
1E+37
1E+37
FAT
20
1E+37
-4.5
1E+37
1E+37
1E+37
1E+37
1E+37
C
1s
-1
Kinetic energy
eV
1191.69
0.1
2
Intensity
d
Transmission
d
pulse counting
0.331492
1
0
1E+37
1E+37
1E+37
0
362
93
20745
1.33571680812406
1.34279197206053
777
1.33571680812406
766
1.33575611459037
732
1.33579542105669
739
1.335834727523
810
1.33587403398932
765
1.33591334045563
731
1.33595264692194
818
1.33599195338826
826
1.33603125985457
781
1.33607056632088
771
1.3361098727872
760
1.33614917925351
748
1.33618848571983
774
1.33622779218614
747
1.33626709865245
776
1.33630640511877
789
1.33634571158508
823
1.33638501805139
834
1.33642432451771
804
1.33646363098402
809
1.33650293745034
840
1.33654224391665
782
1.33658155038296
826
1.33662085684928
867
1.33666016331559
888
1.3366994697819
898
1.33673877624822
867
1.33677808271453
884
1.33681738918085
922
1.33685669564716
919
1.33689600211347
963
1.33693530857979
991
1.3369746150461
966
1.33701392151241
1002
1.33705322797873
1024
1.33709253444504
1010
1.33713184091135
1013
1.33717114737767
1038
1.33721045384398
1059
1.3372497603103
1073
1.33728906677661
1094
1.33732837324292
1070
1.33736767970924
1129
1.33740698617555
1078
1.33744629264186
1054
1.33748559910818
1051
1.33752490557449
1025
1.33756421204081
1037
1.33760351850712
1065
1.33764282497343
1056
1.33768213143975
995
1.33772143790606
1025
1.33776074437237
1038
1.33780005083869
1037
1.337839357305
977
1.33787866377132
1001
1.33791797023763
990
1.33795727670394
972
1.33799658317026
1001
1.33803588963657
992
1.33807519610288
985
1.3381145025692
945
1.33815380903551
970
1.33819311550182
975
1.33823242196814
962
1.33827172843445
989
1.33831103490077
967
1.33835034136708
1044
1.33838964783339
1052
1.33842895429971
1008
1.33846826076602
1055
1.33850756723233
1083
1.33854687369865
1052
1.33858618016496
1079
1.33862548663128
1116
1.33866479309759
1153
1.3387040995639
1168
1.33874340603022
1178
1.33878271249653
1252
1.33882201896284
1254
1.33886132542916
1250
1.33890063189547
1329
1.33893993836179
1344
1.3389792448281
1449
1.33901855129441
1563
1.33905785776073
1590
1.33909716422704
1620
1.33913647069335
1649
1.33917577715967
1731
1.33921508362598
1812
1.3392543900923
1906
1.33929369655861
1962
1.33933300302492
1944
1.33937230949124
2124
1.33941161595755
2178
1.33945092242386
2305
1.33949022889018
2522
1.33952953535649
2797
1.3395688418228
3084
1.33960814828912
3345
1.33964745475543
3971
1.33968676122175
4586
1.33972606768806
5786
1.33976537415437
7339
1.33980468062069
9569
1.339843987087
12716
1.33988329355331
16689
1.33992260001963
20094
1.33996190648594
20745
1.34000121295226
18010
1.34004051941857
12891
1.34007982588488
8055
1.3401191323512
4594
1.34015843881751
2738
1.34019774528382
1805
1.34023705175014
1346
1.34027635821645
995
1.34031566468277
786
1.34035497114908
614
1.34039427761539
525
1.34043358408171
449
1.34047289054802
419
1.34051219701433
408
1.34055150348065
356
1.34059080994696
327
1.34063011641328
301
1.34066942287959
329
1.3407087293459
334
1.34074803581222
351
1.34078734227853
381
1.34082664874484
434
1.34086595521116
588
1.34090526167747
710
1.34094456814378
748
1.3409838746101
707
1.34102318107641
608
1.34106248754273
393
1.34110179400904
295
1.34114110047535
224
1.34118040694167
194
1.34121971340798
184
1.34125901987429
173
1.34129832634061
149
1.34133763280692
132
1.34137693927324
133
1.34141624573955
140
1.34145555220586
125
1.34149485867218
133
1.34153416513849
118
1.3415734716048
117
1.34161277807112
121
1.34165208453743
135
1.34169139100375
131
1.34173069747006
120
1.34177000393637
126
1.34180931040269
131
1.341848616869
115
1.34188792333531
114
1.34192722980163
126
1.34196653626794
135
1.34200584273426
120
1.34204514920057
101
1.34208445566688
93
1.3421237621332
99
1.34216306859951
111
1.34220237506582
104
1.34224168153214
113
1.34228098799845
112
1.34232029446476
119
1.34235960093108
126
1.34239890739739
103
1.34243821386371
102
1.34247752033002
109
1.34251682679633
102
1.34255613326265
97
1.34259543972896
101
1.34263474619527
98
1.34267405266159
94
1.3427133591279
98
1.34275266559422
110
1.34279197206053
Cl2s
MX-UT 0p1 20Ap
2023
5
9
16
4
28
2
41
Creation
Created by : XPSUser
Date created : 09/05/2023 16:04
Computer : DESKTOP-U3MGE2F
Location
Location ID : M1
Sample : MX-UT 0p1 20Ap
Description : (15.979,18.402,-0.833)mm
Tilt : 0.00
Charge Neutraliser : On
Filament Current : 0.53A
Filament Bias : 2.02V
Charge Balance : 5.02V
Settings
Excitation
Mode : XPS - monochromatic
Tuning : Spectroscopy
Emission current : 15.00mA
Anode library : Al
ESCA modes
Collimation : Slot
Lens : Hybrid
Resolution : 20.00
Scan
Deflection : (0.000, 0.000)mm
Cl2s : 1201.690-1231.690eV, Sweeps 1
Start : 1201.690eV
End : 1231.690eV
Centre : 1216.690eV
Width : 30.000eV
Step size : 0.100eV
Number Steps : 300
Dwell time : 199ms
Sweep time : 60s
Sweeps : 1
Target quality : 200
Instrument Conditions
Work function : -4.50
Acquisition Conditions
X-ray Power : 225.00W
Quality : 548.21
XPS
3
15.97875
18.401640625
-0.8333359375
Al (mono)
1486.69
225
1E+37
1E+37
1E+37
1E+37
FAT
20
1E+37
-4.5
1E+37
1E+37
1E+37
1E+37
1E+37
Cl2s

-1
Kinetic energy
eV
1201.69
0.1
2
Intensity
d
Transmission
d
pulse counting
0.199335548172757
1
0
1E+37
1E+37
1E+37
0
602
44
12354
1.33964745475543
1.35143939464955
2787
1.33964745475543
3356
1.33968676122175
4097
1.33972606768806
5614
1.33976537415437
7470
1.33980468062069
9712
1.339843987087
11643
1.33988329355331
12354
1.33992260001963
10858
1.33996190648594
8020
1.34000121295226
4918
1.34004051941857
2820
1.34007982588488
1650
1.3401191323512
1092
1.34015843881751
812
1.34019774528382
573
1.34023705175014
464
1.34027635821645
360
1.34031566468277
283
1.34035497114908
262
1.34039427761539
221
1.34043358408171
220
1.34047289054802
204
1.34051219701433
183
1.34055150348065
196
1.34059080994696
178
1.34063011641328
204
1.34066942287959
207
1.3407087293459
222
1.34074803581222
302
1.34078734227853
373
1.34082664874484
403
1.34086595521116
424
1.34090526167747
427
1.34094456814378
334
1.3409838746101
248
1.34102318107641
152
1.34106248754273
136
1.34110179400904
116
1.34114110047535
98
1.34118040694167
89
1.34121971340798
70
1.34125901987429
83
1.34129832634061
77
1.34133763280692
73
1.34137693927324
82
1.34141624573955
76
1.34145555220586
71
1.34149485867218
67
1.34153416513849
73
1.3415734716048
74
1.34161277807112
71
1.34165208453743
71
1.34169139100375
53
1.34173069747006
61
1.34177000393637
67
1.34180931040269
73
1.341848616869
80
1.34188792333531
66
1.34192722980163
60
1.34196653626794
67
1.34200584273426
71
1.34204514920057
70
1.34208445566688
71
1.3421237621332
63
1.34216306859951
57
1.34220237506582
62
1.34224168153214
67
1.34228098799845
58
1.34232029446476
74
1.34235960093108
78
1.34239890739739
76
1.34243821386371
52
1.34247752033002
54
1.34251682679633
57
1.34255613326265
52
1.34259543972896
63
1.34263474619527
65
1.34267405266159
60
1.3427133591279
57
1.34275266559422
61
1.34279197206053
64
1.34283127852684
65
1.34287058499316
60
1.34290989145947
72
1.34294919792578
65
1.3429885043921
64
1.34302781085841
68
1.34306711732473
52
1.34310642379104
59
1.34314573025735
59
1.34318503672367
49
1.34322434318998
71
1.34326364965629
58
1.34330295612261
56
1.34334226258892
63
1.34338156905524
69
1.34342087552155
65
1.34346018198786
63
1.34349948845418
67
1.34353879492049
59
1.3435781013868
53
1.34361740785312
58
1.34365671431943
54
1.34369602078574
57
1.34373532725206
58
1.34377463371837
63
1.34381394018469
62
1.343853246651
52
1.34389255311731
67
1.34393185958363
63
1.34397116604994
59
1.34401047251625
63
1.34404977898257
66
1.34408908544888
63
1.3441283919152
81
1.34416769838151
66
1.34420700484782
50
1.34424631131414
62
1.34428561778045
53
1.34432492424676
59
1.34436423071308
68
1.34440353717939
54
1.34444284364571
66
1.34448215011202
62
1.34452145657833
54
1.34456076304465
69
1.34460006951096
54
1.34463937597727
55
1.34467868244359
64
1.3447179889099
68
1.34475729537622
63
1.34479660184253
70
1.34483590830884
73
1.34487521477516
61
1.34491452124147
66
1.34495382770778
68
1.3449931341741
62
1.34503244064041
69
1.34507174710672
72
1.34511105357304
69
1.34515036003935
66
1.34518966650567
82
1.34522897297198
74
1.34526827943829
76
1.34530758590461
65
1.34534689237092
66
1.34538619883723
84
1.34542550530355
67
1.34546481176986
78
1.34550411823618
73
1.34554342470249
75
1.3455827311688
71
1.34562203763512
71
1.34566134410143
84
1.34570065056774
77
1.34573995703406
74
1.34577926350037
66
1.34581856996669
67
1.345857876433
65
1.34589718289931
66
1.34593648936563
73
1.34597579583194
67
1.34601510229825
70
1.34605440876457
59
1.34609371523088
64
1.34613302169719
61
1.34617232816351
79
1.34621163462982
76
1.34625094109614
58
1.34629024756245
62
1.34632955402876
64
1.34636886049508
62
1.34640816696139
53
1.3464474734277
64
1.34648677989402
61
1.34652608636033
56
1.34656539282665
65
1.34660469929296
75
1.34664400575927
62
1.34668331222559
59
1.3467226186919
51
1.34676192515821
62
1.34680123162453
58
1.34684053809084
54
1.34687984455716
68
1.34691915102347
58
1.34695845748978
73
1.3469977639561
65
1.34703707042241
65
1.34707637688872
54
1.34711568335504
63
1.34715498982135
62
1.34719429628767
53
1.34723360275398
50
1.34727290922029
65
1.34731221568661
63
1.34735152215292
55
1.34739082861923
62
1.34743013508555
60
1.34746944155186
60
1.34750874801817
57
1.34754805448449
62
1.3475873609508
68
1.34762666741712
65
1.34766597388343
63
1.34770528034974
68
1.34774458681606
65
1.34778389328237
51
1.34782319974868
61
1.347862506215
62
1.34790181268131
56
1.34794111914763
60
1.34798042561394
52
1.34801973208025
57
1.34805903854657
77
1.34809834501288
64
1.34813765147919
55
1.34817695794551
50
1.34821626441182
58
1.34825557087814
65
1.34829487734445
61
1.34833418381076
57
1.34837349027708
61
1.34841279674339
57
1.3484521032097
61
1.34849140967602
62
1.34853071614233
59
1.34857002260865
66
1.34860932907496
54
1.34864863554127
59
1.34868794200759
62
1.3487272484739
60
1.34876655494021
66
1.34880586140653
66
1.34884516787284
58
1.34888447433916
49
1.34892378080547
53
1.34896308727178
52
1.3490023937381
62
1.34904170020441
59
1.34908100667072
61
1.34912031313704
63
1.34915961960335
55
1.34919892606966
61
1.34923823253598
64
1.34927753900229
65
1.34931684546861
59
1.34935615193492
68
1.34939545840123
60
1.34943476486755
57
1.34947407133386
63
1.34951337780017
59
1.34955268426649
61
1.3495919907328
57
1.34963129719912
58
1.34967060366543
55
1.34970991013174
60
1.34974921659806
61
1.34978852306437
58
1.34982782953068
56
1.349867135997
51
1.34990644246331
44
1.34994574892963
58
1.34998505539594
53
1.35002436186225
55
1.35006366832857
59
1.35010297479488
57
1.35014228126119
61
1.35018158772751
56
1.35022089419382
62
1.35026020066013
56
1.35029950712645
60
1.35033881359276
67
1.35037812005908
64
1.35041742652539
63
1.3504567329917
54
1.35049603945802
59
1.35053534592433
62
1.35057465239064
47
1.35061395885696
50
1.35065326532327
54
1.35069257178959
68
1.3507318782559
58
1.35077118472221
52
1.35081049118853
45
1.35084979765484
57
1.35088910412115
67
1.35092841058747
64
1.35096771705378
47
1.3510070235201
64
1.35104632998641
55
1.35108563645272
53
1.35112494291904
55
1.35116424938535
62
1.35120355585166
63
1.35124286231798
50
1.35128216878429
65
1.35132147525061
64
1.35136078171692
65
1.35140008818323
58
1.35143939464955
F1s
MX-UT 0p1 20Ap
2023
5
9
16
4
28
2
41
Creation
Created by : XPSUser
Date created : 09/05/2023 16:04
Computer : DESKTOP-U3MGE2F
Location
Location ID : M1
Sample : MX-UT 0p1 20Ap
Description : (15.979,18.402,-0.833)mm
Tilt : 0.00
Charge Neutraliser : On
Filament Current : 0.53A
Filament Bias : 2.02V
Charge Balance : 5.02V
Settings
Excitation
Mode : XPS - monochromatic
Tuning : Spectroscopy
Emission current : 15.00mA
Anode library : Al
ESCA modes
Collimation : Slot
Lens : Hybrid
Resolution : 20.00
Scan
Deflection : (0.000, 0.000)mm
F1s : 791.690-811.690eV, Sweeps 5
Start : 791.690eV
End : 811.690eV
Centre : 801.690eV
Width : 20.000eV
Step size : 0.100eV
Number Steps : 200
Dwell time : 299ms
Sweep time : 60s
Sweeps : 5
Target quality : 200
Instrument Conditions
Work function : -4.50
Acquisition Conditions
X-ray Power : 225.00W
Quality : 52.10
XPS
4
15.97875
18.401640625
-0.8333359375
Al (mono)
1486.69
225
1E+37
1E+37
1E+37
1E+37
FAT
20
1E+37
-4.5
1E+37
1E+37
1E+37
1E+37
1E+37
F1s

-1
Kinetic energy
eV
791.69
0.1
2
Intensity
d
Transmission
d
pulse counting
0.298507462686567
5
0
1E+37
1E+37
1E+37
0
402
7087
10300
1.45714403256293
1.46809980524165
7254
1.46809980524165
7314
1.46804594968559
7250
1.46799209412953
7355
1.46793823857347
7196
1.46788438301742
7335
1.46783052746136
7276
1.4677766719053
7225
1.46772281634924
7310
1.46766896079318
7269
1.46761510523713
7206
1.46756124968107
7291
1.46750739412501
7385
1.46745353856895
7277
1.46739968301289
7299
1.46734582745684
7284
1.46729197190078
7427
1.46723811634472
7347
1.46718426078866
7320
1.4671304052326
7247
1.46707654967654
7346
1.46702269412049
7457
1.46696883856443
7349
1.46691498300837
7194
1.46686112745231
7321
1.46680727189625
7502
1.4667534163402
7275
1.46669956078414
7224
1.46664570522808
7244
1.46659184967202
7464
1.46653799411596
7338
1.46648413855991
7373
1.46643028300385
7203
1.46637642744779
7207
1.46632257189173
7324
1.46626871633567
7392
1.46621486077962
7368
1.46616100522356
7412
1.4661071496675
7368
1.46605329411144
7420
1.46599943855538
7416
1.46594558299933
7265
1.46589172744327
7296
1.46583787188721
7359
1.46578401633115
7354
1.46573016077509
7255
1.46567630521904
7257
1.46562244966298
7332
1.46556859410692
7351
1.46551473855086
7391
1.4654608829948
7378
1.46540702743874
7275
1.46535317188269
7315
1.46529931632663
7300
1.46524546077057
7322
1.46519160521451
7286
1.46513774965845
7313
1.4650838941024
7305
1.46503003854634
7385
1.46497618299028
7451
1.46492232743422
7404
1.46486847187816
7364
1.46481461632211
7537
1.46476076076605
7499
1.46470690520999
7304
1.46465304965393
7235
1.46459919409787
7464
1.46454533854182
7378
1.46449148298576
7473
1.4644376274297
7382
1.46438377187364
7364
1.46432991631758
7439
1.46427606076153
7324
1.46422220520547
7320
1.46416834964941
7442
1.46411449409335
7566
1.46406063853729
7372
1.46400678298124
7601
1.46395292742518
7463
1.46389907186912
7564
1.46384521631306
7430
1.463791360757
7517
1.46373750520094
7462
1.46368364964489
7583
1.46362979408883
7574
1.46357593853277
7590
1.46352208297671
7744
1.46346822742065
7638
1.4634143718646
7714
1.46336051630854
7765
1.46330666075248
7815
1.46325280519642
7834
1.46319894964036
7900
1.46314509408431
7951
1.46309123852825
8083
1.46303738297219
8288
1.46298352741613
8354
1.46292967186007
8602
1.46287581630402
9004
1.46282196074796
9261
1.4627681051919
9565
1.46271424963584
9897
1.46266039407978
10249
1.46260653852373
10300
1.46255268296767
10300
1.46249882741161
10224
1.46244497185555
10065
1.46239111629949
9696
1.46233726074344
9198
1.46228340518738
8769
1.46222954963132
8436
1.46217569407526
8132
1.4621218385192
8002
1.46206798296314
7888
1.46201412740709
7568
1.46196027185103
7444
1.46190641629497
7288
1.46185256073891
7411
1.46179870518285
7407
1.4617448496268
7506
1.46169099407074
7352
1.46163713851468
7363
1.46158328295862
7322
1.46152942740256
7263
1.46147557184651
7319
1.46142171629045
7258
1.46136786073439
7332
1.46131400517833
7294
1.46126014962227
7302
1.46120629406622
7326
1.46115243851016
7377
1.4610985829541
7277
1.46104472739804
7190
1.46099087184198
7219
1.46093701628593
7252
1.46088316072987
7264
1.46082930517381
7264
1.46077544961775
7331
1.46072159406169
7313
1.46066773850564
7196
1.46061388294958
7243
1.46056002739352
7290
1.46050617183746
7387
1.4604523162814
7279
1.46039846072534
7287
1.46034460516929
7277
1.46029074961323
7225
1.46023689405717
7129
1.46018303850111
7347
1.46012918294505
7291
1.460075327389
7310
1.46002147183294
7330
1.45996761627688
7188
1.45991376072082
7309
1.45985990516476
7327
1.45980604960871
7248
1.45975219405265
7355
1.45969833849659
7262
1.45964448294053
7151
1.45959062738447
7248
1.45953677182842
7225
1.45948291627236
7095
1.4594290607163
7166
1.45937520516024
7276
1.45932134960418
7301
1.45926749404813
7131
1.45921363849207
7295
1.45915978293601
7324
1.45910592737995
7303
1.45905207182389
7273
1.45899821626783
7163
1.45894436071178
7298
1.45889050515572
7166
1.45883664959966
7087
1.4587827940436
7276
1.45872893848754
7323
1.45867508293149
7211
1.45862122737543
7350
1.45856737181937
7199
1.45851351626331
7190
1.45845966070725
7225
1.4584058051512
7289
1.45835194959514
7370
1.45829809403908
7424
1.45824423848302
7249
1.45818054888434
7221
1.45811576661425
7212
1.45805098434416
7330
1.45798620207407
7488
1.45792141980398
7313
1.4578566375339
7291
1.45779185526381
7197
1.45772707299372
7220
1.45766229072363
7234
1.45759750845354
7267
1.45753272618346
7348
1.45746794391337
7243
1.45740316164328
7295
1.45733837937319
7246
1.4572735971031
7223
1.45720881483302
7237
1.45714403256293
O1s
MX-UT 0p1 20Ap
2023
5
9
16
4
28
2
41
Creation
Created by : XPSUser
Date created : 09/05/2023 16:04
Computer : DESKTOP-U3MGE2F
Location
Location ID : M1
Sample : MX-UT 0p1 20Ap
Description : (15.979,18.402,-0.833)mm
Tilt : 0.00
Charge Neutraliser : On
Filament Current : 0.53A
Filament Bias : 2.02V
Charge Balance : 5.02V
Settings
Excitation
Mode : XPS - monochromatic
Tuning : Spectroscopy
Emission current : 15.00mA
Anode library : Al
ESCA modes
Collimation : Slot
Lens : Hybrid
Resolution : 20.00
Scan
Deflection : (0.000, 0.000)mm
O1s : 946.690-961.690eV, Sweeps 5
Start : 946.690eV
End : 961.690eV
Centre : 954.190eV
Width : 15.000eV
Step size : 0.100eV
Number Steps : 150
Dwell time : 397ms
Sweep time : 60s
Sweeps : 5
Target quality : 200
Instrument Conditions
Work function : -4.50
Acquisition Conditions
X-ray Power : 225.00W
Quality : 50.89
XPS
5
15.97875
18.401640625
-0.8333359375
Al (mono)
1486.69
225
1E+37
1E+37
1E+37
1E+37
FAT
20
1E+37
-4.5
1E+37
1E+37
1E+37
1E+37
1E+37
O1s

-1
Kinetic energy
eV
946.69
0.1
2
Intensity
d
Transmission
d
pulse counting
0.397351
5
0
1E+37
1E+37
1E+37
0
302
9071
12589
1.39073012089434
1.39549665066723
9423
1.39549665066723
9507
1.39546487380208
9428
1.39543309693692
9537
1.39540132007177
9341
1.39536954320662
9530
1.39533776634147
9609
1.39530598947631
9447
1.39527421261116
9378
1.39524243574601
9441
1.39521065888085
9406
1.3951788820157
9357
1.39514710515055
9543
1.3951153282854
9571
1.39508355142024
9467
1.39505177455509
9431
1.39501999768994
9391
1.39498822082479
9438
1.39495644395963
9309
1.39492466709448
9328
1.39489289022933
9458
1.39486111336418
9511
1.39482933649902
9388
1.39479755963387
9415
1.39476578276872
9393
1.39473400590357
9425
1.39470222903841
9289
1.39467045217326
9451
1.39463867530811
9508
1.39460689844296
9454
1.3945751215778
9379
1.39454334471265
9574
1.3945115678475
9506
1.39447979098235
9442
1.39444801411719
9482
1.39441623725204
9552
1.39438446038689
9487
1.39435268352174
9541
1.39432090665658
9443
1.39428912979143
9563
1.39425735292628
9597
1.39422557606112
9379
1.39419379919597
9378
1.39416202233082
9500
1.39413024546567
9478
1.39409846860051
9654
1.39406669173536
9488
1.39403491487021
9644
1.39400313800506
9553
1.3939713611399
9676
1.39393958427475
9661
1.3939078074096
9626
1.39387603054445
9609
1.39384425367929
9589
1.39381247681414
9642
1.39378069994899
9650
1.39374892308384
9648
1.39371714621868
9672
1.39368536935353
9939
1.39365359248838
9940
1.39362181562323
9961
1.39359003875807
10088
1.39355826189292
10155
1.39352648502777
10249
1.39349470816262
10302
1.39346293129746
10462
1.39343115443231
10492
1.39339937756716
10639
1.393367600702
10820
1.39333582383685
10922
1.3933040469717
10960
1.39327227010655
11174
1.39324049324139
11323
1.39320871637624
11327
1.39317693951109
11528
1.39314516264594
11375
1.39311338578078
11583
1.39308160891563
11752
1.39304983205048
11575
1.39301805518533
11685
1.39298627832017
11766
1.39295450145502
11873
1.39292272458987
11906
1.39289094772472
11719
1.39285917085956
11671
1.39282739399441
11753
1.39279561712926
11728
1.39276384026411
11620
1.39273206339895
11543
1.3927002865338
11321
1.39266850966865
11172
1.3926367328035
11199
1.39260495593834
11072
1.39257317907319
10913
1.39254140220804
10881
1.39250962534289
10747
1.39247784847773
10744
1.39244607161258
10855
1.39241429474743
10704
1.39238251788227
10789
1.39235074101712
11080
1.39231896415197
11136
1.39228718728682
11343
1.39225541042166
11695
1.39222363355651
12016
1.39219185669136
12226
1.39216007982621
12589
1.39212830296105
12497
1.3920965260959
12251
1.39206474923075
11959
1.3920329723656
11300
1.39200119550044
10678
1.39196941863529
10197
1.39193764177014
9885
1.39190586490499
9735
1.39187408803983
9598
1.39184231117468
9463
1.39181053430953
9542
1.39177875744438
9435
1.39174698057922
9407
1.39171520371407
9305
1.39168342684892
9380
1.39165164998377
9352
1.39161987311861
9292
1.39158809625346
9291
1.39155631938831
9297
1.39152454252316
9071
1.391492765658
9181
1.39146098879285
9107
1.3914292119277
9259
1.39139743506254
9225
1.39136565819739
9384
1.39133388133224
9375
1.39130210446709
9283
1.39127032760193
9330
1.39123855073678
9337
1.39120677387163
9302
1.39117499700648
9223
1.39114322014132
9246
1.39111144327617
9222
1.39107966641102
9236
1.39104788954587
9358
1.39101611268071
9281
1.39098433581556
9287
1.39095255895041
9410
1.39092078208526
9239
1.3908890052201
9244
1.39085722835495
9221
1.3908254514898
9426
1.39079367462465
9350
1.39076189775949
9306
1.39073012089434
Cl2p
MX-UT 0p1 20Ap
2023
5
9
16
4
28
2
41
Creation
Created by : XPSUser
Date created : 09/05/2023 16:04
Computer : DESKTOP-U3MGE2F
Location
Location ID : M1
Sample : MX-UT 0p1 20Ap
Description : (15.979,18.402,-0.833)mm
Tilt : 0.00
Charge Neutraliser : On
Filament Current : 0.53A
Filament Bias : 2.02V
Charge Balance : 5.02V
Settings
Excitation
Mode : XPS - monochromatic
Tuning : Spectroscopy
Emission current : 15.00mA
Anode library : Al
ESCA modes
Collimation : Slot
Lens : Hybrid
Resolution : 20.00
Scan
Deflection : (0.000, 0.000)mm
Cl2p : 1278.690-1291.690eV, Sweeps 5
Start : 1278.690eV
End : 1291.690eV
Centre : 1285.190eV
Width : 13.000eV
Step size : 0.100eV
Number Steps : 130
Dwell time : 458ms
Sweep time : 60s
Sweeps : 5
Target quality : 200
Instrument Conditions
Work function : -4.50
Acquisition Conditions
X-ray Power : 225.00W
Quality : 33.95
XPS
6
15.97875
18.401640625
-0.8333359375
Al (mono)
1486.69
225
1E+37
1E+37
1E+37
1E+37
FAT
20
1E+37
-4.5
1E+37
1E+37
1E+37
1E+37
1E+37
Cl2p

-1
Kinetic energy
eV
1278.69
0.1
2
Intensity
d
Transmission
d
pulse counting
0.458015267175573
5
0
1E+37
1E+37
1E+37
0
262
682
1314
1.34975176565477
1.35099769238123
724
1.35099769238123
772
1.35098810832949
746
1.35097852427775
727
1.35096894022601
706
1.35095935617426
717
1.35094977212252
726
1.35094018807078
740
1.35093060401904
735
1.3509210199673
755
1.35091143591555
720
1.35090185186381
701
1.35089226781207
686
1.35088268376033
729
1.35087309970859
715
1.35086351565684
729
1.3508539316051
720
1.35084434755336
724
1.35083476350162
758
1.35082517944988
759
1.35081559539813
692
1.35080601134639
723
1.35079642729465
688
1.35078684324291
685
1.35077725919117
692
1.35076767513942
713
1.35075809108768
755
1.35074850703594
769
1.3507389229842
698
1.35072933893246
715
1.35071975488071
757
1.35071017082897
752
1.35070058677723
741
1.35069100272549
758
1.35068141867375
710
1.350671834622
724
1.35066225057026
774
1.35065266651852
743
1.35064308246678
741
1.35063349841504
740
1.35062391436329
744
1.35061433031155
733
1.35060474625981
723
1.35059516220807
709
1.35058557815633
770
1.35057599410458
755
1.35056641005284
779
1.3505568260011
753
1.35054724194936
759
1.35053765789762
731
1.35052807384587
718
1.35051848979413
729
1.35050890574239
715
1.35049932169065
742
1.35048973763891
746
1.35048015358716
737
1.35047056953542
749
1.35046098548368
777
1.35045140143194
745
1.3504418173802
744
1.35043223332845
780
1.35042264927671
753
1.35041306522497
788
1.35040348117323
783
1.35039389712149
783
1.35038431306974
813
1.350374729018
794
1.35036514496626
831
1.35035556091452
809
1.35034597686278
838
1.35033639281103
891
1.35032680875929
937
1.35031722470755
962
1.35030764065581
970
1.35029805660407
1051
1.35028847255232
1095
1.35027888850058
1083
1.35026930444884
1062
1.3502597203971
1004
1.35025013634536
958
1.35024055229361
877
1.35023096824187
896
1.35022138419013
864
1.35021180013839
861
1.35020221608665
909
1.3501926320349
898
1.35018304798316
951
1.35017346393142
1032
1.35016387987968
1089
1.35015429582794
1138
1.35014471177619
1219
1.35013512772445
1314
1.35012554367271
1268
1.35011595962097
1287
1.35010637556923
1204
1.35009679151748
1085
1.35008720746574
964
1.350077623414
913
1.35006803936226
858
1.35005845531052
747
1.35004887125877
726
1.35003928720703
763
1.35002970315529
732
1.35002011910355
719
1.35001053505181
751
1.35000095100006
757
1.34999136694832
712
1.34998178289658
706
1.34997219884484
741
1.3499626147931
711
1.34995303074135
712
1.34994344668961
698
1.34993386263787
745
1.34992427858613
700
1.34991469453439
698
1.34990511048264
697
1.3498955264309
719
1.34988594237916
706
1.34987635832742
704
1.34986677427568
682
1.34985719022393
695
1.34984760617219
702
1.34983802212045
731
1.34982843806871
721
1.34981885401697
684
1.34980926996522
711
1.34979968591348
708
1.34979010186174
729
1.34978051781
737
1.34977093375826
730
1.34976134970651
717
1.34975176565477
Ti3s
MX-UT 0p1 20Ap
2023
5
9
16
4
28
2
41
Creation
Created by : XPSUser
Date created : 09/05/2023 16:04
Computer : DESKTOP-U3MGE2F
Location
Location ID : M1
Sample : MX-UT 0p1 20Ap
Description : (15.979,18.402,-0.833)mm
Tilt : 0.00
Charge Neutraliser : On
Filament Current : 0.53A
Filament Bias : 2.02V
Charge Balance : 5.02V
Settings
Excitation
Mode : XPS - monochromatic
Tuning : Spectroscopy
Emission current : 15.00mA
Anode library : Al
ESCA modes
Collimation : Slot
Lens : Hybrid
Resolution : 20.00
Scan
Deflection : (0.000, 0.000)mm
Ti3s : 1412.690-1442.690eV, Sweeps 5
Start : 1412.690eV
End : 1442.690eV
Centre : 1427.690eV
Width : 30.000eV
Step size : 0.100eV
Number Steps : 300
Dwell time : 199ms
Sweep time : 60s
Sweeps : 5
Target quality : 200
Instrument Conditions
Work function : -4.50
Acquisition Conditions
X-ray Power : 225.00W
Quality : 23.35
XPS
7
15.97875
18.401640625
-0.8333359375
Al (mono)
1486.69
225
1E+37
1E+37
1E+37
1E+37
FAT
20
1E+37
-4.5
1E+37
1E+37
1E+37
1E+37
1E+37
Ti3s

-1
Kinetic energy
eV
1412.69
0.1
2
Intensity
d
Transmission
d
pulse counting
0.199335548172757
5
0
1E+37
1E+37
1E+37
0
602
298
609
1.29494863949153
1.2965505499007
404
1.2965505499007
396
1.29654521019933
378
1.29653987049797
381
1.2965345307966
400
1.29652919109524
416
1.29652385139388
383
1.29651851169251
389
1.29651317199115
403
1.29650783228978
372
1.29650249258842
382
1.29649715288706
397
1.29649181318569
353
1.29648647348433
377
1.29648113378297
369
1.2964757940816
389
1.29647045438024
381
1.29646511467887
368
1.29645977497751
345
1.29645443527615
363
1.29644909557478
401
1.29644375587342
386
1.29643841617205
377
1.29643307647069
403
1.29642773676933
414
1.29642239706796
387
1.2964170573666
389
1.29641171766523
385
1.29640637796387
363
1.29640103826251
363
1.29639569856114
347
1.29639035885978
381
1.29638501915842
368
1.29637967945705
360
1.29637433975569
348
1.29636900005432
346
1.29636366035296
354
1.2963583206516
396
1.29635298095023
360
1.29634764124887
362
1.2963423015475
367
1.29633696184614
375
1.29633162214478
368
1.29632628244341
371
1.29632094274205
346
1.29631560304068
350
1.29631026333932
358
1.29630492363796
372
1.29629958393659
365
1.29629424423523
343
1.29628890453386
359
1.2962835648325
367
1.29627822513114
345
1.29627288542977
357
1.29626754572841
408
1.29626220602705
359
1.29625686632568
389
1.29625152662432
391
1.29624618692295
353
1.29624084722159
352
1.29623550752023
372
1.29623016781886
372
1.2962248281175
367
1.29621948841613
393
1.29621414871477
374
1.29620880901341
381
1.29620346931204
349
1.29619812961068
393
1.29619278990931
372
1.29618745020795
379
1.29618211050659
368
1.29617677080522
373
1.29617143110386
360
1.2961660914025
340
1.29616075170113
390
1.29615541199977
392
1.2961500722984
383
1.29614473259704
363
1.29613939289568
381
1.29613405319431
378
1.29612871349295
373
1.29612337379158
351
1.29611803409022
366
1.29611269438886
384
1.29610735468749
384
1.29610201498613
388
1.29609667528476
367
1.2960913355834
384
1.29608599588204
362
1.29608065618067
380
1.29607531647931
343
1.29606997677794
361
1.29606463707658
369
1.29605929737522
386
1.29605395767385
381
1.29604861797249
387
1.29604327827113
361
1.29603793856976
366
1.2960325988684
397
1.29602725916703
397
1.29602191946567
407
1.29601657976431
397
1.29601124006294
397
1.29600590036158
408
1.29600056066021
418
1.29599522095885
412
1.29598988125749
399
1.29598454155612
424
1.29597920185476
425
1.29597386215339
414
1.29596852245203
405
1.29596318275067
425
1.2959578430493
425
1.29595250334794
466
1.29594716364658
426
1.29594182394521
436
1.29593648424385
451
1.29593114454248
450
1.29592580484112
443
1.29592046513976
446
1.29591512543839
483
1.29590978573703
502
1.29590444603566
512
1.2958991063343
494
1.29589376663294
486
1.29588842693157
477
1.29588308723021
509
1.29587774752884
494
1.29587240782748
509
1.29586706812612
530
1.29586172842475
514
1.29585638872339
534
1.29585104902202
515
1.29584570932066
514
1.2958403696193
542
1.29583502991793
533
1.29582969021657
565
1.29582435051521
576
1.29581901081384
596
1.29581367111248
596
1.29580833141111
605
1.29580299170975
560
1.29579765200839
609
1.29579231230702
570
1.29578697260566
586
1.29578163290429
578
1.29577629320293
595
1.29577095350157
589
1.2957656138002
582
1.29576027409884
608
1.29575493439747
607
1.29574959469611
563
1.29574425499475
537
1.29573891529338
507
1.29573357559202
517
1.29572823589066
494
1.29572289618929
508
1.29571755648793
535
1.29571221678656
501
1.2957068770852
500
1.29570153738384
485
1.29569619768247
460
1.29569085798111
479
1.29568551827974
449
1.29568017857838
400
1.29567483887702
398
1.29566949917565
411
1.29566415947429
379
1.29565881977292
403
1.29565348007156
390
1.2956481403702
399
1.29564280066883
387
1.29563746096747
400
1.2956321212661
389
1.29562678156474
389
1.29562144186338
366
1.29561610216201
390
1.29561076246065
362
1.29560542275929
355
1.29560008305792
381
1.29559474335656
369
1.29558940365519
353
1.29558406395383
347
1.29557872425247
370
1.2955733845511
371
1.29556804484974
362
1.29556270514837
342
1.29555736544701
355
1.29555202574565
363
1.29554668604428
372
1.29554134634292
376
1.29553600664155
368
1.29553066694019
326
1.29552532723883
376
1.29551998753746
365
1.2955146478361
330
1.29550930813473
343
1.29550396843337
341
1.29549862873201
364
1.29549328903064
361
1.29548794932928
334
1.29548260962792
342
1.29547726992655
352
1.29547193022519
361
1.29546659052382
338
1.29546125082246
345
1.2954559111211
332
[...]
347
1.29519426575426
351
1.2951889260529
338
1.29518358635154
332
1.29517824665017
381
1.29517290694881
360
1.29516756724745
360
1.29516222754608
351
1.29515688784472
369
1.29515154814335
350
1.29514620844199
368
1.29514086874063
329
1.29513552903926
349
1.2951301893379
363
1.29512484963653
379
1.29511950993517
361
1.29511417023381
342
1.29510883053244
346
1.29510349083108
332
1.29509815112971
346
1.29509281142835
352
1.29508747172699
348
1.29508213202562
355
1.29507679232426
356
1.29507145262289
363
1.29506611292153
349
1.29506077322017
339
1.2950554335188
358
1.29505009381744
352
1.29504475411608
343
1.29503941441471
325
1.29503407471335
336
1.29502873501198
314
1.29502339531062
362
1.29501805560926
330
1.29501271590789
327
1.29500737620653
322
1.29500203650516
307
1.2949966968038
298
1.29499135710244
324
1.29498601740107
325
1.29498067769971
315
1.29497533799834
324
1.29496999829698
315
1.29496465859562
324
1.29495931889425
314
1.29495397919289
311
1.29494863949153
303
1.29494329979016
289
1.2949379600888
293
1.29493262038743
312
1.29492728068607
315
1.29492194098471
294
1.29491660128334
323
1.29491126158198
334
1.29490592188061
326
1.29490058217925
310
1.29489524247789
301
1.29488990277652
308
1.29488456307516
339
1.29487922337379
326
1.29487388367243
357
1.29486854397107
319
1.2948632042697
303
1.29485786456834
300
1.29485252486697
322
1.29484718516561
304
1.29484184546425
310
1.29483650576288
321
1.29483116606152
330
1.29482582636016
322
1.29482048665879
329
1.29481514695743
321
1.29480980725606
316
1.2948044675547
312
1.29479912785334
294
1.29479378815197
316
1.29478844845061
319
1.29478310874924
332
1.29477776904788
339
1.29477242934652
333
1.29476708964515
344
1.29476174994379
345
1.29475641024242
324
1.29475107054106
339
1.2947457308397
344
1.29474039113833
313
1.29473505143697
350
1.29472971173561
346
1.29472437203424
349
1.29471903233288
387
1.29471369263151
352
1.29470835293015
345
1.29470301322879
353
1.29469767352742
364
1.29469233382606
353
1.29468699412469
344
1.29468165442333
360
1.29467631472197
342
1.2946709750206
381
1.29466563531924
385
1.29466029561787
370
1.29465495591651
405
1.29464961621515
395
1.29464427651378
391
1.29463893681242
420
1.29463359711105
409
1.29462825740969
386
1.29462291770833
417
1.29461757800696
435
1.2946122383056
427
1.29460689860424
456
1.29460155890287
443
1.29459621920151
471
1.29459087950014
483
1.29458553979878
461
1.29458020009742
449
1.29457486039605
493
1.29456952069469
476
1.29456418099332
522
1.29455884129196
490
1.2945535015906
522
1.29454816188923
561
1.29454282218787
552
1.2945374824865
563
1.29453214278514
554
1.29452680308378
618
1.29452146338241
609
1.29451612368105
597
1.29451078397968
648
1.29450544427832
733
1.29450010457696
726
1.29449476487559
711
1.29448942517423
692
1.29448408547287
706
1.2944787457715
773
1.29447340607014
736
1.29446806636877
751
1.29446272666741
792
1.29445738696605
807
1.29445204726468
756
1.29444670756332
776
1.29444136786195
802
1.29443602816059
789
1.29443068845923
775
1.29442534875786
744
1.2944200090565
739
1.29441466935513
730
1.29440932965377
714
1.29440398995241
694
1.29439865025104
652
1.29439331054968
588
1.29438797084832
560
1.29438263114695
511
1.29437729144559
459
1.29437195174422
427
1.29436661204286
372
1.2943612723415
320
1.29435593264013
299
1.29435059293877
282
1.2943452532374
278
1.29433991353604
249
1.29433457383468
254
1.29432923413331
228
1.29432389443195
217
1.29431855473058
214
1.29431321502922
205
1.29430787532786
221
1.29430253562649
203
1.29429719592513
194
1.29429185622377
206
1.2942865165224
170
1.29428117682104
204
1.29427583711967
178
1.29427049741831
199
1.29426515771695
197
1.29425981801558
207
1.29425447831422
206
1.29424913861285
216
1.29424379891149
197
1.29423845921013
180
1.29423311950876
203
1.2942277798074
209
1.29422244010603
200
1.29421710040467
204
1.29421176070331
190
1.29420642100194
186
1.29420108130058
199
1.29419574159921
227
1.29419040189785
210
1.29418506219649
202
1.29417972249512
204
1.29417438279376
230
1.2941690430924
223
1.29416370339103
214
1.29415836368967
228
1.2941530239883
234
1.29414768428694
206
1.29414234458558
227
1.29413700488421
203
1.29413166518285
205
1.29412632548148
201
1.29412098578012
174
1.29411564607876
190
1.29411030637739
183
1.29410496667603
181
1.29409962697466
172
1.2940942872733
162
1.29408894757194
165
1.29408360787057
183
1.29407826816921
172
1.29407292846784
154
1.29406758876648
162
1.29406224906512
173
1.29405690936375
164
1.29405156966239
174
1.29404622996103
165
1.29404089025966
172
1.2940355505583
181
1.29403021085693
153
1.29402487115557
151
1.29401953145421
160
1.29401419175284
167
1.29400885205148
165
1.29400351235011
149
1.29399817264875
160
1.29399283294739
158
1.29398749324602
162
1.29398215354466
179
1.29397681384329
176
1.29397147414193
158
1.29396613444057
187
1.2939607947392
194
1.29395545503784
168
1.29395011533648
147
1.29394477563511
150
1.29393943593375
158
1.29393409623238
164
1.29392875653102
186
1.29392341682966
175
1.29391807712829
156
1.29391273742693
159
1.29390739772556
180
1.2939020580242
153
1.29389671832284
157
1.29389137862147
168
1.29388603892011
169
1.29388069921874
162
1.29387535951738
152
1.29387001981602
196
1.29386468011465
182
1.29385934041329
166
1.29385400071192
165
1.29384866101056
161
1.2938433213092
171
1.29383798160783
182
1.29383264190647
177
1.29382730220511
197
1.29382196250374
197
1.29381662280238
196
1.29381128310101
190
1.29380594339965
199
1.29380060369829
199
1.29379526399692
209
1.29378992429556
226
1.29378458459419
219
1.29377924489283
239
1.29377390519147
243
1.2937685654901
220
1.29376322578874
236
1.29375788608737
245
1.29375254638601
237
1.29374720668465
258
1.29374186698328
264
1.29373652728192
282
1.29373118758056
264
1.29372584787919
266
1.29372050817783
278
1.29371516847646
264
1.2937098287751
273
1.29370448907374
258
1.29369914937237
268
1.29369380967101
267
1.29368846996964
287
1.29368313026828
254
1.29367779056692
269
1.29367245086555
273
1.29366711116419
240
1.29366177146282
259
1.29365643176146
257
1.2936510920601
271
1.29364575235873
282
1.29364041265737
266
1.293635072956
252
1.29362973325464
264
1.29362439355328
282
1.29361905385191
277
1.29361371415055
Ti2s
MX-UT 0p1 20Ap
2023
5
9
16
4
28
2
41
Creation
Created by : XPSUser
Date created : 09/05/2023 16:04
Computer : DESKTOP-U3MGE2F
Location
Location ID : M1
Sample : MX-UT 0p1 20Ap
Description : (15.979,18.402,-0.833)mm
Tilt : 0.00
Charge Neutraliser : On
Filament Current : 0.53A
Filament Bias : 2.02V
Charge Balance : 5.02V
Settings
Excitation
Mode : XPS - monochromatic
Tuning : Spectroscopy
Emission current : 15.00mA
Anode library : Al
ESCA modes
Collimation : Slot
Lens : Hybrid
Resolution : 20.00
Scan
Deflection : (0.000, 0.000)mm
Ti2s : 907.690-937.690eV, Sweeps 10
Start : 907.690eV
End : 937.690eV
Centre : 922.690eV
Width : 30.000eV
Step size : 0.100eV
Number Steps : 300
Dwell time : 199ms
Sweep time : 60s
Sweeps : 10
Target quality : 200
Instrument Conditions
Work function : -4.50
Acquisition Conditions
X-ray Power : 225.00W
Quality : 26.73
XPS
9
15.97875
18.401640625
-0.8333359375
Al (mono)
1486.69
225
1E+37
1E+37
1E+37
1E+37
FAT
20
1E+37
-4.5
1E+37
1E+37
1E+37
1E+37
1E+37
Ti2s

-1
Kinetic energy
eV
907.69
0.1
2
Intensity
d
Transmission
d
pulse counting
0.199335548172757
10
0
1E+37
1E+37
1E+37
0
602
9645
11382
1.39835656853096
1.40786093570082
10364
1.40786093570082
10379
1.40783040092986
10447
1.40779986615891
10233
1.40776933138795
10463
1.40773879661699
10627
1.40770826184604
10605
1.40767772707508
10418
1.40764719230412
10526
1.40761665753316
10526
1.40758612276221
10519
1.40755558799125
10429
1.40752505322029
10401
1.40749451844934
10365
1.40746398367838
10367
1.40743344890742
10479
1.40740291413646
10470
1.40737237936551
10537
1.40734184459455
10371
1.40731130982359
10363
1.40728077505264
10408
1.40725024028168
10484
1.40721970551072
10295
1.40718917073976
10298
1.40715863596881
10522
1.40712698331307
10423
1.40709520644792
10475
1.40706342958277
10372
1.40703165271762
10503
1.40699987585246
10534
1.40696809898731
10297
1.40693632212216
10474
1.40690454525701
10494
1.40687276839185
10644
1.4068409915267
10421
1.40680921466155
10313
1.4067774377964
10370
1.40674566093124
10402
1.40671388406609
10482
1.40668210720094
10537
1.40665033033579
10322
1.40661855347063
10243
1.40658677660548
10449
1.40655499974033
10483
1.40652322287517
10487
1.40649144601002
10365
1.40645966914487
10328
1.40642789227972
10567
1.40639611541456
10528
1.40636433854941
10482
1.40633256168426
10518
1.40630078481911
10327
1.40626900795395
10375
1.4062372310888
10435
1.40620545422365
10317
1.4061736773585
10438
1.40614190049334
10548
1.40611012362819
10440
1.40607834676304
10393
1.40604656989789
10388
1.40601479303273
10352
1.40598301616758
10254
1.40595123930243
10356
1.40591946243728
10389
1.40588768557212
10511
1.40585590870697
10425
1.40582413184182
10393
1.40579235497667
10418
1.40576057811151
10374
1.40572880124636
10326
1.40569702438121
10386
1.40566524751605
10349
1.4056334706509
10366
1.40560169378575
10455
1.4055699169206
10380
1.40553814005544
10451
1.40550636319029
10218
1.40547458632514
10511
1.40544280945999
10277
1.40541103259483
10263
1.40537925572968
10397
1.40534747886453
10384
1.40531570199938
10449
1.40528392513422
10327
1.40525214826907
10197
1.40522037140392
10476
1.40518859453877
10364
1.40515681767361
10363
1.40512504080846
10312
1.40509326394331
10285
1.40506148707816
10299
1.405029710213
10242
1.40499793334785
10342
1.4049661564827
10368
1.40493437961755
10335
1.40490260275239
10215
1.40487082588724
10344
1.40483904902209
10509
1.40480727215694
10364
1.40477549529178
10215
1.40474371842663
10292
1.40471194156148
10257
1.40468016469632
10322
1.40464838783117
10439
1.40461661096602
10554
1.40458483410087
10438
1.40455305723571
10423
1.40452128037056
10325
1.40448950350541
10339
1.40445772664026
10414
1.4044259497751
10391
1.40439417290995
10462
1.4043623960448
10442
1.40433061917965
10535
1.40429884231449
10403
1.40426706544934
10413
1.40423528858419
10321
1.40420351171904
10332
1.40417173485388
10590
1.40413995798873
10546
1.40410818112358
10680
1.40407640425843
10572
1.40404462739327
10389
1.40401285052812
10516
1.40398107366297
10569
1.40394929679782
10552
1.40391751993266
10594
1.40388574306751
10614
1.40385396620236
10697
1.40382218933721
10570
1.40379041247205
10510
1.4037586356069
10537
1.40372685874175
10566
1.40369508187659
10515
1.40366330501144
10589
1.40363152814629
10544
1.40359975128114
10648
1.40356797441598
10593
1.40353619755083
10675
1.40350442068568
10740
1.40347264382053
10771
1.40344086695537
10816
1.40340909009022
10599
1.40337731322507
10723
1.40334553635992
10880
1.40331375949476
10812
1.40328198262961
10979
1.40325020576446
10835
1.40321842889931
10717
1.40318665203415
10996
1.403154875169
10946
1.40312309830385
10873
1.4030913214387
10924
1.40305954457354
10859
1.40302776770839
10939
1.40299599084324
11013
1.40296421397809
11221
1.40293243711293
11103
1.40290066024778
11034
1.40286888338263
11032
1.40283710651747
11262
1.40280532965232
11162
1.40277355278717
11021
1.40274177592202
11235
1.40270999905686
11364
1.40267822219171
11278
1.40264644532656
11285
1.40261466846141
11155
1.40258289159625
11117
1.4025511147311
11263
1.40251933786595
11242
1.4024875610008
11235
1.40245578413564
11382
1.40242400727049
11241
1.40239223040534
11144
1.40236045354019
11254
1.40232867667503
11213
1.40229689980988
11125
1.40226512294473
11126
1.40223334607958
11133
1.40220156921442
10923
1.40216979234927
10921
1.40213801548412
10946
1.40210623861897
11043
1.40207446175381
11109
1.40204268488866
11016
1.40201090802351
10970
1.40197913115836
10698
1.4019473542932
10614
1.40191557742805
10746
1.4018838005629
10714
1.40185202369774
10683
1.40182024683259
10763
1.40178846996744
10508
1.40175669310229
10527
1.40172491623713
10600
1.40169313937198
10464
1.40166136250683
10324
1.40162958564168
10613
1.40159780877652
10519
1.40156603191137
10426
1.40153425504622
10475
1.40150247818107
10426
1.40147070131591
10419
1.40143892445076
10343
1.40140714758561
10157
1.40137537072046
10324
1.4013435938553
10287
1.40131181699015
10222
1.401280040125
10304
1.40124826325985
10225
1.40121648639469
10159
1.40118470952954
10107
1.40115293266439
10009
1.40112115579924
10047
1.40108937893408
9998
1.40105760206893
10002
1.40102582520378
10015
1.40099404833863
10120
1.40096227147347
10107
1.40093049460832
10059
1.40089871774317
10030
1.40086694087801
10133
1.40083516401286
10083
1.40080338714771
9965
1.40077161028256
10076
1.4007398334174
10054
1.40070805655225
9985
1.4006762796871
9941
1.40064450282195
9978
1.40061272595679
10000
1.40058094909164
10128
1.40054917222649
10120
1.40051739536134
9915
1.40048561849618
9995
1.40045384163103
9862
1.40042206476588
9963
1.40039028790073
9995
1.40035851103557
9987
1.40032673417042
9910
1.40029495730527
9917
1.40026318044012
9999
1.40023140357496
10031
1.40019962670981
9962
1.40016784984466
10027
1.40013607297951
9979
1.40010429611435
9993
1.4000725192492
9962
1.40004074238405
9870
1.40000896551889
9964
1.39997718865374
9929
1.39994541178859
9887
1.39991363492344
9869
1.39988185805828
9880
1.39985008119313
9882
1.39981830432798
9884
1.39978652746283
9969
1.39975475059767
9959
1.39972297373252
9954
1.39969119686737
9879
1.39965942000222
9816
1.39962764313706
9752
1.39959586627191
9822
1.39956408940676
9848
1.39953231254161
9903
1.39950053567645
9945
1.3994687588113
9953
1.39943698194615
9968
1.399405205081
9913
1.39937342821584
9922
1.39934165135069
10001
1.39930987448554
9809
1.39927809762039
9782
1.39924632075523
9666
1.39921454389008
9740
1.39918276702493
9780
1.39915099015978
9681
1.39911921329462
9739
1.39908743642947
9748
1.39905565956432
9841
1.39902388269916
9719
1.39899210583401
9863
1.39896032896886
9936
1.39892855210371
9765
1.39889677523855
9849
1.3988649983734
9818
1.39883322150825
9917
1.3988014446431
9870
1.39876966777794
9720
1.39873789091279
9701
1.39870611404764
9747
1.39867433718249
9697
1.39864256031733
9761
1.39861078345218
9796
1.39857900658703
9760
1.39854722972188
9809
1.39851545285672
9879
1.39848367599157
9833
1.39845189912642
9937
1.39842012226127
9784
1.39838834539611
9645
1.39835656853096
Ti2p
MX-UT 0p1 20Ap
2023
5
9
16
4
28
2
41
Creation
Created by : XPSUser
Date created : 09/05/2023 16:04
Computer : DESKTOP-U3MGE2F
Location
Location ID : M1
Sample : MX-UT 0p1 20Ap
Description : (15.979,18.402,-0.833)mm
Tilt : 0.00
Charge Neutraliser : On
Filament Current : 0.53A
Filament Bias : 2.02V
Charge Balance : 5.02V
Settings
Excitation
Mode : XPS - monochromatic
Tuning : Spectroscopy
Emission current : 15.00mA
Anode library : Al
ESCA modes
Collimation : Slot
Lens : Hybrid
Resolution : 20.00
Scan
Deflection : (0.000, 0.000)mm
Ti2p : 1016.690-1036.690eV, Sweeps 10
Start : 1016.690eV
End : 1036.690eV
Centre : 1026.690eV
Width : 20.000eV
Step size : 0.100eV
Number Steps : 200
Dwell time : 299ms
Sweep time : 60s
Sweeps : 10
Target quality : 200
Instrument Conditions
Work function : -4.50
Acquisition Conditions
X-ray Power : 225.00W
Quality : 140.55
XPS
10
15.97875
18.401640625
-0.8333359375
Al (mono)
1486.69
225
1E+37
1E+37
1E+37
1E+37
FAT
20
1E+37
-4.5
1E+37
1E+37
1E+37
1E+37
1E+37
Ti2p

-1
Kinetic energy
eV
1016.69
0.1
2
Intensity
d
Transmission
d
pulse counting
0.298507462686567
10
0
1E+37
1E+37
1E+37
0
402
10914
22159
1.34818394035546
1.35812104677082
14476
1.35812104677082
14476
1.35807136123875
14584
1.35802167570667
14494
1.35797199017459
14297
1.35792230464252
14291
1.35787261911044
14243
1.35782293357836
14296
1.35777324804629
14536
1.35772356251421
14446
1.35767387698213
14395
1.35762419145005
14440
1.35757450591798
14333
1.3575248203859
14388
1.35747513485382
14291
1.35742544932175
14336
1.35737576378967
14317
1.35732607825759
14229
1.35727639272552
14410
1.35722670719344
14260
1.35717702166136
14195
1.35712733612929
14060
1.35707765059721
14032
1.35702796506513
14351
1.35697827953306
14323
1.35692859400098
14242
1.3568789084689
14317
1.35682922293683
14347
1.35677953740475
14236
1.35672985187267
14411
1.3566801663406
14406
1.35663048080852
14296
1.35658079527644
14252
1.35653110974437
14114
1.35648142421229
14075
1.35643173868021
14229
1.35638205314813
14230
1.35633236761606
14187
1.35628268208398
14017
1.3562329965519
14149
1.35618331101983
14232
1.35613362548775
14111
1.35608393995567
14240
1.3560342544236
14146
1.35598456889152
13956
1.35593488335944
14196
1.35588519782737
14139
1.35583551229529
14162
1.35578582676321
14305
1.35573614123114
14234
1.35568645569906
14107
1.35563677016698
14191
1.35558708463491
14140
1.35553739910283
14437
1.35548771357075
14440
1.35543802803868
14421
1.3553883425066
14451
1.35533865697452
14676
1.35528897144245
14554
1.35523928591037
14504
1.35518960037829
14528
1.35513991484622
14687
1.35509022931414
14834
1.35504054378206
14872
1.35499085824998
15006
1.35494117271791
14957
1.35489148718583
15102
1.35484180165375
15354
1.35479211612168
15466
1.3547424305896
15513
1.35469274505752
15449
1.35464305952545
15616
1.35459337399337
15769
1.35454368846129
15814
1.35449400292922
16150
1.35444431739714
16164
1.35439463186506
16201
1.35434494633299
16257
1.35429526080091
16472
1.35424557526883
16602
1.35419588973676
16795
1.35414620420468
16811
1.3540965186726
17016
1.35404683314053
17059
1.35399714760845
17394
1.35394746207637
17401
1.3538977765443
17433
1.35384809101222
17469
1.35379840548014
17647
1.35374871994806
17752
1.35369903441599
17795
1.35364934888391
17632
1.35359966335183
17698
1.35354997781976
17491
1.35350029228768
17199
1.3534506067556
16844
1.35340092122353
16619
1.35335123569145
16507
1.35330155015937
16149
1.3532518646273
15775
1.35320217909522
15426
1.35315249356314
15178
1.35310280803107
14844
1.35305312249899
14816
1.35300343696691
14778
1.35295375143484
14727
1.35290406590276
14746
1.35285438037068
14641
1.35280469483861
14608
1.35275500930653
14494
1.35270532377445
14570
1.35265563824238
14611
1.3526059527103
14673
1.35255626717822
14833
1.35250658164615
14876
1.35245689611407
14839
1.35240721058199
14924
1.35235752504991
15077
1.35230783951784
14878
1.35225815398576
14874
1.35220846845368
14963
1.35215878292161
15183
1.35210909738953
15255
1.35205941185745
15450
1.35200972632538
15516
1.3519600407933
15752
1.35191035526122
15809
1.35186066972915
16112
1.35181098419707
16236
1.35176129866499
16689
1.35171161313292
16901
1.35166192760084
17069
1.35161224206876
17319
1.35156255653669
17425
1.35151287100461
17963
1.35146318547253
18142
1.35141349994046
18670
1.35136381440838
19197
1.3513141288763
19230
1.35126444334423
19488
1.35121475781215
19950
1.35116507228007
20272
1.35111538674799
20408
1.35106570121592
20702
1.35101601568384
21115
1.35096633015176
21489
1.35091664461969
21564
1.35086695908761
21873
1.35081727355553
22120
1.35076758802346
22159
1.35071790249138
21996
1.3506682169593
21779
1.35061853142723
21541
1.35056884589515
21680
1.35051916036307
21287
1.350469474831
20832
1.35041978929892
19868
1.35037010376684
18245
1.35032041823477
16150
1.35027073270269
14305
1.35022104717061
13159
1.35017136163854
12387
1.35012167610646
11879
1.35007199057438
11715
1.35002230504231
11522
1.34997261951023
11625
1.34992293397815
11510
1.34987324844607
11426
1.349823562914
11364
1.34977387738192
11337
1.34972419184984
11325
1.34967450631777
11296
1.34962482078569
11248
1.34957513525361
11206
1.34952544972154
11113
1.34947576418946
11035
1.34942607865738
11128
1.34937639312531
11051
1.34932670759323
11078
1.34927702206115
11067
1.34922733652908
11063
1.349177650997
11147
1.34912796546492
11122
1.34907827993285
10977
1.34902859440077
11161
1.34897890886869
11178
1.34892922333662
10929
1.34887953780454
11108
1.34882985227246
11149
1.34878016674039
10957
1.34873048120831
10914
1.34868079567623
10987
1.34863111014416
11033
1.34858142461208
11007
1.34853173908
11100
1.34848205354792
11078
1.34843236801585
11067
1.34838268248377
11176
1.34833299695169
11095
1.34828331141962
11141
1.34823362588754
11032
1.34818394035546
end of experiment