File: XPS/Casa format/UT 18 Ap location T1 in image-0.6322.vms
VAMAS Surface Chemical Analysis Standard Data Transfer Format 1988 May 4
Not specified
MI-600-BE9240AA
XPSUser
KTH Amireza_C-paper-Mxene-sample sent on 17 April2023.experiment
0
NORM
REGULAR
1
4
Index
d
PositionX [mm]
n
PositionY [mm]
n
PositionZ [mm]
n
0
0
0
0
10
wide
UT 18 Ap
2023
5
9
14
29
4
2
39
Creation
Created by : XPSUser
Date created : 09/05/2023 14:29
Computer : DESKTOP-U3MGE2F
Location
Location ID : T1
Sample : UT 18 Ap
Description : (41.239,15.301,-0.906)mm
Tilt : 0.00
Charge Neutraliser : On
Filament Current : 0.53A
Filament Bias : 2.02V
Charge Balance : 5.02V
Settings
Excitation
Mode : XPS - monochromatic
Tuning : Spectroscopy
Emission current : 15.00mA
Anode library : Al
ESCA modes
Collimation : Slot
Lens : Hybrid
Resolution : 160.00
Scan
Deflection : (0.000, 0.000)mm
wide : 286.690-1491.690eV, Sweeps 5
Start : 286.690eV
End : 1491.690eV
Centre : 889.190eV
Width : 1205.000eV
Step size : 1.000eV
Number Steps : 1205
Dwell time : 100ms
Sweep time : 120s
Sweeps : 5
Instrument Conditions
Work function : -4.50
Acquisition Conditions
X-ray Power : 225.00W
XPS
1
41.23875
15.3013671875
-0.9057578125
Al (mono)
1486.69
225
1E+37
1E+37
1E+37
1E+37
FAT
160
1E+37
-4.5
1E+37
1E+37
1E+37
1E+37
1E+37
wide

-1
Kinetic energy
eV
286.69
1
2
Intensity
d
Transmission
d
pulse counting
0.0995024875621891
0
1E+37
0
2
31.1899525550317
21098
21169
20893
20854
20900
20891
20907
20977
20854
20967
21226
21313
21078
21025
20958
21026
20968
21178
21222
21389
21153
21236
21183
21537
21459
21537
21512
21566
21572
21869
22012
21729
21672
21864
21849
21713
22069
21968
21841
21874
21900
21874
21810
21959
21867
21889
21821
22007
21929
22101
22078
22157
22134
22142
22136
22367
22251
22334
22385
22318
22345
22342
22330
22320
22269
22267
22453
22350
22594
22739
22506
22415
22582
22677
22698
22729
22707
22768
22740
22830
22839
22918
22977
23058
23125
22937
23077
23301
23221
23180
23275
23069
23519
23490
23416
23606
23497
23190
23455
23432
23589
23351
23445
23629
23745
23496
23493
23596
23854
23796
23867
23484
23719
23900
24023
23968
23914
23971
24174
24190
24006
23740
24034
24090
23995
24249
24434
24652
24429
25017
24844
24387
24289
24553
24628
24542
24782
24662
24769
24601
24990
24910
24738
24679
25003
24810
24901
25106
25155
25109
25175
25150
25269
25345
25163
25309
25291
25387
25523
25592
25747
25660
25717
25785
25844
25650
25971
26119
25813
26092
26231
26382
26327
26538
26410
26549
26556
26479
26644
26727
27161
27061
26937
27038
27032
27247
27260
27180
27217
27069
27313
27513
27431
27754
27935
28149
28377
28195
28426
28894
28928
28811
28672
28861
28916
28687
28873
28515
28624
28559
28414
28238
28538
28537
28502
28497
28751
28910
29376
29927
29973
30543
31066
31267
31454
31400
31065
30870
30497
30055
29615
29170
28582
27918
27379
27071
26913
26771
26598
26646
26721
26537
26553
26570
26668
26614
26648
26900
26719
26726
26542
26710
27127
27088
26912
26831
26581
26889
26977
26911
26910
27099
27222
27100
27208
27011
27082
27222
27428
27032
27058
27324
27346
27190
27146
27302
27410
27550
27383
27575
27705
27455
27553
27682
27527
27570
27644
27627
27795
27512
27549
27848
27722
27972
27876
27711
27994
27956
27625
27851
27870
27962
28034
28156
27912
27723
28103
28059
28083
28364
28002
28052
28042
28159
28426
28739
28518
28437
28416
28293
28198
28665
28338
28301
28577
28573
28713
28524
28805
28551
28706
28525
28629
28654
28798
28892
28749
28868
28880
28679
28951
29136
28948
28997
29045
29135
29158
29032
29035
29040
29312
28973
29167
28982
29317
29256
29325
28987
29004
29241
29206
29262
29227
29255
29512
29170
29191
29469
29594
29623
29583
29562
29525
29470
29401
29556
29838
29566
29701
29485
29680
29764
29650
29769
29890
29758
29740
30071
30144
29998
30215
30127
29988
30078
30199
30280
30085
30070
30077
30123
29964
30320
30501
30033
29977
30143
30358
30339
30162
30247
30377
30266
30552
30365
30524
30186
30352
30661
30532
30433
30359
30521
30455
30462
30606
30540
30695
30636
30857
30628
30562
30962
30854
30717
30711
30736
30817
30906
30860
30752
30933
31321
31226
30971
30943
31122
31014
31165
30944
31003
30856
31029
31098
31247
31394
31533
31096
31488
31215
31245
31614
31565
31260
31384
31527
31428
31517
31492
31559
31321
31466
31695
31741
31946
31373
31533
31499
31831
31657
31811
31653
31651
31642
31897
31948
31844
31921
31571
31561
31772
31901
31798
31860
31784
32001
31957
32094
31985
32109
32131
32159
31946
32286
32264
32070
31897
32079
32322
32061
32328
32298
32260
32361
32462
32399
32345
32409
32294
32566
32529
32313
32447
32408
32659
32563
32585
32415
32298
32497
32557
32461
32805
32652
32572
32657
32596
32650
32633
32635
32426
32822
32904
32965
33056
32689
32881
32851
32757
33268
33043
32758
32871
33238
33037
33060
33187
33238
33285
33402
33461
33278
32959
33281
33208
33297
33247
33380
33422
33414
33261
33354
33404
33551
33823
33429
33555
33526
33339
33544
33676
33570
33651
33570
33593
33538
33834
33724
33765
33926
33672
33803
33975
34030
33892
33677
33651
34011
34292
34197
34337
34229
34276
34194
34523
34400
34352
34371
34239
34418
34507
34593
34449
34310
34624
34450
34450
34535
34726
34816
34730
34644
34975
34851
35205
34741
34803
35016
34950
35010
34858
35038
35309
34999
35014
35293
35269
35370
35622
35433
35786
35753
35538
35594
35785
35715
35868
35787
36034
35709
35734
35913
35578
35434
35789
35775
35595
35622
35299
35227
35609
35589
35580
35709
35832
36323
37292
39826
45266
49637
46818
40714
36664
35462
35098
34947
35131
35000
34412
34577
34659
34570
34911
35092
35065
34994
34951
35044
35086
34975
34781
34821
35065
34823
35048
35151
35106
35291
35421
35201
35482
35299
35409
35434
35338
35443
35381
35507
35477
35266
35462
35584
35240
35340
35801
35758
35506
35746
35805
35423
35644
35626
35868
35677
35679
35816
35515
35597
35989
35901
36088
36040
35816
35904
35805
36121
36067
36151
36161
36022
35883
35999
36237
36268
36428
35979
36150
36505
36258
36137
36403
36453
36514
36365
36647
36489
36564
36559
36412
36259
36697
36726
36585
36732
36751
36817
36942
37184
36891
36698
36960
36896
37013
37020
37026
36941
37239
37379
36848
37427
37570
37313
37224
37449
37299
37248
37173
37640
37707
37635
37601
37464
37634
37591
37528
37763
37642
37601
37917
38072
38277
38315
38463
38302
38422
38049
38072
38066
38147
38082
38183
38230
38211
38293
38226
38012
38269
38208
38511
38238
38512
38610
38345
38502
38548
38930
38972
38792
38594
38639
38885
38954
38928
38809
39069
38931
38791
38775
38799
38506
38982
39073
39262
39015
39190
39487
39359
39287
39568
39806
39923
39993
40117
40198
40480
40496
40755
40385
40527
40559
40208
40255
40060
39755
39504
39036
38732
38451
38217
38041
37728
37489
37785
37796
38430
38774
39081
39672
40370
41300
41569
42430
43186
43597
43932
44295
44596
44519
44922
44423
43706
42852
41567
39555
37482
35070
32971
31147
29347
27253
25330
23638
22311
21807
21291
21432
22300
24141
26182
29197
33285
36240
37439
39855
46998
66969
123889
210034
148955
37925
7673
4633
3373
2407
1873
1667
1499
1464
1477
1446
1441
1376
1399
1413
1353
1307
1334
1282
1254
1228
1279
1282
1272
1288
1308
1324
1241
1254
1284
1260
1300
1293
1282
1305
1280
1241
1247
1276
1303
1342
1292
1311
1296
1300
1295
1293
1291
1293
1308
1289
1288
1279
1217
1281
1348
1330
1335
1276
1313
1288
1265
1293
1282
1230
1243
1267
1309
1346
1287
1307
1292
1300
1328
1290
1267
1305
1271
1283
1292
1291
1296
1349
1321
1269
1314
1333
1297
1307
1335
1330
1344
1328
1282
1292
1358
1317
1290
1291
1363
1321
1270
1295
1292
1304
1333
1301
1281
1363
1351
1302
1270
1326
1357
1364
1368
1337
1299
1299
1328
1284
1293
1319
1282
1313
1339
1328
1360
1392
1454
1436
1400
1374
1334
1342
1337
1292
1273
1291
1342
1310
1291
1344
1336
1257
1259
1345
1329
1375
1374
1319
1330
1326
1380
1388
1374
1349
1353
1337
1380
1357
1293
1379
1321
1334
1372
1367
1320
1298
1345
1337
1315
1331
1317
1331
1335
1328
1369
1392
1446
1444
1436
1432
1427
1388
1368
1361
1347
1361
1328
1334
1345
1375
1332
1365
1360
1357
1384
1383
1431
1445
1454
1380
1434
1464
1460
1458
1465
1402
1428
1508
1452
1416
1418
1432
1396
1361
1417
1396
1447
1454
1420
1383
1411
1413
1419
1407
1489
1470
1502
1534
1540
1595
1616
1600
1632
1573
1614
1619
1632
1563
1563
1561
1472
1497
1428
1308
1246
1260
1251
1173
1141
1180
1238
1347
1399
1475
1563
1587
1681
1853
2117
2389
2549
2544
2563
2462
2297
2101
1983
1712
1466
1312
1199
1044
874
735
512
383
248
146
85
40
15
7
2
3
3
31.1899525550317
C 1s
UT 18 Ap
2023
5
9
18
57
10
2
41
Creation
Created by : XPSUser
Date created : 09/05/2023 18:57
Computer : DESKTOP-U3MGE2F
Location
Location ID : T1
Sample : UT 18 Ap
Description : (41.239,15.301,-0.906)mm
Tilt : 0.00
Charge Neutraliser : On
Filament Current : 0.53A
Filament Bias : 2.02V
Charge Balance : 5.02V
Settings
Excitation
Mode : XPS - monochromatic
Tuning : Spectroscopy
Emission current : 15.00mA
Anode library : Al
ESCA modes
Collimation : Slot
Lens : Hybrid
Resolution : 20.00
Scan
Deflection : (0.000, 0.000)mm
C 1s : 1191.690-1209.690eV, Sweeps 1
Start : 1191.690eV
End : 1209.690eV
Centre : 1200.690eV
Width : 18.000eV
Step size : 0.100eV
Number Steps : 180
Dwell time : 331ms
Sweep time : 60s
Sweeps : 1
Target quality : 200
Instrument Conditions
Work function : -4.50
Acquisition Conditions
X-ray Power : 225.00W
Quality : 330.26
XPS
2
41.23875
15.3013671875
-0.9057578125
Al (mono)
1486.69
225
1E+37
1E+37
1E+37
1E+37
FAT
20
1E+37
-4.5
1E+37
1E+37
1E+37
1E+37
1E+37
C
1s
-1
Kinetic energy
eV
1191.69
0.1
2
Intensity
d
Transmission
d
pulse counting
0.331492
1
0
1E+37
1E+37
1E+37
0
362
48
24820
1.33571680812406
1.34279197206053
721
1.33571680812406
762
1.33575611459037
759
1.33579542105669
798
1.335834727523
820
1.33587403398932
840
1.33591334045563
792
1.33595264692194
825
1.33599195338826
810
1.33603125985457
842
1.33607056632088
847
1.3361098727872
819
1.33614917925351
848
1.33618848571983
833
1.33622779218614
800
1.33626709865245
831
1.33630640511877
795
1.33634571158508
797
1.33638501805139
808
1.33642432451771
852
1.33646363098402
846
1.33650293745034
846
1.33654224391665
861
1.33658155038296
872
1.33662085684928
865
1.33666016331559
870
1.3366994697819
880
1.33673877624822
895
1.33677808271453
907
1.33681738918085
942
1.33685669564716
977
1.33689600211347
988
1.33693530857979
1001
1.3369746150461
996
1.33701392151241
1034
1.33705322797873
1083
1.33709253444504
1109
1.33713184091135
1107
1.33717114737767
1106
1.33721045384398
1104
1.3372497603103
1201
1.33728906677661
1128
1.33732837324292
1200
1.33736767970924
1198
1.33740698617555
1230
1.33744629264186
1172
1.33748559910818
1193
1.33752490557449
1178
1.33756421204081
1214
1.33760351850712
1200
1.33764282497343
1090
1.33768213143975
1135
1.33772143790606
1159
1.33776074437237
1127
1.33780005083869
1166
1.337839357305
1156
1.33787866377132
1137
1.33791797023763
1141
1.33795727670394
1122
1.33799658317026
1104
1.33803588963657
1131
1.33807519610288
1134
1.3381145025692
1134
1.33815380903551
1142
1.33819311550182
1152
1.33823242196814
1161
1.33827172843445
1189
1.33831103490077
1154
1.33835034136708
1166
1.33838964783339
1156
1.33842895429971
1160
1.33846826076602
1171
1.33850756723233
1128
1.33854687369865
1160
1.33858618016496
1219
1.33862548663128
1232
1.33866479309759
1284
1.3387040995639
1299
1.33874340603022
1290
1.33878271249653
1300
1.33882201896284
1316
1.33886132542916
1405
1.33890063189547
1417
1.33893993836179
1459
1.3389792448281
1498
1.33901855129441
1571
1.33905785776073
1594
1.33909716422704
1712
1.33913647069335
1774
1.33917577715967
1844
1.33921508362598
1981
1.3392543900923
2027
1.33929369655861
2131
1.33933300302492
2218
1.33937230949124
2301
1.33941161595755
2386
1.33945092242386
2440
1.33949022889018
2529
1.33952953535649
2742
1.3395688418228
2887
1.33960814828912
3093
1.33964745475543
3382
1.33968676122175
3682
1.33972606768806
4259
1.33976537415437
5026
1.33980468062069
6002
1.339843987087
7615
1.33988329355331
10084
1.33992260001963
13816
1.33996190648594
18764
1.34000121295226
23025
1.34004051941857
24820
1.34007982588488
22477
1.3401191323512
16787
1.34015843881751
10456
1.34019774528382
5895
1.34023705175014
3322
1.34027635821645
2016
1.34031566468277
1413
1.34035497114908
1069
1.34039427761539
794
1.34043358408171
595
1.34047289054802
470
1.34051219701433
369
1.34055150348065
324
1.34059080994696
279
1.34063011641328
244
1.34066942287959
221
1.3407087293459
213
1.34074803581222
178
1.34078734227853
174
1.34082664874484
169
1.34086595521116
161
1.34090526167747
144
1.34094456814378
129
1.3409838746101
126
1.34102318107641
135
1.34106248754273
113
1.34110179400904
118
1.34114110047535
117
1.34118040694167
103
1.34121971340798
100
1.34125901987429
106
1.34129832634061
97
1.34133763280692
89
1.34137693927324
82
1.34141624573955
82
1.34145555220586
81
1.34149485867218
74
1.34153416513849
81
1.3415734716048
82
1.34161277807112
62
1.34165208453743
68
1.34169139100375
78
1.34173069747006
63
1.34177000393637
64
1.34180931040269
58
1.341848616869
72
1.34188792333531
61
1.34192722980163
65
1.34196653626794
54
1.34200584273426
59
1.34204514920057
49
1.34208445566688
55
1.3421237621332
53
1.34216306859951
55
1.34220237506582
53
1.34224168153214
55
1.34228098799845
61
1.34232029446476
49
1.34235960093108
54
1.34239890739739
61
1.34243821386371
63
1.34247752033002
64
1.34251682679633
64
1.34255613326265
67
1.34259543972896
57
1.34263474619527
49
1.34267405266159
55
1.3427133591279
50
1.34275266559422
48
1.34279197206053
Cl2s
UT 18 Ap
2023
5
9
18
57
10
2
41
Creation
Created by : XPSUser
Date created : 09/05/2023 18:57
Computer : DESKTOP-U3MGE2F
Location
Location ID : T1
Sample : UT 18 Ap
Description : (41.239,15.301,-0.906)mm
Tilt : 0.00
Charge Neutraliser : On
Filament Current : 0.53A
Filament Bias : 2.02V
Charge Balance : 5.02V
Settings
Excitation
Mode : XPS - monochromatic
Tuning : Spectroscopy
Emission current : 15.00mA
Anode library : Al
ESCA modes
Collimation : Slot
Lens : Hybrid
Resolution : 20.00
Scan
Deflection : (0.000, 0.000)mm
Cl2s : 1201.690-1231.690eV, Sweeps 1
Start : 1201.690eV
End : 1231.690eV
Centre : 1216.690eV
Width : 30.000eV
Step size : 0.100eV
Number Steps : 300
Dwell time : 199ms
Sweep time : 60s
Sweeps : 1
Target quality : 200
Instrument Conditions
Work function : -4.50
Acquisition Conditions
X-ray Power : 225.00W
Quality : 602.81
XPS
3
41.23875
15.3013671875
-0.9057578125
Al (mono)
1486.69
225
1E+37
1E+37
1E+37
1E+37
FAT
20
1E+37
-4.5
1E+37
1E+37
1E+37
1E+37
1E+37
Cl2s

-1
Kinetic energy
eV
1201.69
0.1
2
Intensity
d
Transmission
d
pulse counting
0.199335548172757
1
0
1E+37
1E+37
1E+37
0
602
19
14926
1.33964745475543
1.35143939464955
1934
1.33964745475543
2085
1.33968676122175
2345
1.33972606768806
2672
1.33976537415437
3097
1.33980468062069
3890
1.339843987087
4856
1.33988329355331
6564
1.33992260001963
8921
1.33996190648594
11735
1.34000121295226
14281
1.34004051941857
14926
1.34007982588488
12881
1.3401191323512
9239
1.34015843881751
5575
1.34019774528382
3007
1.34023705175014
1765
1.34027635821645
1121
1.34031566468277
820
1.34035497114908
597
1.34039427761539
437
1.34043358408171
364
1.34047289054802
262
1.34051219701433
213
1.34055150348065
178
1.34059080994696
162
1.34063011641328
162
1.34066942287959
138
1.3407087293459
126
1.34074803581222
107
1.34078734227853
106
1.34082664874484
89
1.34086595521116
85
1.34090526167747
85
1.34094456814378
84
1.3409838746101
76
1.34102318107641
74
1.34106248754273
72
1.34110179400904
65
1.34114110047535
68
1.34118040694167
69
1.34121971340798
52
1.34125901987429
60
1.34129832634061
60
1.34133763280692
40
1.34137693927324
44
1.34141624573955
56
1.34145555220586
53
1.34149485867218
43
1.34153416513849
49
1.3415734716048
45
1.34161277807112
36
1.34165208453743
40
1.34169139100375
43
1.34173069747006
37
1.34177000393637
35
1.34180931040269
30
1.341848616869
31
1.34188792333531
34
1.34192722980163
28
1.34196653626794
35
1.34200584273426
31
1.34204514920057
29
1.34208445566688
28
1.3421237621332
32
1.34216306859951
32
1.34220237506582
27
1.34224168153214
27
1.34228098799845
27
1.34232029446476
34
1.34235960093108
28
1.34239890739739
39
1.34243821386371
41
1.34247752033002
29
1.34251682679633
24
1.34255613326265
27
1.34259543972896
37
1.34263474619527
34
1.34267405266159
27
1.3427133591279
38
1.34275266559422
26
1.34279197206053
35
1.34283127852684
32
1.34287058499316
29
1.34290989145947
23
1.34294919792578
21
1.3429885043921
35
1.34302781085841
34
1.34306711732473
38
1.34310642379104
32
1.34314573025735
26
1.34318503672367
21
1.34322434318998
19
1.34326364965629
22
1.34330295612261
34
1.34334226258892
30
1.34338156905524
28
1.34342087552155
28
1.34346018198786
30
1.34349948845418
32
1.34353879492049
32
1.3435781013868
35
1.34361740785312
32
1.34365671431943
29
1.34369602078574
32
1.34373532725206
30
1.34377463371837
33
1.34381394018469
36
1.343853246651
28
1.34389255311731
27
1.34393185958363
31
1.34397116604994
30
1.34401047251625
25
1.34404977898257
22
1.34408908544888
24
1.3441283919152
31
1.34416769838151
28
1.34420700484782
30
1.34424631131414
23
1.34428561778045
31
1.34432492424676
28
1.34436423071308
26
1.34440353717939
36
1.34444284364571
32
1.34448215011202
32
1.34452145657833
31
1.34456076304465
31
1.34460006951096
33
1.34463937597727
28
1.34467868244359
23
1.3447179889099
32
1.34475729537622
29
1.34479660184253
33
1.34483590830884
32
1.34487521477516
30
1.34491452124147
30
1.34495382770778
34
1.3449931341741
33
1.34503244064041
33
1.34507174710672
31
1.34511105357304
20
1.34515036003935
27
1.34518966650567
35
1.34522897297198
25
1.34526827943829
30
1.34530758590461
32
1.34534689237092
27
1.34538619883723
29
1.34542550530355
32
1.34546481176986
31
1.34550411823618
28
1.34554342470249
21
1.3455827311688
27
1.34562203763512
28
1.34566134410143
23
1.34570065056774
34
1.34573995703406
33
1.34577926350037
33
1.34581856996669
25
1.345857876433
31
1.34589718289931
26
1.34593648936563
23
1.34597579583194
33
1.34601510229825
34
1.34605440876457
34
1.34609371523088
33
1.34613302169719
29
1.34617232816351
33
1.34621163462982
33
1.34625094109614
32
1.34629024756245
33
1.34632955402876
27
1.34636886049508
24
1.34640816696139
22
1.3464474734277
28
1.34648677989402
28
1.34652608636033
25
1.34656539282665
30
1.34660469929296
29
1.34664400575927
31
1.34668331222559
24
1.3467226186919
27
1.34676192515821
35
1.34680123162453
34
1.34684053809084
27
1.34687984455716
25
1.34691915102347
32
1.34695845748978
30
1.3469977639561
25
1.34703707042241
28
1.34707637688872
27
1.34711568335504
27
1.34715498982135
26
1.34719429628767
29
1.34723360275398
31
1.34727290922029
29
1.34731221568661
22
1.34735152215292
28
1.34739082861923
32
1.34743013508555
34
1.34746944155186
32
1.34750874801817
28
1.34754805448449
30
1.3475873609508
30
1.34762666741712
30
1.34766597388343
22
1.34770528034974
22
1.34774458681606
23
1.34778389328237
26
1.34782319974868
25
1.347862506215
24
1.34790181268131
34
1.34794111914763
37
1.34798042561394
34
1.34801973208025
30
1.34805903854657
26
1.34809834501288
24
1.34813765147919
34
1.34817695794551
38
1.34821626441182
25
1.34825557087814
24
1.34829487734445
29
1.34833418381076
24
1.34837349027708
28
1.34841279674339
24
1.3484521032097
33
1.34849140967602
33
1.34853071614233
27
1.34857002260865
27
1.34860932907496
29
1.34864863554127
31
1.34868794200759
25
1.3487272484739
23
1.34876655494021
30
1.34880586140653
40
1.34884516787284
26
1.34888447433916
25
1.34892378080547
20
1.34896308727178
26
1.3490023937381
26
1.34904170020441
28
1.34908100667072
20
1.34912031313704
23
1.34915961960335
29
1.34919892606966
31
1.34923823253598
39
1.34927753900229
35
1.34931684546861
30
1.34935615193492
23
1.34939545840123
25
1.34943476486755
22
1.34947407133386
20
1.34951337780017
32
1.34955268426649
33
1.3495919907328
40
1.34963129719912
30
1.34967060366543
31
1.34970991013174
26
1.34974921659806
30
1.34978852306437
22
1.34982782953068
25
1.349867135997
20
1.34990644246331
23
1.34994574892963
30
1.34998505539594
26
1.35002436186225
28
1.35006366832857
28
1.35010297479488
25
1.35014228126119
41
1.35018158772751
30
1.35022089419382
31
1.35026020066013
31
1.35029950712645
35
1.35033881359276
31
1.35037812005908
32
1.35041742652539
30
1.3504567329917
37
1.35049603945802
32
1.35053534592433
20
1.35057465239064
28
1.35061395885696
26
1.35065326532327
24
1.35069257178959
25
1.3507318782559
24
1.35077118472221
28
1.35081049118853
24
1.35084979765484
30
1.35088910412115
22
1.35092841058747
22
1.35096771705378
24
1.3510070235201
26
1.35104632998641
30
1.35108563645272
32
1.35112494291904
27
1.35116424938535
28
1.35120355585166
27
1.35124286231798
26
1.35128216878429
28
1.35132147525061
33
1.35136078171692
33
1.35140008818323
24
1.35143939464955
F1s
UT 18 Ap
2023
5
9
18
57
10
2
41
Creation
Created by : XPSUser
Date created : 09/05/2023 18:57
Computer : DESKTOP-U3MGE2F
Location
Location ID : T1
Sample : UT 18 Ap
Description : (41.239,15.301,-0.906)mm
Tilt : 0.00
Charge Neutraliser : On
Filament Current : 0.53A
Filament Bias : 2.02V
Charge Balance : 5.02V
Settings
Excitation
Mode : XPS - monochromatic
Tuning : Spectroscopy
Emission current : 15.00mA
Anode library : Al
ESCA modes
Collimation : Slot
Lens : Hybrid
Resolution : 20.00
Scan
Deflection : (0.000, 0.000)mm
F1s : 791.690-811.690eV, Sweeps 5
Start : 791.690eV
End : 811.690eV
Centre : 801.690eV
Width : 20.000eV
Step size : 0.100eV
Number Steps : 200
Dwell time : 299ms
Sweep time : 60s
Sweeps : 5
Target quality : 200
Instrument Conditions
Work function : -4.50
Acquisition Conditions
X-ray Power : 225.00W
Quality : 7.95
XPS
4
41.23875
15.3013671875
-0.9057578125
Al (mono)
1486.69
225
1E+37
1E+37
1E+37
1E+37
FAT
20
1E+37
-4.5
1E+37
1E+37
1E+37
1E+37
1E+37
F1s

-1
Kinetic energy
eV
791.69
0.1
2
Intensity
d
Transmission
d
pulse counting
0.298507462686567
5
0
1E+37
1E+37
1E+37
0
402
5571
5931
1.45714403256293
1.46809980524165
5789
1.46809980524165
5729
1.46804594968559
5766
1.46799209412953
5786
1.46793823857347
5866
1.46788438301742
5721
1.46783052746136
5701
1.4677766719053
5691
1.46772281634924
5810
1.46766896079318
5691
1.46761510523713
5718
1.46756124968107
5693
1.46750739412501
5647
1.46745353856895
5677
1.46739968301289
5750
1.46734582745684
5654
1.46729197190078
5571
1.46723811634472
5792
1.46718426078866
5804
1.4671304052326
5830
1.46707654967654
5885
1.46702269412049
5715
1.46696883856443
5741
1.46691498300837
5740
1.46686112745231
5735
1.46680727189625
5829
1.4667534163402
5779
1.46669956078414
5918
1.46664570522808
5861
1.46659184967202
5751
1.46653799411596
5727
1.46648413855991
5742
1.46643028300385
5731
1.46637642744779
5792
1.46632257189173
5745
1.46626871633567
5627
1.46621486077962
5848
1.46616100522356
5833
1.4661071496675
5690
1.46605329411144
5680
1.46599943855538
5675
1.46594558299933
5787
1.46589172744327
5841
1.46583787188721
5893
1.46578401633115
5931
1.46573016077509
5713
1.46567630521904
5768
1.46562244966298
5893
1.46556859410692
5780
1.46551473855086
5797
1.4654608829948
5743
1.46540702743874
5694
1.46535317188269
5854
1.46529931632663
5847
1.46524546077057
5793
1.46519160521451
5773
1.46513774965845
5786
1.4650838941024
5857
1.46503003854634
5806
1.46497618299028
5766
1.46492232743422
5890
1.46486847187816
5838
1.46481461632211
5798
1.46476076076605
5818
1.46470690520999
5829
1.46465304965393
5813
1.46459919409787
5799
1.46454533854182
5824
1.46449148298576
5747
1.4644376274297
5804
1.46438377187364
5829
1.46432991631758
5848
1.46427606076153
5791
1.46422220520547
5730
1.46416834964941
5725
1.46411449409335
5823
1.46406063853729
5847
1.46400678298124
5831
1.46395292742518
5686
1.46389907186912
5698
1.46384521631306
5841
1.463791360757
5792
1.46373750520094
5779
1.46368364964489
5827
1.46362979408883
5855
1.46357593853277
5842
1.46352208297671
5833
1.46346822742065
5787
1.4634143718646
5780
1.46336051630854
5782
1.46330666075248
5810
1.46325280519642
5761
1.46319894964036
5746
1.46314509408431
5753
1.46309123852825
5786
1.46303738297219
5891
1.46298352741613
5738
1.46292967186007
5760
1.46287581630402
5734
1.46282196074796
5694
1.4627681051919
5720
1.46271424963584
5847
1.46266039407978
5803
1.46260653852373
5710
1.46255268296767
5778
1.46249882741161
5838
1.46244497185555
5740
1.46239111629949
5734
1.46233726074344
5775
1.46228340518738
5810
1.46222954963132
5762
1.46217569407526
5775
1.4621218385192
5793
1.46206798296314
5793
1.46201412740709
5768
1.46196027185103
5880
1.46190641629497
5817
1.46185256073891
5764
1.46179870518285
5773
1.4617448496268
5740
1.46169099407074
5796
1.46163713851468
5702
1.46158328295862
5731
1.46152942740256
5753
1.46147557184651
5783
1.46142171629045
5722
1.46136786073439
5810
1.46131400517833
5802
1.46126014962227
5849
1.46120629406622
5729
1.46115243851016
5791
1.4610985829541
5862
1.46104472739804
5807
1.46099087184198
5742
1.46093701628593
5815
1.46088316072987
5793
1.46082930517381
5816
1.46077544961775
5768
1.46072159406169
5648
1.46066773850564
5788
1.46061388294958
5786
1.46056002739352
5708
1.46050617183746
5691
1.4604523162814
5819
1.46039846072534
5743
1.46034460516929
5725
1.46029074961323
5747
1.46023689405717
5737
1.46018303850111
5705
1.46012918294505
5673
1.460075327389
5817
1.46002147183294
5747
1.45996761627688
5789
1.45991376072082
5750
1.45985990516476
5816
1.45980604960871
5896
1.45975219405265
5769
1.45969833849659
5765
1.45964448294053
5769
1.45959062738447
5840
1.45953677182842
5874
1.45948291627236
5793
1.4594290607163
5753
1.45937520516024
5710
1.45932134960418
5669
1.45926749404813
5793
1.45921363849207
5712
1.45915978293601
5769
1.45910592737995
5670
1.45905207182389
5735
1.45899821626783
5848
1.45894436071178
5737
1.45889050515572
5780
1.45883664959966
5862
1.4587827940436
5737
1.45872893848754
5795
1.45867508293149
5759
1.45862122737543
5795
1.45856737181937
5797
1.45851351626331
5774
1.45845966070725
5719
1.4584058051512
5699
1.45835194959514
5801
1.45829809403908
5896
1.45824423848302
5755
1.45818054888434
5803
1.45811576661425
5857
1.45805098434416
5845
1.45798620207407
5887
1.45792141980398
5887
1.4578566375339
5825
1.45779185526381
5781
1.45772707299372
5730
1.45766229072363
5800
1.45759750845354
5854
1.45753272618346
5742
1.45746794391337
5784
1.45740316164328
5743
1.45733837937319
5714
1.4572735971031
5828
1.45720881483302
5895
1.45714403256293
O1s
UT 18 Ap
2023
5
9
18
57
10
2
41
Creation
Created by : XPSUser
Date created : 09/05/2023 18:57
Computer : DESKTOP-U3MGE2F
Location
Location ID : T1
Sample : UT 18 Ap
Description : (41.239,15.301,-0.906)mm
Tilt : 0.00
Charge Neutraliser : On
Filament Current : 0.53A
Filament Bias : 2.02V
Charge Balance : 5.02V
Settings
Excitation
Mode : XPS - monochromatic
Tuning : Spectroscopy
Emission current : 15.00mA
Anode library : Al
ESCA modes
Collimation : Slot
Lens : Hybrid
Resolution : 20.00
Scan
Deflection : (0.000, 0.000)mm
O1s : 946.690-961.690eV, Sweeps 5
Start : 946.690eV
End : 961.690eV
Centre : 954.190eV
Width : 15.000eV
Step size : 0.100eV
Number Steps : 150
Dwell time : 397ms
Sweep time : 60s
Sweeps : 5
Target quality : 200
Instrument Conditions
Work function : -4.50
Acquisition Conditions
X-ray Power : 225.00W
Quality : 83.13
XPS
5
41.23875
15.3013671875
-0.9057578125
Al (mono)
1486.69
225
1E+37
1E+37
1E+37
1E+37
FAT
20
1E+37
-4.5
1E+37
1E+37
1E+37
1E+37
1E+37
O1s

-1
Kinetic energy
eV
946.69
0.1
2
Intensity
d
Transmission
d
pulse counting
0.397351
5
0
1E+37
1E+37
1E+37
0
302
7722
12822
1.39073012089434
1.39549665066723
7866
1.39549665066723
7990
1.39546487380208
8033
1.39543309693692
8043
1.39540132007177
8037
1.39536954320662
8102
1.39533776634147
7958
1.39530598947631
8052
1.39527421261116
7982
1.39524243574601
8066
1.39521065888085
8056
1.3951788820157
8042
1.39514710515055
7910
1.3951153282854
8026
1.39508355142024
7940
1.39505177455509
8118
1.39501999768994
8021
1.39498822082479
8000
1.39495644395963
7835
1.39492466709448
8092
1.39489289022933
8061
1.39486111336418
8036
1.39482933649902
7957
1.39479755963387
8093
1.39476578276872
8099
1.39473400590357
7938
1.39470222903841
7976
1.39467045217326
8060
1.39463867530811
8048
1.39460689844296
8148
1.3945751215778
7977
1.39454334471265
7949
1.3945115678475
7945
1.39447979098235
7930
1.39444801411719
8015
1.39441623725204
8218
1.39438446038689
8033
1.39435268352174
8115
1.39432090665658
8034
1.39428912979143
7961
1.39425735292628
7961
1.39422557606112
8026
1.39419379919597
8006
1.39416202233082
8139
1.39413024546567
8110
1.39409846860051
8129
1.39406669173536
8128
1.39403491487021
8106
1.39400313800506
8308
1.3939713611399
8230
1.39393958427475
8245
1.3939078074096
8225
1.39387603054445
8186
1.39384425367929
8271
1.39381247681414
8202
1.39378069994899
8367
1.39374892308384
8397
1.39371714621868
8313
1.39368536935353
8483
1.39365359248838
8522
1.39362181562323
8699
1.39359003875807
8858
1.39355826189292
9084
1.39352648502777
9327
1.39349470816262
9296
1.39346293129746
9703
1.39343115443231
9786
1.39339937756716
10145
1.393367600702
10565
1.39333582383685
10783
1.3933040469717
11039
1.39327227010655
11416
1.39324049324139
11764
1.39320871637624
12061
1.39317693951109
12379
1.39314516264594
12508
1.39311338578078
12490
1.39308160891563
12735
1.39304983205048
12807
1.39301805518533
12822
1.39298627832017
12624
1.39295450145502
12544
1.39292272458987
12428
1.39289094772472
12182
1.39285917085956
11909
1.39282739399441
11663
1.39279561712926
11479
1.39276384026411
11242
1.39273206339895
10875
1.3927002865338
10403
1.39266850966865
10279
1.3926367328035
9998
1.39260495593834
9588
1.39257317907319
9348
1.39254140220804
9219
1.39250962534289
8928
1.39247784847773
8717
1.39244607161258
8471
1.39241429474743
8533
1.39238251788227
8425
1.39235074101712
8363
1.39231896415197
8284
1.39228718728682
8203
1.39225541042166
8041
1.39222363355651
7997
1.39219185669136
8171
1.39216007982621
7961
1.39212830296105
7992
1.3920965260959
8002
1.39206474923075
8047
1.3920329723656
7930
1.39200119550044
7964
1.39196941863529
7886
1.39193764177014
7992
1.39190586490499
7991
1.39187408803983
7972
1.39184231117468
7961
1.39181053430953
7876
1.39177875744438
7809
1.39174698057922
7868
1.39171520371407
7964
1.39168342684892
7917
1.39165164998377
7834
1.39161987311861
7890
1.39158809625346
7921
1.39155631938831
7970
1.39152454252316
8051
1.391492765658
8051
1.39146098879285
7970
1.3914292119277
7896
1.39139743506254
7855
1.39136565819739
8041
1.39133388133224
7969
1.39130210446709
7824
1.39127032760193
7820
1.39123855073678
7902
1.39120677387163
7922
1.39117499700648
8022
1.39114322014132
7966
1.39111144327617
7860
1.39107966641102
7892
1.39104788954587
7943
1.39101611268071
7904
1.39098433581556
7833
1.39095255895041
7725
1.39092078208526
7722
1.3908890052201
7907
1.39085722835495
7891
1.3908254514898
7872
1.39079367462465
7833
1.39076189775949
7838
1.39073012089434
Cl2p
UT 18 Ap
2023
5
9
18
57
10
2
41
Creation
Created by : XPSUser
Date created : 09/05/2023 18:57
Computer : DESKTOP-U3MGE2F
Location
Location ID : T1
Sample : UT 18 Ap
Description : (41.239,15.301,-0.906)mm
Tilt : 0.00
Charge Neutraliser : On
Filament Current : 0.53A
Filament Bias : 2.02V
Charge Balance : 5.02V
Settings
Excitation
Mode : XPS - monochromatic
Tuning : Spectroscopy
Emission current : 15.00mA
Anode library : Al
ESCA modes
Collimation : Slot
Lens : Hybrid
Resolution : 20.00
Scan
Deflection : (0.000, 0.000)mm
Cl2p : 1278.690-1291.690eV, Sweeps 5
Start : 1278.690eV
End : 1291.690eV
Centre : 1285.190eV
Width : 13.000eV
Step size : 0.100eV
Number Steps : 130
Dwell time : 458ms
Sweep time : 60s
Sweeps : 5
Target quality : 200
Instrument Conditions
Work function : -4.50
Acquisition Conditions
X-ray Power : 225.00W
Quality : 7.86
XPS
6
41.23875
15.3013671875
-0.9057578125
Al (mono)
1486.69
225
1E+37
1E+37
1E+37
1E+37
FAT
20
1E+37
-4.5
1E+37
1E+37
1E+37
1E+37
1E+37
Cl2p

-1
Kinetic energy
eV
1278.69
0.1
2
Intensity
d
Transmission
d
pulse counting
0.458015267175573
5
0
1E+37
1E+37
1E+37
0
262
291
367
1.34975176565477
1.35099769238123
323
1.35099769238123
318
1.35098810832949
317
1.35097852427775
305
1.35096894022601
326
1.35095935617426
334
1.35094977212252
317
1.35094018807078
291
1.35093060401904
305
1.3509210199673
307
1.35091143591555
335
1.35090185186381
331
1.35089226781207
304
1.35088268376033
299
1.35087309970859
333
1.35086351565684
331
1.3508539316051
339
1.35084434755336
299
1.35083476350162
310
1.35082517944988
309
1.35081559539813
307
1.35080601134639
332
1.35079642729465
321
1.35078684324291
320
1.35077725919117
321
1.35076767513942
331
1.35075809108768
336
1.35074850703594
334
1.3507389229842
336
1.35072933893246
328
1.35071975488071
321
1.35071017082897
349
1.35070058677723
343
1.35069100272549
332
1.35068141867375
325
1.350671834622
307
1.35066225057026
311
1.35065266651852
339
1.35064308246678
350
1.35063349841504
322
1.35062391436329
314
1.35061433031155
310
1.35060474625981
310
1.35059516220807
301
1.35058557815633
328
1.35057599410458
333
1.35056641005284
335
1.3505568260011
321
1.35054724194936
324
1.35053765789762
328
1.35052807384587
337
1.35051848979413
317
1.35050890574239
310
1.35049932169065
309
1.35048973763891
325
1.35048015358716
320
1.35047056953542
325
1.35046098548368
310
1.35045140143194
318
1.3504418173802
332
1.35043223332845
356
1.35042264927671
352
1.35041306522497
328
1.35040348117323
339
1.35039389712149
338
1.35038431306974
337
1.350374729018
317
1.35036514496626
326
1.35035556091452
332
1.35034597686278
333
1.35033639281103
308
1.35032680875929
319
1.35031722470755
336
1.35030764065581
306
1.35029805660407
306
1.35028847255232
320
1.35027888850058
335
1.35026930444884
333
1.3502597203971
327
1.35025013634536
350
1.35024055229361
329
1.35023096824187
349
1.35022138419013
367
1.35021180013839
348
1.35020221608665
362
1.3501926320349
347
1.35018304798316
332
1.35017346393142
309
1.35016387987968
338
1.35015429582794
355
1.35014471177619
345
1.35013512772445
325
1.35012554367271
329
1.35011595962097
337
1.35010637556923
300
1.35009679151748
319
1.35008720746574
328
1.350077623414
341
1.35006803936226
346
1.35005845531052
340
1.35004887125877
333
1.35003928720703
306
1.35002970315529
307
1.35002011910355
304
1.35001053505181
311
1.35000095100006
316
1.34999136694832
347
1.34998178289658
299
1.34997219884484
310
1.3499626147931
335
1.34995303074135
344
1.34994344668961
355
1.34993386263787
339
1.34992427858613
321
1.34991469453439
320
1.34990511048264
330
1.3498955264309
333
1.34988594237916
312
1.34987635832742
330
1.34986677427568
332
1.34985719022393
318
1.34984760617219
333
1.34983802212045
321
1.34982843806871
317
1.34981885401697
336
1.34980926996522
321
1.34979968591348
320
1.34979010186174
331
1.34978051781
321
1.34977093375826
297
1.34976134970651
307
1.34975176565477
Ti3s
UT 18 Ap
2023
5
9
18
57
10
2
41
Creation
Created by : XPSUser
Date created : 09/05/2023 18:57
Computer : DESKTOP-U3MGE2F
Location
Location ID : T1
Sample : UT 18 Ap
Description : (41.239,15.301,-0.906)mm
Tilt : 0.00
Charge Neutraliser : On
Filament Current : 0.53A
Filament Bias : 2.02V
Charge Balance : 5.02V
Settings
Excitation
Mode : XPS - monochromatic
Tuning : Spectroscopy
Emission current : 15.00mA
Anode library : Al
ESCA modes
Collimation : Slot
Lens : Hybrid
Resolution : 20.00
Scan
Deflection : (0.000, 0.000)mm
Ti3s : 1412.690-1442.690eV, Sweeps 5
Start : 1412.690eV
End : 1442.690eV
Centre : 1427.690eV
Width : 30.000eV
Step size : 0.100eV
Number Steps : 300
Dwell time : 199ms
Sweep time : 60s
Sweeps : 5
Target quality : 200
Instrument Conditions
Work function : -4.50
Acquisition Conditions
X-ray Power : 225.00W
Quality : 7.75
XPS
7
41.23875
15.3013671875
-0.9057578125
Al (mono)
1486.69
225
1E+37
1E+37
1E+37
1E+37
FAT
20
1E+37
-4.5
1E+37
1E+37
1E+37
1E+37
1E+37
Ti3s

-1
Kinetic energy
eV
1412.69
0.1
2
Intensity
d
Transmission
d
pulse counting
0.199335548172757
5
0
1E+37
1E+37
1E+37
0
602
119
186
1.29494863949153
1.2965505499007
146
1.2965505499007
160
1.29654521019933
151
1.29653987049797
150
1.2965345307966
168
1.29652919109524
149
1.29652385139388
134
1.29651851169251
134
1.29651317199115
149
1.29650783228978
139
1.29650249258842
154
1.29649715288706
143
1.29649181318569
133
1.29648647348433
143
1.29648113378297
146
1.2964757940816
148
1.29647045438024
132
1.29646511467887
141
1.29645977497751
138
1.29645443527615
144
1.29644909557478
133
1.29644375587342
152
1.29643841617205
144
1.29643307647069
162
1.29642773676933
156
1.29642239706796
151
1.2964170573666
139
1.29641171766523
157
1.29640637796387
154
1.29640103826251
131
1.29639569856114
145
1.29639035885978
148
1.29638501915842
142
1.29637967945705
130
1.29637433975569
127
1.29636900005432
142
1.29636366035296
158
1.2963583206516
154
1.29635298095023
146
1.29634764124887
139
1.2963423015475
144
1.29633696184614
152
1.29633162214478
160
1.29632628244341
131
1.29632094274205
149
1.29631560304068
152
1.29631026333932
170
1.29630492363796
159
1.29629958393659
150
1.29629424423523
131
1.29628890453386
148
1.2962835648325
149
1.29627822513114
125
1.29627288542977
140
1.29626754572841
148
1.29626220602705
160
1.29625686632568
140
1.29625152662432
136
1.29624618692295
136
1.29624084722159
138
1.29623550752023
170
1.29623016781886
159
1.2962248281175
151
1.29621948841613
147
1.29621414871477
134
1.29620880901341
140
1.29620346931204
154
1.29619812961068
146
1.29619278990931
143
1.29618745020795
141
1.29618211050659
152
1.29617677080522
137
1.29617143110386
134
1.2961660914025
154
1.29616075170113
141
1.29615541199977
119
1.2961500722984
122
1.29614473259704
155
1.29613939289568
141
1.29613405319431
157
1.29612871349295
151
1.29612337379158
135
1.29611803409022
156
1.29611269438886
160
1.29610735468749
146
1.29610201498613
122
1.29609667528476
130
1.2960913355834
145
1.29608599588204
144
1.29608065618067
165
1.29607531647931
176
1.29606997677794
150
1.29606463707658
133
1.29605929737522
153
1.29605395767385
151
1.29604861797249
143
1.29604327827113
143
1.29603793856976
126
1.2960325988684
139
1.29602725916703
151
1.29602191946567
159
1.29601657976431
140
1.29601124006294
144
1.29600590036158
130
1.29600056066021
135
1.29599522095885
150
1.29598988125749
134
1.29598454155612
152
1.29597920185476
148
1.29597386215339
143
1.29596852245203
132
1.29596318275067
131
1.2959578430493
137
1.29595250334794
132
1.29594716364658
154
1.29594182394521
139
1.29593648424385
155
1.29593114454248
144
1.29592580484112
150
1.29592046513976
135
1.29591512543839
152
1.29590978573703
162
1.29590444603566
154
1.2958991063343
154
1.29589376663294
140
1.29588842693157
139
1.29588308723021
130
1.29587774752884
145
1.29587240782748
150
1.29586706812612
143
1.29586172842475
165
1.29585638872339
140
1.29585104902202
154
1.29584570932066
140
1.2958403696193
146
1.29583502991793
145
1.29582969021657
134
1.29582435051521
134
1.29581901081384
134
1.29581367111248
152
1.29580833141111
149
1.29580299170975
128
1.29579765200839
143
1.29579231230702
136
1.29578697260566
135
1.29578163290429
142
1.29577629320293
147
1.29577095350157
126
1.2957656138002
141
1.29576027409884
145
1.29575493439747
149
1.29574959469611
151
1.29574425499475
159
1.29573891529338
135
1.29573357559202
151
1.29572823589066
133
1.29572289618929
136
1.29571755648793
154
1.29571221678656
168
1.2957068770852
141
1.29570153738384
142
1.29569619768247
143
1.29569085798111
161
1.29568551827974
155
1.29568017857838
151
1.29567483887702
149
1.29566949917565
150
1.29566415947429
135
1.29565881977292
144
1.29565348007156
138
1.2956481403702
138
1.29564280066883
149
1.29563746096747
156
1.2956321212661
128
1.29562678156474
138
1.29562144186338
139
1.29561610216201
153
1.29561076246065
129
1.29560542275929
145
1.29560008305792
151
1.29559474335656
155
1.29558940365519
147
1.29558406395383
152
1.29557872425247
161
1.2955733845511
147
1.29556804484974
158
1.29556270514837
144
1.29555736544701
159
1.29555202574565
148
1.29554668604428
128
1.29554134634292
144
1.29553600664155
143
1.29553066694019
155
1.29552532723883
136
1.29551998753746
152
1.2955146478361
148
1.29550930813473
148
1.29550396843337
137
1.29549862873201
164
1.29549328903064
151
1.29548794932928
136
1.29548260962792
137
1.29547726992655
151
1.29547193022519
177
1.29546659052382
150
1.29546125082246
158
1.2954559111211
163
1.29545057141973
136
1.29544523171837
143
1.295439892017
147
1.29543455231564
148
1.29542921261428
163
1.29542387291291
161
1.29541853321155
160
[...]
1E+37
Ti3p

-1
Kinetic energy
eV
1437.69
0.1
2
Intensity
d
Transmission
d
pulse counting
0.199335548172757
5
0
1E+37
1E+37
1E+37
0
602
101
299
1.29361371415055
1.29521562455972
171
1.29521562455972
158
1.29521028485836
173
1.29520494515699
159
1.29519960545563
148
1.29519426575426
160
1.2951889260529
161
1.29518358635154
159
1.29517824665017
166
1.29517290694881
178
1.29516756724745
166
1.29516222754608
161
1.29515688784472
177
1.29515154814335
167
1.29514620844199
156
1.29514086874063
160
1.29513552903926
170
1.2951301893379
171
1.29512484963653
177
1.29511950993517
163
1.29511417023381
173
1.29510883053244
162
1.29510349083108
169
1.29509815112971
173
1.29509281142835
174
1.29508747172699
162
1.29508213202562
163
1.29507679232426
166
1.29507145262289
170
1.29506611292153
177
1.29506077322017
173
1.2950554335188
172
1.29505009381744
172
1.29504475411608
164
1.29503941441471
178
1.29503407471335
173
1.29502873501198
163
1.29502339531062
153
1.29501805560926
165
1.29501271590789
177
1.29500737620653
171
1.29500203650516
166
1.2949966968038
170
1.29499135710244
190
1.29498601740107
175
1.29498067769971
170
1.29497533799834
174
1.29496999829698
187
1.29496465859562
185
1.29495931889425
183
1.29495397919289
154
1.29494863949153
157
1.29494329979016
164
1.2949379600888
165
1.29493262038743
180
1.29492728068607
188
1.29492194098471
181
1.29491660128334
168
1.29491126158198
156
1.29490592188061
148
1.29490058217925
156
1.29489524247789
150
1.29488990277652
163
1.29488456307516
164
1.29487922337379
156
1.29487388367243
162
1.29486854397107
167
1.2948632042697
172
1.29485786456834
170
1.29485252486697
135
1.29484718516561
162
1.29484184546425
156
1.29483650576288
168
1.29483116606152
159
1.29482582636016
154
1.29482048665879
158
1.29481514695743
165
1.29480980725606
151
1.2948044675547
175
1.29479912785334
162
1.29479378815197
149
1.29478844845061
157
1.29478310874924
137
1.29477776904788
169
1.29477242934652
134
1.29476708964515
151
1.29476174994379
162
1.29475641024242
158
1.29475107054106
157
1.2947457308397
160
1.29474039113833
159
1.29473505143697
152
1.29472971173561
153
1.29472437203424
156
1.29471903233288
166
1.29471369263151
170
1.29470835293015
160
1.29470301322879
153
1.29469767352742
139
1.29469233382606
147
1.29468699412469
157
1.29468165442333
166
1.29467631472197
152
1.2946709750206
166
1.29466563531924
167
1.29466029561787
168
1.29465495591651
155
1.29464961621515
133
1.29464427651378
127
1.29463893681242
148
1.29463359711105
142
1.29462825740969
127
1.29462291770833
148
1.29461757800696
132
1.2946122383056
146
1.29460689860424
160
1.29460155890287
155
1.29459621920151
154
1.29459087950014
132
1.29458553979878
138
1.29458020009742
131
1.29457486039605
134
1.29456952069469
148
1.29456418099332
141
1.29455884129196
138
1.2945535015906
137
1.29454816188923
127
1.29454282218787
136
1.2945374824865
145
1.29453214278514
136
1.29452680308378
151
1.29452146338241
134
1.29451612368105
141
1.29451078397968
140
1.29450544427832
143
1.29450010457696
139
1.29449476487559
133
1.29448942517423
136
1.29448408547287
146
1.2944787457715
153
1.29447340607014
145
1.29446806636877
142
1.29446272666741
138
1.29445738696605
128
1.29445204726468
122
1.29444670756332
144
1.29444136786195
130
1.29443602816059
140
1.29443068845923
125
1.29442534875786
130
1.2944200090565
132
1.29441466935513
114
1.29440932965377
120
1.29440398995241
139
1.29439865025104
127
1.29439331054968
134
1.29438797084832
116
1.29438263114695
127
1.29437729144559
131
1.29437195174422
135
1.29436661204286
134
1.2943612723415
130
1.29435593264013
110
1.29435059293877
114
1.2943452532374
131
1.29433991353604
131
1.29433457383468
123
1.29432923413331
124
1.29432389443195
143
1.29431855473058
133
1.29431321502922
121
1.29430787532786
127
1.29430253562649
110
1.29429719592513
131
1.29429185622377
114
1.2942865165224
120
1.29428117682104
114
1.29427583711967
120
1.29427049741831
111
1.29426515771695
110
1.29425981801558
101
1.29425447831422
124
1.29424913861285
114
1.29424379891149
126
1.29423845921013
111
1.29423311950876
128
1.2942277798074
134
1.29422244010603
122
1.29421710040467
116
1.29421176070331
116
1.29420642100194
117
1.29420108130058
116
1.29419574159921
111
1.29419040189785
128
1.29418506219649
125
1.29417972249512
115
1.29417438279376
112
1.2941690430924
132
1.29416370339103
144
1.29415836368967
130
1.2941530239883
132
1.29414768428694
134
1.29414234458558
128
1.29413700488421
121
1.29413166518285
145
1.29412632548148
121
1.29412098578012
131
1.29411564607876
123
1.29411030637739
120
1.29410496667603
125
1.29409962697466
131
1.2940942872733
122
1.29408894757194
131
1.29408360787057
139
1.29407826816921
140
1.29407292846784
148
1.29406758876648
147
1.29406224906512
129
1.29405690936375
134
1.29405156966239
143
1.29404622996103
136
1.29404089025966
128
1.2940355505583
140
1.29403021085693
144
1.29402487115557
147
1.29401953145421
134
1.29401419175284
132
1.29400885205148
145
1.29400351235011
124
1.29399817264875
140
1.29399283294739
159
1.29398749324602
149
1.29398215354466
160
1.29397681384329
157
1.29397147414193
143
1.29396613444057
129
1.2939607947392
149
1.29395545503784
162
1.29395011533648
165
1.29394477563511
162
1.29393943593375
144
1.29393409623238
154
1.29392875653102
166
1.29392341682966
158
1.29391807712829
148
1.29391273742693
155
1.29390739772556
178
1.2939020580242
168
1.29389671832284
142
1.29389137862147
146
1.29388603892011
157
1.29388069921874
151
1.29387535951738
159
1.29387001981602
167
1.29386468011465
165
1.29385934041329
163
1.29385400071192
158
1.29384866101056
149
1.2938433213092
148
1.29383798160783
166
1.29383264190647
156
1.29382730220511
170
1.29382196250374
173
1.29381662280238
168
1.29381128310101
176
1.29380594339965
163
1.29380060369829
173
1.29379526399692
169
1.29378992429556
156
1.29378458459419
176
1.29377924489283
184
1.29377390519147
196
1.2937685654901
199
1.29376322578874
202
1.29375788608737
211
1.29375254638601
194
1.29374720668465
205
1.29374186698328
211
1.29373652728192
243
1.29373118758056
227
1.29372584787919
239
1.29372050817783
237
1.29371516847646
214
1.2937098287751
237
1.29370448907374
246
1.29369914937237
237
1.29369380967101
270
1.29368846996964
273
1.29368313026828
299
1.29367779056692
262
1.29367245086555
240
1.29366711116419
274
1.29366177146282
277
1.29365643176146
265
1.2936510920601
247
1.29364575235873
260
1.29364041265737
279
1.293635072956
259
1.29362973325464
265
1.29362439355328
271
1.29361905385191
286
1.29361371415055
Ti2s
UT 18 Ap
2023
5
9
18
57
10
2
41
Creation
Created by : XPSUser
Date created : 09/05/2023 18:57
Computer : DESKTOP-U3MGE2F
Location
Location ID : T1
Sample : UT 18 Ap
Description : (41.239,15.301,-0.906)mm
Tilt : 0.00
Charge Neutraliser : On
Filament Current : 0.53A
Filament Bias : 2.02V
Charge Balance : 5.02V
Settings
Excitation
Mode : XPS - monochromatic
Tuning : Spectroscopy
Emission current : 15.00mA
Anode library : Al
ESCA modes
Collimation : Slot
Lens : Hybrid
Resolution : 20.00
Scan
Deflection : (0.000, 0.000)mm
Ti2s : 907.690-937.690eV, Sweeps 10
Start : 907.690eV
End : 937.690eV
Centre : 922.690eV
Width : 30.000eV
Step size : 0.100eV
Number Steps : 300
Dwell time : 199ms
Sweep time : 60s
Sweeps : 10
Target quality : 200
Instrument Conditions
Work function : -4.50
Acquisition Conditions
X-ray Power : 225.00W
Quality : 7.58
XPS
9
41.23875
15.3013671875
-0.9057578125
Al (mono)
1486.69
225
1E+37
1E+37
1E+37
1E+37
FAT
20
1E+37
-4.5
1E+37
1E+37
1E+37
1E+37
1E+37
Ti2s

-1
Kinetic energy
eV
907.69
0.1
2
Intensity
d
Transmission
d
pulse counting
0.199335548172757
10
0
1E+37
1E+37
1E+37
0
602
7876
8300
1.39835656853096
1.40786093570082
7970
1.40786093570082
7933
1.40783040092986
7924
1.40779986615891
8052
1.40776933138795
8111
1.40773879661699
8164
1.40770826184604
8085
1.40767772707508
8126
1.40764719230412
7933
1.40761665753316
8056
1.40758612276221
8039
1.40755558799125
8056
1.40752505322029
8115
1.40749451844934
7926
1.40746398367838
8054
1.40743344890742
8154
1.40740291413646
8008
1.40737237936551
7998
1.40734184459455
8071
1.40731130982359
7961
1.40728077505264
8100
1.40725024028168
8069
1.40721970551072
8161
1.40718917073976
8102
1.40715863596881
8119
1.40712698331307
8169
1.40709520644792
8167
1.40706342958277
8051
1.40703165271762
8109
1.40699987585246
7998
1.40696809898731
8039
1.40693632212216
7988
1.40690454525701
8177
1.40687276839185
8042
1.4068409915267
8082
1.40680921466155
8071
1.4067774377964
7997
1.40674566093124
7978
1.40671388406609
8195
1.40668210720094
8090
1.40665033033579
7935
1.40661855347063
7966
1.40658677660548
8046
1.40655499974033
7969
1.40652322287517
8001
1.40649144601002
8056
1.40645966914487
7954
1.40642789227972
8001
1.40639611541456
7924
1.40636433854941
8038
1.40633256168426
8137
1.40630078481911
7968
1.40626900795395
8085
1.4062372310888
8054
1.40620545422365
8099
1.4061736773585
8117
1.40614190049334
7978
1.40611012362819
8098
1.40607834676304
8045
1.40604656989789
7936
1.40601479303273
7917
1.40598301616758
8087
1.40595123930243
8044
1.40591946243728
8077
1.40588768557212
8024
1.40585590870697
8095
1.40582413184182
8088
1.40579235497667
8144
1.40576057811151
8129
1.40572880124636
8160
1.40569702438121
8153
1.40566524751605
8062
1.4056334706509
8084
1.40560169378575
8036
1.4055699169206
7947
1.40553814005544
8012
1.40550636319029
8095
1.40547458632514
8016
1.40544280945999
7983
1.40541103259483
8047
1.40537925572968
8174
1.40534747886453
8003
1.40531570199938
8014
1.40528392513422
8014
1.40525214826907
8032
1.40522037140392
8086
1.40518859453877
8056
1.40515681767361
8079
1.40512504080846
8127
1.40509326394331
8128
1.40506148707816
8035
1.405029710213
7989
1.40499793334785
8074
1.4049661564827
8186
1.40493437961755
8066
1.40490260275239
7941
1.40487082588724
8071
1.40483904902209
8009
1.40480727215694
8020
1.40477549529178
8186
1.40474371842663
8199
1.40471194156148
8104
1.40468016469632
8195
1.40464838783117
8070
1.40461661096602
8127
1.40458483410087
8015
1.40455305723571
7964
1.40452128037056
8032
1.40448950350541
8080
1.40445772664026
8057
1.4044259497751
8200
1.40439417290995
8054
1.4043623960448
7961
1.40433061917965
8130
1.40429884231449
8109
1.40426706544934
8052
1.40423528858419
7991
1.40420351171904
8050
1.40417173485388
8075
1.40413995798873
8039
1.40410818112358
8071
1.40407640425843
8117
1.40404462739327
8133
1.40401285052812
8153
1.40398107366297
7884
1.40394929679782
8015
1.40391751993266
8057
1.40388574306751
8018
1.40385396620236
8119
1.40382218933721
8163
1.40379041247205
8102
1.4037586356069
8055
1.40372685874175
8052
1.40369508187659
8029
1.40366330501144
8015
1.40363152814629
7981
1.40359975128114
8008
1.40356797441598
8038
1.40353619755083
7991
1.40350442068568
8037
1.40347264382053
8000
1.40344086695537
8050
1.40340909009022
8089
1.40337731322507
8064
1.40334553635992
8043
1.40331375949476
7952
1.40328198262961
8098
1.40325020576446
8143
1.40321842889931
8191
1.40318665203415
8134
1.403154875169
8093
1.40312309830385
8130
1.4030913214387
8059
1.40305954457354
8135
1.40302776770839
8145
1.40299599084324
8181
1.40296421397809
8078
1.40293243711293
8115
1.40290066024778
8219
1.40286888338263
8156
1.40283710651747
8099
1.40280532965232
8151
1.40277355278717
8141
1.40274177592202
8119
1.40270999905686
8279
1.40267822219171
8282
1.40264644532656
8126
1.40261466846141
8062
1.40258289159625
8141
1.4025511147311
8134
1.40251933786595
8050
1.4024875610008
8164
1.40245578413564
8079
1.40242400727049
8156
1.40239223040534
7982
1.40236045354019
8103
1.40232867667503
8054
1.40229689980988
8169
1.40226512294473
8209
1.40223334607958
8227
1.40220156921442
8140
1.40216979234927
8025
1.40213801548412
8111
1.40210623861897
8158
1.40207446175381
8300
1.40204268488866
7969
1.40201090802351
7895
1.40197913115836
8093
1.4019473542932
8229
1.40191557742805
8153
1.4018838005629
7989
1.40185202369774
8123
1.40182024683259
8166
1.40178846996744
8193
1.40175669310229
8180
1.40172491623713
8126
1.40169313937198
8169
1.40166136250683
8156
1.40162958564168
8116
1.40159780877652
8176
1.40156603191137
8213
1.40153425504622
8158
1.40150247818107
8100
1.40147070131591
8171
1.40143892445076
8146
1.40140714758561
8205
1.40137537072046
8160
1.4013435938553
8189
1.40131181699015
8220
1.401280040125
8147
1.40124826325985
8203
1.40121648639469
8237
1.40118470952954
8232
1.40115293266439
8126
1.40112115579924
8112
1.40108937893408
8185
1.40105760206893
8274
1.40102582520378
8067
1.40099404833863
8123
1.40096227147347
8164
1.40093049460832
8117
1.40089871774317
8102
1.40086694087801
8227
1.40083516401286
8203
1.40080338714771
8281
1.40077161028256
8219
1.4007398334174
8159
1.40070805655225
8233
1.4006762796871
8216
1.40064450282195
8263
1.40061272595679
8185
1.40058094909164
8059
1.40054917222649
8160
1.40051739536134
8152
1.40048561849618
8137
1.40045384163103
8137
1.40042206476588
8070
1.40039028790073
8223
1.40035851103557
8241
1.40032673417042
8161
1.40029495730527
8125
1.40026318044012
8154
1.40023140357496
8089
1.40019962670981
8072
1.40016784984466
8245
1.40013607297951
8110
1.40010429611435
8085
1.4000725192492
8172
1.40004074238405
8193
1.40000896551889
8277
1.39997718865374
8151
1.39994541178859
8133
1.39991363492344
8102
1.39988185805828
8081
1.39985008119313
8150
1.39981830432798
8243
1.39978652746283
8214
1.39975475059767
8050
1.39972297373252
8177
1.39969119686737
8150
1.39965942000222
8155
1.39962764313706
8033
1.39959586627191
8026
1.39956408940676
8153
1.39953231254161
8181
1.39950053567645
8080
1.3994687588113
8196
1.39943698194615
8262
1.399405205081
8193
1.39937342821584
8107
1.39934165135069
8203
1.39930987448554
8112
1.39927809762039
8092
1.39924632075523
8108
1.39921454389008
8132
1.39918276702493
8209
1.39915099015978
8200
1.39911921329462
8152
1.39908743642947
8133
1.39905565956432
8249
1.39902388269916
8160
1.39899210583401
8194
1.39896032896886
8151
1.39892855210371
8120
1.39889677523855
8128
1.3988649983734
8106
1.39883322150825
8073
1.3988014446431
8191
1.39876966777794
8092
1.39873789091279
8133
1.39870611404764
8246
1.39867433718249
8165
1.39864256031733
8074
1.39861078345218
8106
1.39857900658703
8087
1.39854722972188
8123
1.39851545285672
8055
1.39848367599157
7944
1.39845189912642
8056
1.39842012226127
7876
1.39838834539611
7941
1.39835656853096
Ti2p
UT 18 Ap
2023
5
9
18
57
10
2
41
Creation
Created by : XPSUser
Date created : 09/05/2023 18:57
Computer : DESKTOP-U3MGE2F
Location
Location ID : T1
Sample : UT 18 Ap
Description : (41.239,15.301,-0.906)mm
Tilt : 0.00
Charge Neutraliser : On
Filament Current : 0.53A
Filament Bias : 2.02V
Charge Balance : 5.02V
Settings
Excitation
Mode : XPS - monochromatic
Tuning : Spectroscopy
Emission current : 15.00mA
Anode library : Al
ESCA modes
Collimation : Slot
Lens : Hybrid
Resolution : 20.00
Scan
Deflection : (0.000, 0.000)mm
Ti2p : 1016.690-1036.690eV, Sweeps 10
Start : 1016.690eV
End : 1036.690eV
Centre : 1026.690eV
Width : 20.000eV
Step size : 0.100eV
Number Steps : 200
Dwell time : 299ms
Sweep time : 60s
Sweeps : 10
Target quality : 200
Instrument Conditions
Work function : -4.50
Acquisition Conditions
X-ray Power : 225.00W
Quality : 7.13
XPS
10
41.23875
15.3013671875
-0.9057578125
Al (mono)
1486.69
225
1E+37
1E+37
1E+37
1E+37
FAT
20
1E+37
-4.5
1E+37
1E+37
1E+37
1E+37
1E+37
Ti2p

-1
Kinetic energy
eV
1016.69
0.1
2
Intensity
d
Transmission
d
pulse counting
0.298507462686567
10
0
1E+37
1E+37
1E+37
0
402
11791
12269
1.34818394035546
1.35812104677082
11791
1.35812104677082
12018
1.35807136123875
11910
1.35802167570667
11850
1.35797199017459
11886
1.35792230464252
11876
1.35787261911044
12053
1.35782293357836
12022
1.35777324804629
12017
1.35772356251421
11973
1.35767387698213
12027
1.35762419145005
12011
1.35757450591798
12038
1.3575248203859
12038
1.35747513485382
12074
1.35742544932175
11960
1.35737576378967
12110
1.35732607825759
12093
1.35727639272552
12002
1.35722670719344
12165
1.35717702166136
12114
1.35712733612929
11860
1.35707765059721
11982
1.35702796506513
12026
1.35697827953306
11952
1.35692859400098
11881
1.3568789084689
11969
1.35682922293683
11968
1.35677953740475
12039
1.35672985187267
12135
1.3566801663406
11912
1.35663048080852
12027
1.35658079527644
12091
1.35653110974437
12182
1.35648142421229
12027
1.35643173868021
11920
1.35638205314813
12072
1.35633236761606
11902
1.35628268208398
12160
1.3562329965519
12157
1.35618331101983
11995
1.35613362548775
12015
1.35608393995567
12048
1.3560342544236
12074
1.35598456889152
12207
1.35593488335944
11914
1.35588519782737
12040
1.35583551229529
12039
1.35578582676321
11994
1.35573614123114
12095
1.35568645569906
12145
1.35563677016698
12221
1.35558708463491
12106
1.35553739910283
11908
1.35548771357075
11989
1.35543802803868
12084
1.3553883425066
12049
1.35533865697452
11904
1.35528897144245
12126
1.35523928591037
11979
1.35518960037829
12092
1.35513991484622
12019
1.35509022931414
12174
1.35504054378206
12080
1.35499085824998
11942
1.35494117271791
12075
1.35489148718583
11964
1.35484180165375
12008
1.35479211612168
12174
1.3547424305896
12012
1.35469274505752
12107
1.35464305952545
12015
1.35459337399337
11982
1.35454368846129
11939
1.35449400292922
11887
1.35444431739714
11956
1.35439463186506
12035
1.35434494633299
12168
1.35429526080091
11994
1.35424557526883
12051
1.35419588973676
12030
1.35414620420468
12047
1.3540965186726
12036
1.35404683314053
11974
1.35399714760845
11943
1.35394746207637
11997
1.3538977765443
11950
1.35384809101222
11945
1.35379840548014
12021
1.35374871994806
12134
1.35369903441599
12107
1.35364934888391
12029
1.35359966335183
12214
1.35354997781976
12093
1.35350029228768
11941
1.3534506067556
11958
1.35340092122353
12035
1.35335123569145
11989
1.35330155015937
12059
1.3532518646273
12004
1.35320217909522
12042
1.35315249356314
11909
1.35310280803107
11967
1.35305312249899
12090
1.35300343696691
12124
1.35295375143484
12053
1.35290406590276
12014
1.35285438037068
11993
1.35280469483861
12145
1.35275500930653
12214
1.35270532377445
12113
1.35265563824238
12013
1.3526059527103
12066
1.35255626717822
12029
1.35250658164615
11992
1.35245689611407
12092
1.35240721058199
11962
1.35235752504991
11979
1.35230783951784
11900
1.35225815398576
12136
1.35220846845368
12072
1.35215878292161
12012
1.35210909738953
12113
1.35205941185745
12147
1.35200972632538
12117
1.3519600407933
11997
1.35191035526122
11966
1.35186066972915
12123
1.35181098419707
12100
1.35176129866499
11992
1.35171161313292
12230
1.35166192760084
12119
1.35161224206876
12159
1.35156255653669
12174
1.35151287100461
12194
1.35146318547253
12193
1.35141349994046
12142
1.35136381440838
12094
1.3513141288763
12046
1.35126444334423
12108
1.35121475781215
12082
1.35116507228007
12131
1.35111538674799
12269
1.35106570121592
12149
1.35101601568384
12033
1.35096633015176
11902
1.35091664461969
11860
1.35086695908761
12045
1.35081727355553
11950
1.35076758802346
12128
1.35071790249138
12042
1.3506682169593
12065
1.35061853142723
12024
1.35056884589515
11918
1.35051916036307
11965
1.350469474831
12150
1.35041978929892
12121
1.35037010376684
11908
1.35032041823477
11934
1.35027073270269
11942
1.35022104717061
12025
1.35017136163854
12161
1.35012167610646
12130
1.35007199057438
12107
1.35002230504231
12213
1.34997261951023
12166
1.34992293397815
12097
1.34987324844607
12052
1.349823562914
12109
1.34977387738192
12104
1.34972419184984
12139
1.34967450631777
12033
1.34962482078569
12171
1.34957513525361
12093
1.34952544972154
12069
1.34947576418946
11976
1.34942607865738
12127
1.34937639312531
12165
1.34932670759323
12235
1.34927702206115
12107
1.34922733652908
12235
1.349177650997
12015
1.34912796546492
12098
1.34907827993285
11891
1.34902859440077
11996
1.34897890886869
12122
1.34892922333662
12047
1.34887953780454
12038
1.34882985227246
12019
1.34878016674039
12083
1.34873048120831
12154
1.34868079567623
12026
1.34863111014416
12045
1.34858142461208
12030
1.34853173908
12010
1.34848205354792
12016
1.34843236801585
12137
1.34838268248377
12165
1.34833299695169
12109
1.34828331141962
12144
1.34823362588754
12170
1.34818394035546
end of experiment